<?xml version="1.0" ?>
<!-- =================================================================================== -->
<!-- |    This document was autogenerated by xacro from xacro/genie.robot.xacro        | -->
<!-- |    EDITING THIS FILE BY HAND IS NOT RECOMMENDED                                 | -->
<!-- =================================================================================== -->
<robot name="genie">
  <!-- coarse, fine, visual -->
  <!-- <xacro:arg name="robot_model" default="G1" />
  <xacro:arg name="robot_model" default="G1" /> -->
  <!-- robot -->
  <!-- <xacro:property name="mesh_dir" value="package://${package_name}/meshes" /> -->
  <!-- Material Definition -->
  <material name="black">
    <color rgba="0.0 0.0 0.0 1.0"/>
  </material>
  <material name="blue">
    <color rgba="0.0 0.0 0.8 1.0"/>
  </material>
  <material name="green">
    <color rgba="0.0 1.0 0.0 1.0"/>
  </material>
  <material name="grey">
    <color rgba="0.2 0.2 0.2 1.0"/>
  </material>
  <material name="orange">
    <color rgba="1.0 0.4235294117647059 0.0392156862745098 1.0"/>
  </material>
  <material name="brown">
    <color rgba="0.8705882352941177 0.8117647058823529 0.7647058823529411 1.0"/>
  </material>
  <material name="red">
    <color rgba="0.8 0.0 0.0 1.0"/>
  </material>
  <material name="white">
    <color rgba="1.0 1.0 1.0 1.0"/>
  </material>
  <!-- transparent is not working properly -->
  <material name="transparent">
    <color rgba="1.0 1.0 1.0 0.999"/>
  </material>
  <material name="default">
    <color rgba="0.752941176470588 0.752941176470588 0.752941176470588 1"/>
  </material>
  <!-- main xacro -->
  <!-- main xacro -->
  <!-- main xacro -->
  <!-- <xacro:macro name="arm_l" params="debug parent_link end_link"> -->
  <!-- properties -->
  <!-- Arm -->
  <!-- assemble robot -->
  <!-- properties -->
  <!-- Base -->
  <link name="base_link">
    <inertial>
      <origin rpy="0 0 0" xyz="0.00149 -0.002673 0.117552"/>
      <mass value="74"/>
      <inertia ixx="3.032489" ixy="-0.003519" ixz="0.010648" iyy="2.833502" iyz="-0.000989" izz="4.644149"/>
    </inertial>
    <visual>
      <origin rpy="0 0 0" xyz="0 0 0"/>
      <geometry>
        <mesh filename="package://genie_robot_description/meshes/G2/T1/base_link.STL"/>
      </geometry>
      <material name="white"/>
    </visual>
    <collision name="base_link_coarse_0">
      <geometry>
        <box size="0.62673163 0.17409083 0.3258258"/>
      </geometry>
      <origin rpy="0.0 -0.0 0.0" xyz="0.011247277 -0.21094544 0.16291195"/>
    </collision>
    <collision name="base_link_coarse_1">
      <geometry>
        <box size="0.62667394 0.18714839 0.3258258"/>
      </geometry>
      <origin rpy="0.0 -0.0 0.0" xyz="0.011277318 0.20441666 0.16291195"/>
    </collision>
    <collision name="base_link_coarse_2">
      <geometry>
        <box size="0.6246023 0.23870158 0.06967827"/>
      </geometry>
      <origin rpy="0.0 -0.0 0.0" xyz="0.01230073 -0.01307106 0.11483914"/>
    </collision>
  </link>
  <link name="body_link1">
    <inertial>
      <origin rpy="0 0 0" xyz="-0.107323 -0.039185 0.050115"/>
      <mass value="14.129"/>
      <inertia ixx="0.151776" ixy="-0.023402" ixz="0.090707" iyy="0.276733" iyz="0.010903" izz="0.304201"/>
    </inertial>
    <visual>
      <origin rpy="0 0 0" xyz="0 0 0"/>
      <geometry>
        <mesh filename="package://genie_robot_description/meshes/G2/T1/body_link1.STL"/>
      </geometry>
      <material name="white"/>
    </visual>
    <collision name="body_link1_coarse_0">
      <geometry>
        <box size="0.146916653064989 0.21210148364482734 0.4984007347291842"/>
      </geometry>
      <origin rpy="3.131859512133172 1.1132561689202216 3.1309874363998365" xyz="-0.15756349693645624 -0.0027857167676530476 0.07797823284372236"/>
    </collision>
  </link>
  <joint name="idx01_body_joint1" type="revolute">
    <origin rpy="0 0 0" xyz="0.102 0 0.144"/>
    <parent link="base_link"/>
    <child link="body_link1"/>
    <axis xyz="0 1 0"/>
    <limit effort="0" lower="0" upper="1.18" velocity="1"/>
  </joint>
  <link name="body_link2">
    <inertial>
      <origin rpy="0 0 0" xyz="0.014787 -0.004305 -4.7E-05"/>
      <mass value="8.5"/>
      <inertia ixx="0.037974" ixy="-0.00042" ixz="-0.000627" iyy="0.043889" iyz="-4.9E-05" izz="0.053192"/>
    </inertial>
    <visual>
      <origin rpy="0 0 0" xyz="0 0 0"/>
      <geometry>
        <mesh filename="package://genie_robot_description/meshes/G2/T1/body_link2.STL"/>
      </geometry>
      <material name="white"/>
    </visual>
    <collision name="body_link2_coarse_0">
      <origin rpy="-0.0 0.0 -0.0" xyz="0.15452659 -0.0003606267299999938 0.0005599260300000047"/>
      <geometry>
        <box size="0.17897915999999997 0.14396027 0.14191318"/>
      </geometry>
    </collision>
    <collision name="body_link2_coarse_1">
      <origin rpy="-0.0 0.0 -0.0" xyz="0.007503151999999999 0.001936905099999997 0.0"/>
      <geometry>
        <box size="0.16681123 0.19921139 0.15199995"/>
      </geometry>
    </collision>
  </link>
  <joint name="idx02_body_joint2" type="revolute">
    <origin rpy="0 0 0" xyz="-0.32627 0 0.15214"/>
    <parent link="body_link1"/>
    <child link="body_link2"/>
    <axis xyz="0 1 0"/>
    <limit effort="0" lower="-3.2" upper="3.2" velocity="1"/>
  </joint>
  <link name="body_link3">
    <inertial>
      <origin rpy="0 0 0" xyz="0.090164 -0.000208 0.000106"/>
      <mass value="11.3"/>
      <inertia ixx="0.032314" ixy="0.000154" ixz="-0.000109" iyy="0.157458" iyz="-6.8E-05" izz="0.160611"/>
    </inertial>
    <visual>
      <origin rpy="0 0 0" xyz="0 0 0"/>
      <geometry>
        <mesh filename="package://genie_robot_description/meshes/G2/T1/body_link3.STL"/>
      </geometry>
      <material name="white"/>
    </visual>
    <collision name="body_link3_coarse_0">
      <origin rpy="-0.0 0.0 -0.0" xyz="-0.0068293809999999955 -7.301568999973362e-07 1.394748699999615e-05"/>
      <geometry>
        <box size="0.21439385 0.13700145 0.13697219"/>
      </geometry>
    </collision>
    <collision name="body_link3_coarse_1">
      <origin rpy="-0.0 0.0 -0.0" xyz="0.17601156 -0.012499623000000001 0.0"/>
      <geometry>
        <box size="0.15228176000000002 0.17600076 0.15199995"/>
      </geometry>
    </collision>
  </link>
  <joint name="idx03_body_joint3" type="revolute">
    <origin rpy="0 0 0" xyz="0.23 0 0"/>
    <parent link="body_link2"/>
    <child link="body_link3"/>
    <axis xyz="-1 0 0"/>
    <limit effort="0" lower="-0.52" upper="0.52" velocity="1"/>
  </joint>
  <link name="body_link4">
    <inertial>
      <origin rpy="0 0 0" xyz="-0.00051665 -0.0075684 0.05319"/>
      <mass value="2.5631"/>
      <inertia ixx="0.024754" ixy="7.8E-05" ixz="0.000303" iyy="0.015703" iyz="-0.000687" izz="0.021641"/>
    </inertial>
    <visual>
      <origin rpy="0 0 0" xyz="0 0 0"/>
      <geometry>
        <mesh filename="package://genie_robot_description/meshes/G2/T1/body_link4.STL"/>
      </geometry>
      <material name="white"/>
    </visual>
    <collision name="body_link4_coarse_0">
      <origin rpy="-0.0 0.0 -0.0" xyz="-2.6226043999960647e-06 -0.0024472474999999994 0.042441845000000006"/>
      <geometry>
        <box size="0.13012743 0.19439101 0.21517658"/>
      </geometry>
    </collision>
  </link>
  <joint name="idx04_body_joint4" type="revolute">
    <origin rpy="0 0 0" xyz="0.175 0 0"/>
    <parent link="body_link3"/>
    <child link="body_link4"/>
    <axis xyz="0 1 0"/>
    <limit effort="0" lower="-0.39" upper="3.19" velocity="1"/>
  </joint>
  <link name="body_link5">
    <inertial>
      <origin rpy="0 0 0" xyz="-0.018295 0.00022303 0.20326"/>
      <mass value="17.326"/>
      <inertia ixx="0.324244" ixy="0.000839" ixz="0.025409" iyy="0.336475" iyz="0.000377" izz="0.148307"/>
    </inertial>
    <visual>
      <origin rpy="0 0 0" xyz="0 0 0"/>
      <geometry>
        <mesh filename="package://genie_robot_description/meshes/G2/T1/body_link5.STL"/>
      </geometry>
      <material name="default"/>
    </visual>
    <collision name="body_link5_coarse_0">
      <origin rpy="-0.0 0.0 -0.0" xyz="0.0022273064000000037 3.695487999999525e-06 0.242803"/>
      <geometry>
        <box size="0.17862797 0.2499926 0.2571556"/>
      </geometry>
    </collision>
    <collision name="body_link5_coarse_1">
      <origin rpy="-0.0 0.0 -0.0" xyz="-0.12621355 -0.004532456399999996 0.23204112"/>
      <geometry>
        <box size="0.088994026 0.15906501 0.19257259999999998"/>
      </geometry>
    </collision>
    <collision name="body_link5_coarse_2">
      <origin rpy="-0.0 0.0 -0.0" xyz="0.12886572 0.0 0.26373816"/>
      <geometry>
        <box size="0.07847308999999998 0.074500084 0.10599135999999998"/>
      </geometry>
    </collision>
    <collision name="body_link5_coarse_3">
      <origin rpy="-0.0 0.0 -0.0" xyz="-0.00021123886000000425 1.1920928999487046e-07 0.054496765"/>
      <geometry>
        <box size="0.15000057 0.16199994 0.11851597"/>
      </geometry>
    </collision>
  </link>
  <joint name="idx05_body_joint5" type="revolute">
    <origin rpy="0 0 0" xyz="0.00017436 0 0.14676"/>
    <parent link="body_link4"/>
    <child link="body_link5"/>
    <axis xyz="0 0 -1"/>
    <limit effort="0" lower="-3.2" upper="3.2" velocity="1"/>
  </joint>
  <!-- Arm -->
  <link name="arm_base_link"/>
  <joint name="idx20_arm_base_joint" type="fixed">
    <origin rpy="-1.5707963267948966 0 0" xyz="0.0 0.0 0.3085"/>
    <parent link="body_link5"/>
    <child link="arm_base_link"/>
    <axis xyz="0 0 0"/>
  </joint>
  <!-- Chassis -->
  <link name="chassis_link">
    <inertial>
      <origin rpy="0 0 0" xyz="-0.0018354 0.00048186 0.098072"/>
      <mass value="69.65"/>
      <inertia ixx="0.54948" ixy="-0.00025682" ixz="0.021942" iyy="0.94415" iyz="6.8345E-06" izz="1.2015"/>
    </inertial>
    <!-- <visual>
        <origin
          xyz="0 0 0"
          rpy="0 0 0" />
        <geometry>
          <mesh
            filename="${mesh_dir}/G2/chassis_link.STL" />
        </geometry>
        <material
          name="">
          <color
            rgba="0.75294 0.75294 0.75294 1" />
        </material>
      </visual>
      <collision>
        <origin
          xyz="0 0 0"
          rpy="0 0 0" />
        <geometry>
          <mesh
            filename="${mesh_dir}/G2/chassis_link.STL" />
        </geometry>
      </collision> -->
  </link>
  <link name="chassis_lwheel_front_link1">
    <inertial>
      <origin rpy="0 0 0" xyz="4.8347E-05 -0.021386 -0.055149"/>
      <mass value="0.59301"/>
      <inertia ixx="0.001129" ixy="-6.1014E-07" ixz="-1.4058E-06" iyy="0.00087934" iyz="-0.00039606" izz="0.00056331"/>
    </inertial>
    <visual>
      <origin rpy="0 0 0" xyz="0 0 0"/>
      <geometry>
        <mesh filename="package://genie_robot_description/meshes/G2/chassis_lwheel_front_link1.STL"/>
      </geometry>
      <material name="">
        <color rgba="0.86667 0.86667 0.8902 1"/>
      </material>
    </visual>
    <!-- <collision>
        <origin
          xyz="0 0 0"
          rpy="0 0 0" />
        <geometry>
          <mesh
            filename="${mesh_dir}/G2/chassis_lwheel_front_link1.STL" />
        </geometry>
      </collision> -->
  </link>
  <joint name="idx111_chassis_lwheel_front_joint1" type="revolute">
    <origin rpy="0 0 0" xyz="0.23 0.218 0.16675"/>
    <parent link="chassis_link"/>
    <child link="chassis_lwheel_front_link1"/>
    <axis xyz="0 0 1"/>
    <limit effort="10" lower="-2.97" upper="2.97" velocity="10"/>
  </joint>
  <link name="chassis_lwheel_front_link2">
    <inertial>
      <origin rpy="0 0 0" xyz="-2.3442E-06 -0.0013086 1.0892E-05"/>
      <mass value="3.6283"/>
      <inertia ixx="0.0058835" ixy="2.2411E-07" ixz="3.433E-08" iyy="0.010779" iyz="3.6966E-07" izz="0.0058842"/>
    </inertial>
    <visual>
      <origin rpy="0 0 0" xyz="0 0 0"/>
      <geometry>
        <mesh filename="package://genie_robot_description/meshes/G2/chassis_lwheel_front_link2.STL"/>
      </geometry>
      <material name="">
        <color rgba="1 1 1 1"/>
      </material>
    </visual>
    <!-- <collision>
        <origin
          xyz="0 0 0"
          rpy="${PI_2} 0 0" />
        <geometry>
          <cylinder radius="0.07" length="0.04" />
        </geometry>
      </collision> -->
  </link>
  <joint name="idx112_chassis_lwheel_front_joint2" type="continuous">
    <origin rpy="0 0 0" xyz="0 -5E-05 -0.13675"/>
    <parent link="chassis_lwheel_front_link1"/>
    <child link="chassis_lwheel_front_link2"/>
    <axis xyz="0 1 0"/>
    <limit effort="10" lower="0" upper="0" velocity="10"/>
  </joint>
  <link name="chassis_rwheel_front_link1">
    <inertial>
      <origin rpy="0 0 0" xyz="-4.8347E-05 0.021386 -0.055149"/>
      <mass value="0.59301"/>
      <inertia ixx="0.001129" ixy="-6.1014E-07" ixz="1.4058E-06" iyy="0.00087934" iyz="0.00039606" izz="0.00056331"/>
    </inertial>
    <visual>
      <origin rpy="0 0 0" xyz="0 0 0"/>
      <geometry>
        <mesh filename="package://genie_robot_description/meshes/G2/chassis_rwheel_front_link1.STL"/>
      </geometry>
      <material name="">
        <color rgba="0.86667 0.86667 0.8902 1"/>
      </material>
    </visual>
    <!-- <collision>
        <origin
          xyz="0 0 0"
          rpy="0 0 0" />
        <geometry>
          <mesh
            filename="${mesh_dir}/G2/chassis_rwheel_front_link1.STL" />
        </geometry>
      </collision> -->
  </link>
  <joint name="idx131_chassis_rwheel_front_joint1" type="revolute">
    <origin rpy="0 0 0" xyz="0.23 -0.218 0.16675"/>
    <parent link="chassis_link"/>
    <child link="chassis_rwheel_front_link1"/>
    <axis xyz="0 0 1"/>
    <limit effort="10" lower="-2.97" upper="2.97" velocity="10"/>
  </joint>
  <link name="chassis_rwheel_front_link2">
    <inertial>
      <origin rpy="0 0 0" xyz="2.3442E-06 0.0013086 1.0892E-05"/>
      <mass value="3.6283"/>
      <inertia ixx="0.0058835" ixy="2.2411E-07" ixz="-3.433E-08" iyy="0.010779" iyz="-3.6966E-07" izz="0.0058842"/>
    </inertial>
    <visual>
      <origin rpy="0 0 0" xyz="0 0 0"/>
      <geometry>
        <mesh filename="package://genie_robot_description/meshes/G2/chassis_rwheel_front_link2.STL"/>
      </geometry>
      <material name="">
        <color rgba="1 1 1 1"/>
      </material>
    </visual>
    <!-- <collision>
        <origin
          xyz="0 0 0"
          rpy="${PI_2} 0 0" />
        <geometry>
          <cylinder radius="0.07" length="0.04" />
        </geometry>
      </collision> -->
  </link>
  <joint name="idx132_chassis_rwheel_front_joint2" type="continuous">
    <origin rpy="0 0 0" xyz="0 5E-05 -0.13675"/>
    <parent link="chassis_rwheel_front_link1"/>
    <child link="chassis_rwheel_front_link2"/>
    <axis xyz="0 1 0"/>
    <limit effort="10" lower="0" upper="0" velocity="10"/>
  </joint>
  <link name="chassis_rwheel_rear_link1">
    <inertial>
      <origin rpy="0 0 0" xyz="-4.8347E-05 0.021386 -0.055149"/>
      <mass value="0.59301"/>
      <inertia ixx="0.001129" ixy="-6.1014E-07" ixz="1.4058E-06" iyy="0.00087934" iyz="0.00039606" izz="0.00056331"/>
    </inertial>
    <visual>
      <origin rpy="0 0 0" xyz="0 0 0"/>
      <geometry>
        <mesh filename="package://genie_robot_description/meshes/G2/chassis_rwheel_rear_link1.STL"/>
      </geometry>
      <material name="">
        <color rgba="0.86667 0.86667 0.8902 1"/>
      </material>
    </visual>
    <!-- <collision>
        <origin
          xyz="0 0 0"
          rpy="0 0 0" />
        <geometry>
          <mesh
            filename="${mesh_dir}/G2/chassis_rwheel_rear_link1.STL" />
        </geometry>
      </collision> -->
  </link>
  <joint name="idx141_chassis_rwheel_rear_joint1" type="revolute">
    <origin rpy="0 0 0" xyz="-0.23 -0.218 0.16675"/>
    <parent link="chassis_link"/>
    <child link="chassis_rwheel_rear_link1"/>
    <axis xyz="0 0 1"/>
    <limit effort="10" lower="-2.97" upper="2.97" velocity="10"/>
  </joint>
  <link name="chassis_rwheel_rear_link2">
    <inertial>
      <origin rpy="0 0 0" xyz="2.3442E-06 0.0013086 1.0892E-05"/>
      <mass value="3.6283"/>
      <inertia ixx="0.0058835" ixy="2.2411E-07" ixz="-3.433E-08" iyy="0.010779" iyz="-3.6966E-07" izz="0.0058842"/>
    </inertial>
    <visual>
      <origin rpy="0 0 0" xyz="0 0 0"/>
      <geometry>
        <mesh filename="package://genie_robot_description/meshes/G2/chassis_rwheel_rear_link2.STL"/>
      </geometry>
      <material name="">
        <color rgba="1 1 1 1"/>
      </material>
    </visual>
    <!-- <collision>
        <origin
          xyz="0 0 0"
          rpy="${PI_2} 0 0" />
        <geometry>
          <cylinder radius="0.07" length="0.04" />
        </geometry>
      </collision> -->
  </link>
  <joint name="idx142_chassis_rwheel_rear_joint2" type="continuous">
    <origin rpy="0 0 0" xyz="0 5E-05 -0.13675"/>
    <parent link="chassis_rwheel_rear_link1"/>
    <child link="chassis_rwheel_rear_link2"/>
    <axis xyz="0 1 0"/>
    <limit effort="10" lower="0" upper="0" velocity="10"/>
  </joint>
  <link name="chassis_lwheel_rear_link1">
    <inertial>
      <origin rpy="0 0 0" xyz="4.8347E-05 -0.021386 -0.055149"/>
      <mass value="0.59301"/>
      <inertia ixx="0.001129" ixy="-6.1014E-07" ixz="-1.4058E-06" iyy="0.00087934" iyz="-0.00039606" izz="0.00056331"/>
    </inertial>
    <visual>
      <origin rpy="0 0 0" xyz="0 0 0"/>
      <geometry>
        <mesh filename="package://genie_robot_description/meshes/G2/chassis_lwheel_rear_link1.STL"/>
      </geometry>
      <material name="">
        <color rgba="0.86667 0.86667 0.8902 1"/>
      </material>
    </visual>
    <!-- <collision>
        <origin
          xyz="0 0 0"
          rpy="0 0 0" />
        <geometry>
          <mesh
            filename="${mesh_dir}/G2/chassis_lwheel_rear_link1.STL" />
        </geometry>
      </collision> -->
  </link>
  <joint name="idx121_chassis_lwheel_rear_joint1" type="revolute">
    <origin rpy="0 0 0" xyz="-0.23 0.218 0.16675"/>
    <parent link="chassis_link"/>
    <child link="chassis_lwheel_rear_link1"/>
    <axis xyz="0 0 1"/>
    <limit effort="10" lower="-2.97" upper="2.97" velocity="10"/>
  </joint>
  <link name="chassis_lwheel_rear_link2">
    <inertial>
      <origin rpy="0 0 0" xyz="-2.3442E-06 -0.0013086 1.0892E-05"/>
      <mass value="3.6283"/>
      <inertia ixx="0.0058835" ixy="2.2411E-07" ixz="3.433E-08" iyy="0.010779" iyz="3.6966E-07" izz="0.0058842"/>
    </inertial>
    <visual>
      <origin rpy="0 0 0" xyz="0 0 0"/>
      <geometry>
        <mesh filename="package://genie_robot_description/meshes/G2/chassis_lwheel_rear_link2.STL"/>
      </geometry>
      <material name="">
        <color rgba="1 1 1 1"/>
      </material>
    </visual>
    <!-- <collision>
        <origin
          xyz="0 0 0"
          rpy="${PI_2} 0 0" />
        <geometry>
          <cylinder radius="0.07" length="0.04" />
        </geometry>
      </collision> -->
  </link>
  <joint name="idx122_chassis_lwheel_rear_joint2" type="continuous">
    <origin rpy="0 0 0" xyz="0 -5E-05 -0.13675"/>
    <parent link="chassis_lwheel_rear_link1"/>
    <child link="chassis_lwheel_rear_link2"/>
    <axis xyz="0 1 0"/>
    <limit effort="10" lower="0" upper="0" velocity="10"/>
  </joint>
  <joint name="idx100_chassis_base_joint" type="fixed">
    <origin rpy="0 0 0" xyz="0 0 0"/>
    <parent link="base_link"/>
    <child link="chassis_link"/>
  </joint>
  <!-- Head -->
  <link name="head_base_link"/>
  <joint name="idx10_head_base_joint" type="fixed">
    <origin rpy="0 0 0" xyz="-0.013211 0 0.35976"/>
    <parent link="body_link5"/>
    <child link="head_base_link"/>
    <axis xyz="0 0 0"/>
  </joint>
  <link name="head_link1">
    <inertial>
      <origin rpy="0 0 0" xyz="0.0049863 1.3573E-09 0.13188"/>
      <mass value="0.29497"/>
      <inertia ixx="0.000842" ixy="0" ixz="-0.000128" iyy="0.00087" iyz="0" izz="0.000126"/>
    </inertial>
    <visual>
      <origin rpy="0 0 0" xyz="0 0 0"/>
      <geometry>
        <mesh filename="package://genie_robot_description/meshes/G2/T1/head_link1.STL"/>
      </geometry>
      <material name="white"/>
    </visual>
    <collision name="head_link1_coarse_0">
      <origin rpy="-0.0 0.0 -0.0" xyz="-0.0008687973000000015 0.00011444092000000017 0.08756709"/>
      <geometry>
        <box size="0.053949356 0.052459717 0.10913419999999999"/>
      </geometry>
    </collision>
    <collision name="head_link1_coarse_1">
      <origin rpy="-0.0 0.0 -0.0" xyz="0.0298028 -0.0004730224599999999 0.17724355"/>
      <geometry>
        <box size="0.029593468000000005 0.05860901 0.06831196"/>
      </geometry>
    </collision>
  </link>
  <joint name="idx11_head_joint1" type="revolute">
    <origin rpy="0 0 0" xyz="0 0 0"/>
    <parent link="head_base_link"/>
    <child link="head_link1"/>
    <axis xyz="0 0 1"/>
    <limit effort="0" lower="-3.14" upper="3.14" velocity="1"/>
  </joint>
  <link name="head_link2">
    <inertial>
      <origin rpy="0 0 0" xyz="-0.031307 -0.0003235 -0.00019793"/>
      <mass value="0.34548"/>
      <inertia ixx="0.000179" ixy="-3E-06" ixz="-1E-06" iyy="0.000146" iyz="0" izz="0.000189"/>
    </inertial>
    <visual>
      <origin rpy="0 0 0" xyz="0 0 0"/>
      <geometry>
        <mesh filename="package://genie_robot_description/meshes/G2/T1/head_link2.STL"/>
      </geometry>
      <material name="white"/>
    </visual>
    <collision name="head_link2_coarse_0">
      <origin rpy="-0.0 0.0 -0.0" xyz="-0.012349606 -0.04070282 0.0040000677"/>
      <geometry>
        <box size="0.012000083999999998 0.016403198000000008 0.01699996"/>
      </geometry>
    </collision>
    <collision name="head_link2_coarse_1">
      <origin rpy="-0.0 0.0 -0.0" xyz="-0.027349949 0.0 5.066394800000082e-05"/>
      <geometry>
        <box size="0.06199932 0.06500244 0.05789876"/>
      </geometry>
    </collision>
  </link>
  <joint name="idx12_head_joint2" type="revolute">
    <origin rpy="0 0 0" xyz="0.029814 0 0.21419"/>
    <parent link="head_link1"/>
    <child link="head_link2"/>
    <axis xyz="-1 0 0"/>
    <limit effort="0" lower="-0.35" upper="0.35" velocity="1"/>
  </joint>
  <link name="head_link3">
    <inertial>
      <origin rpy="0 0 0" xyz="0.031207 -0.002346 0.034439"/>
      <mass value="1.88"/>
      <inertia ixx="0.006816" ixy="-0.000139" ixz="0.002671" iyy="0.009005" iyz="0.000143" izz="0.00568"/>
    </inertial>
    <visual>
      <origin rpy="0 0 0" xyz="0 0 0"/>
      <geometry>
        <mesh filename="package://genie_robot_description/meshes/G2/T1/head_link3.STL"/>
      </geometry>
      <material name="white"/>
    </visual>
    <collision name="head_link3_coarse_0">
      <origin rpy="-0.0 0.0 -0.0" xyz="-0.013225079 -0.002861023000000004 0.11197662"/>
      <geometry>
        <box size="0.13921642 0.15089417 0.030090331999999997"/>
      </geometry>
    </collision>
    <collision name="head_link3_coarse_1">
      <origin rpy="-0.0 0.0 -0.0" xyz="0.08184695 -0.004905700700000001 -0.027374268"/>
      <geometry>
        <box size="0.05158186000000001 0.1085968 0.052001953000000004"/>
      </geometry>
    </collision>
    <collision name="head_link3_coarse_2">
      <origin rpy="-0.0 0.0 -0.0" xyz="0.034275055 -0.0023956299000000014 0.04024887"/>
      <geometry>
        <box size="0.14655018 0.12200928 0.10849762"/>
      </geometry>
    </collision>
  </link>
  <joint name="idx13_head_joint3" type="revolute">
    <origin rpy="0 0 0" xyz="-0.029814 0 -0.00019325"/>
    <parent link="head_link2"/>
    <child link="head_link3"/>
    <axis xyz="0 1 0"/>
    <limit effort="0" lower="-0.52" upper="0.52" velocity="1"/>
  </joint>
  <!-- properties -->
  <!-- Arm -->
  <link name="arm_l_link1">
    <inertial>
      <origin rpy="0 0 0" xyz="1.875E-05 0.006003 0.1438"/>
      <mass value="2.0926"/>
      <inertia ixx="0.0485" ixy="2.85E-06" ixz="9.42E-06" iyy="0.048824" iyz="0.0021904" izz="0.0020558"/>
    </inertial>
    <visual name="">
      <geometry>
        <mesh filename="package://genie_robot_description/meshes/arms/Link1_P6.STL"/>
      </geometry>
      <origin rpy="0 0 0" xyz="0 0 0"/>
      <material name="default"/>
    </visual>
    <collision name="arm_l_link1_coarse_0">
      <origin rpy="-0.0 0.0 -0.0" xyz="-0.0004959106400000004 -1.945484272123522e-19 0.17853164999999982"/>
      <geometry>
        <sphere radius="0.06300305"/>
      </geometry>
    </collision>
    <collision name="arm_l_link1_coarse_1">
      <origin rpy="-0.0 0.0 -0.0" xyz="-0.009067535000000005 -0.004526614999999998 0.12142944"/>
      <geometry>
        <sphere radius="0.06310095999999998"/>
      </geometry>
    </collision>
  </link>
  <joint name="idx21_arm_l_joint1" type="revolute">
    <origin rpy="0 0 0" xyz="0 0 0.069"/>
    <parent link="arm_base_link"/>
    <child link="arm_l_link1"/>
    <axis xyz="0 0 1"/>
    <limit effort="108" lower="-3.1067" upper="3.1067" velocity="3.1416"/>
  </joint>
  <link name="arm_l_link2">
    <inertial>
      <origin rpy="0 0 0" xyz="-7.03E-06 0.05542 0.010995"/>
      <mass value="1.9432"/>
      <inertia ixx="0.016558" ixy="-6.34E-06" ixz="1.91E-06" iyy="0.0033963" iyz="-6.31E-06" izz="0.015504"/>
    </inertial>
    <visual name="">
      <geometry>
        <mesh filename="package://genie_robot_description/meshes/arms/Link2_P6.STL"/>
      </geometry>
      <origin rpy="0 0 0" xyz="0 0 0"/>
      <material name="default"/>
    </visual>
    <collision name="arm_l_link2_coarse_0">
      <origin rpy="-0.0 0.0 -0.0" xyz="-0.004974365200000007 0.006954193000000001 -0.01338499999999954"/>
      <geometry>
        <sphere radius="0.07498259999999999"/>
      </geometry>
    </collision>
    <collision name="arm_l_link2_coarse_1">
      <origin rpy="-0.0 0.0 -0.0" xyz="-0.004501343000000002 0.0072174069999999925 0.01335839199999999"/>
      <geometry>
        <sphere radius="0.074983405"/>
      </geometry>
    </collision>
    <collision name="arm_l_link2_coarse_2">
      <origin rpy="-0.0 0.0 -0.0" xyz="0.0010223389000000094 0.1094703699999999 0.0012550354000000002"/>
      <geometry>
        <sphere radius="0.06165532800000009"/>
      </geometry>
    </collision>
  </link>
  <joint name="idx22_arm_l_joint2" type="revolute">
    <origin rpy="1.5708 0 0" xyz="0 0 0.1745"/>
    <parent link="arm_l_link1"/>
    <child link="arm_l_link2"/>
    <axis xyz="0 0 1"/>
    <limit effort="108" lower="-2.0944" upper="2.0944" velocity="3.1416"/>
  </joint>
  <link name="arm_l_link3">
    <inertial>
      <origin rpy="0 0 0" xyz="0.0087411 0.0019043 0.23487"/>
      <mass value="1.6913"/>
      <inertia ixx="0.099807" ixy="6.153E-05" ixz="0.0042654" iyy="0.10032" iyz="0.0009332" izz="0.0017797"/>
    </inertial>
    <visual name="">
      <geometry>
        <mesh filename="package://genie_robot_description/meshes/arms/Link3_P6.STL"/>
      </geometry>
      <origin rpy="0 0 0" xyz="0 0 0"/>
      <material name="default"/>
    </visual>
    <!-- <collision name="arm_l_link3_coarse_0">
          <geometry>
            <sphere radius="0.073823" />
          </geometry>
          <origin xyz="-0.002493036787214638 -0.0 0.19334736154660487"
            rpy="0.0 -0.0 0.0" />
        </collision>
        <collision name="arm_l_link3_coarse_1">
          <geometry>
            <sphere radius="0.070649" />
          </geometry>
          <origin xyz="0.015268963212785362 0.0 0.26469536154660483"
            rpy="0.0 -0.0 0.0" />
        </collision> -->
    <collision name="arm_l_link3_coarse_0">
      <origin rpy="-0.0 0.0 -0.0" xyz="0.0007324219000000129 -0.00011956971000000159 0.19502639999999993"/>
      <geometry>
        <sphere radius="0.06603523000000001"/>
      </geometry>
    </collision>
    <collision name="arm_l_link3_coarse_1">
      <origin rpy="-0.0 0.0 -0.0" xyz="0.01489257800000002 -0.001605738900000001 0.2844047500000005"/>
      <geometry>
        <sphere radius="0.061628755000000014"/>
      </geometry>
    </collision>
  </link>
  <joint name="idx23_arm_l_joint3" type="revolute">
    <origin rpy="-1.5708 0 0" xyz="0 0 0"/>
    <parent link="arm_l_link2"/>
    <child link="arm_l_link3"/>
    <axis xyz="0 0 1"/>
    <limit effort="66" lower="-3.1067" upper="3.1067" velocity="3.1416"/>
  </joint>
  <link name="arm_l_link4">
    <inertial>
      <origin rpy="0 0 0" xyz="-0.0086935 0.045984 0.011135"/>
      <mass value="1.5332"/>
      <inertia ixx="0.0087075" ixy="-0.0012304" ixz="-1.947E-05" iyy="0.0023918" iyz="9.793E-05" izz="0.0082548"/>
    </inertial>
    <visual name="">
      <geometry>
        <mesh filename="package://genie_robot_description/meshes/arms/Link4_P6.STL"/>
      </geometry>
      <origin rpy="0 0 0" xyz="0 0 0"/>
      <material name="default"/>
    </visual>
    <collision name="arm_l_link4_coarse_0">
      <origin rpy="-0.0 0.0 -0.0" xyz="-0.003173828099999999 0.004589356499999994 -0.011833649999999894"/>
      <geometry>
        <sphere radius="0.06991342"/>
      </geometry>
    </collision>
    <collision name="arm_l_link4_coarse_1">
      <origin rpy="-0.0 0.0 -0.0" xyz="-0.004821777299999992 0.004589356499999994 0.011815094000000035"/>
      <geometry>
        <sphere radius="0.069075850000000004"/>
      </geometry>
    </collision>
    <collision name="arm_l_link4_coarse_2">
      <origin rpy="-0.0 0.0 -0.0" xyz="-0.012329101999999996 0.09249994000000004 0.003940582300000001"/>
      <geometry>
        <sphere radius="0.05453134999999996"/>
      </geometry>
    </collision>
  </link>
  <joint name="idx24_arm_l_joint4" type="revolute">
    <origin rpy="1.5708 0 0" xyz="0.018 0 0.287"/>
    <parent link="arm_l_link3"/>
    <child link="arm_l_link4"/>
    <axis xyz="0 0 1"/>
    <limit effort="66" lower="-2.5307" upper="1.0472" velocity="3.1416"/>
  </joint>
  <link name="arm_l_link5">
    <inertial>
      <origin rpy="0 0 0" xyz="-0.00036467 0.0001479 0.19902"/>
      <mass value="2.0095"/>
      <inertia ixx="0.08529" ixy="-3.491E-05" ixz="-0.0001918" iyy="0.084873" iyz="8.319E-05" izz="0.0021133"/>
    </inertial>
    <visual name="">
      <geometry>
        <mesh filename="package://genie_robot_description/meshes/arms/Link5_P6.STL"/>
      </geometry>
      <origin rpy="0 0 0" xyz="0 0 0"/>
      <material name="default"/>
    </visual>
    <collision name="arm_l_link5_coarse_0">
      <origin rpy="-0.0 0.0 -0.0" xyz="0.001464843800000002 0.02441250000000014 0.217128723000000035"/>
      <geometry>
        <sphere radius="0.0521019999999999"/>
      </geometry>
    </collision>
    <collision name="arm_l_link5_coarse_1">
      <origin rpy="-0.0 0.0 -0.0" xyz="-0.0015869140999999996 -0.02448128500000002 0.21791775999999984"/>
      <geometry>
        <sphere radius="0.05214000000001"/>
      </geometry>
    </collision>
    <collision name="arm_l_link5_coarse_2">
      <origin rpy="-0.0 0.0 -0.0" xyz="0.001464843800000002 0.02841250000000014 0.287128723000000035"/>
      <geometry>
        <sphere radius="0.0521019999999999"/>
      </geometry>
    </collision>
    <collision name="arm_l_link5_coarse_3">
      <origin rpy="-0.0 0.0 -0.0" xyz="-0.0015869140999999996 -0.02848128500000002 0.2891775999999984"/>
      <geometry>
        <sphere radius="0.05214000000001"/>
      </geometry>
    </collision>
    <collision name="arm_l_link5_coarse_4">
      <origin rpy="-0.0 0.0 -0.0" xyz="-0.0009765625000000072 0.0031794570000000027 0.1568145800000001"/>
      <geometry>
        <sphere radius="0.05447049"/>
      </geometry>
    </collision>
  </link>
  <joint name="idx25_arm_l_joint5" type="revolute">
    <origin rpy="-1.5708 0 0" xyz="-0.018 0 0"/>
    <parent link="arm_l_link4"/>
    <child link="arm_l_link5"/>
    <axis xyz="0 0 1"/>
    <limit effort="18" lower="-3.1067" upper="3.1067" velocity="3.1416"/>
  </joint>
  <link name="arm_l_link6">
    <inertial>
      <origin rpy="0 0 0" xyz="-0.004911 0.00027206 -8.14E-05"/>
      <mass value="0.67002"/>
      <inertia ixx="0.00048938" ixy="-2.3E-06" ixz="2.16E-06" iyy="0.0004162" iyz="6.3E-07" izz="0.00038542"/>
    </inertial>
    <visual name="">
      <geometry>
        <mesh filename="package://genie_robot_description/meshes/arms/Link6_P6.STL"/>
      </geometry>
      <origin rpy="0 0 0" xyz="0 0 0"/>
      <material name="default"/>
    </visual>
    <collision name="arm_l_link6_coarse_0">
      <origin rpy="-0.0 0.0 -0.0" xyz="1.4374967121801579e-18 -1.7293193529986862e-19 5.755390971698752e-19"/>
      <geometry>
        <sphere radius="0.052349735"/>
      </geometry>
    </collision>
  </link>
  <joint name="idx26_arm_l_joint6" type="revolute">
    <origin rpy="1.5708 0 0" xyz="0 0 0.314"/>
    <parent link="arm_l_link5"/>
    <child link="arm_l_link6"/>
    <axis xyz="0 0 1"/>
    <limit effort="18" lower="-1.0472" upper="1.0472" velocity="3.1416"/>
  </joint>
  <link name="arm_l_link7">
    <inertial>
      <origin rpy="0 0 0" xyz="0.044988 -4.226E-05 0.0055581"/>
      <mass value="0.31658"/>
      <inertia ixx="0.00038289" ixy="-7.4E-07" ixz="-1.403E-05" iyy="0.00133" iyz="-6.1E-07" izz="0.0011774"/>
    </inertial>
    <visual name="">
      <geometry>
        <mesh filename="package://genie_robot_description/meshes/arms/Link7_P6.STL"/>
      </geometry>
      <origin rpy="0 0 0" xyz="0 0 0"/>
      <material name="default"/>
    </visual>
    <collision name="arm_l_link7_coarse_0">
      <origin rpy="-0.0 0.0 -0.0" xyz="0.05914825400000002 0.0 0.0"/>
      <geometry>
        <sphere radius="0.04457995700000001"/>
      </geometry>
    </collision>
    <collision name="arm_l_link7_coarse_1">
      <origin rpy="-0.0 0.0 -0.0" xyz="0.0 0.0 0.02"/>
      <geometry>
        <sphere radius="0.04457995700000001"/>
      </geometry>
    </collision>
    <collision name="arm_l_link7_coarse_2">
      <origin rpy="-0.0 0.0 -0.0" xyz="0.0 0.0 -0.02"/>
      <geometry>
        <sphere radius="0.04457995700000001"/>
      </geometry>
    </collision>
  </link>
  <joint name="idx27_arm_l_joint7" type="revolute">
    <origin rpy="1.5708 0 1.5708" xyz="0 0 0"/>
    <parent link="arm_l_link6"/>
    <child link="arm_l_link7"/>
    <axis xyz="0 0 1"/>
    <limit effort="18" lower="-1.5708" upper="1.5708" velocity="3.1416"/>
  </joint>
  <link name="arm_l_end_link"/>
  <joint name="arm_l_end_joint" type="fixed">
    <origin rpy="3.1416 -1.5708 0" xyz="0.088 0.0 0.0"/>
    <parent link="arm_l_link7"/>
    <child link="arm_l_end_link"/>
  </joint>
  <!-- properties -->
  <!-- Arm -->
  <link name="arm_r_link1">
    <inertial>
      <origin rpy="0 0 0" xyz="1.875E-05 0.006003 0.1438"/>
      <mass value="2.0926"/>
      <inertia ixx="0.0485" ixy="2.85E-06" ixz="9.42E-06" iyy="0.048824" iyz="0.0021904" izz="0.0020558"/>
    </inertial>
    <visual name="">
      <geometry>
        <mesh filename="package://genie_robot_description/meshes/arms/Link1_P6.STL"/>
      </geometry>
      <origin rpy="0 0 0" xyz="0 0 0"/>
      <material name="default"/>
    </visual>
    <collision name="arm_r_link1_coarse_0">
      <origin rpy="-0.0 0.0 -0.0" xyz="-0.0004959106400000004 -1.945484272123522e-19 0.17853164999999982"/>
      <geometry>
        <sphere radius="0.06300305"/>
      </geometry>
    </collision>
    <collision name="arm_r_link1_coarse_1">
      <origin rpy="-0.0 0.0 -0.0" xyz="-0.009067535000000005 -0.004526614999999998 0.12142944"/>
      <geometry>
        <sphere radius="0.06310095999999998"/>
      </geometry>
    </collision>
  </link>
  <joint name="idx61_arm_r_joint1" type="revolute">
    <origin rpy="3.141592653589793 0 0" xyz="0 0 -0.069"/>
    <parent link="arm_base_link"/>
    <child link="arm_r_link1"/>
    <axis xyz="0 0 1"/>
    <limit effort="108" lower="-3.1067" upper="3.1067" velocity="3.1416"/>
  </joint>
  <link name="arm_r_link2">
    <inertial>
      <origin rpy="0 0 0" xyz="-7.03E-06 0.05542 0.010995"/>
      <mass value="1.9432"/>
      <inertia ixx="0.016558" ixy="-6.34E-06" ixz="1.91E-06" iyy="0.0033963" iyz="-6.31E-06" izz="0.015504"/>
    </inertial>
    <visual name="">
      <geometry>
        <mesh filename="package://genie_robot_description/meshes/arms/Link2_P6.STL"/>
      </geometry>
      <origin rpy="0 0 0" xyz="0 0 0"/>
      <material name="default"/>
    </visual>
    <collision name="arm_r_link2_coarse_0">
      <origin rpy="-0.0 0.0 -0.0" xyz="-0.004974365200000007 0.006954193000000001 -0.01338499999999954"/>
      <geometry>
        <sphere radius="0.07498259999999999"/>
      </geometry>
    </collision>
    <collision name="arm_r_link2_coarse_1">
      <origin rpy="-0.0 0.0 -0.0" xyz="-0.004501343000000002 0.0072174069999999925 0.01335839199999999"/>
      <geometry>
        <sphere radius="0.074983405"/>
      </geometry>
    </collision>
    <collision name="arm_r_link2_coarse_2">
      <origin rpy="-0.0 0.0 -0.0" xyz="0.0010223389000000094 0.1094703699999999 0.0012550354000000002"/>
      <geometry>
        <sphere radius="0.06165532800000009"/>
      </geometry>
    </collision>
  </link>
  <joint name="idx62_arm_r_joint2" type="revolute">
    <origin rpy="1.5707963267948966 0 0" xyz="0 0 0.1745"/>
    <parent link="arm_r_link1"/>
    <child link="arm_r_link2"/>
    <axis xyz="0 0 1"/>
    <limit effort="108" lower="-2.0944" upper="2.0944" velocity="3.1416"/>
  </joint>
  <link name="arm_r_link3">
    <inertial>
      <origin rpy="0 0 0" xyz="0.0087411 0.0019043 0.23487"/>
      <mass value="1.6913"/>
      <inertia ixx="0.099807" ixy="6.153E-05" ixz="0.0042654" iyy="0.10032" iyz="0.0009332" izz="0.0017797"/>
    </inertial>
    <visual name="">
      <geometry>
        <mesh filename="package://genie_robot_description/meshes/arms/Link3_P6.STL"/>
      </geometry>
      <origin rpy="0 0 0" xyz="0 0 0"/>
      <material name="default"/>
    </visual>
    <collision name="arm_r_link3_coarse_0">
      <origin rpy="-0.0 0.0 -0.0" xyz="0.0007324219000000129 -0.00011956971000000159 0.19502639999999993"/>
      <geometry>
        <sphere radius="0.06603523000000001"/>
      </geometry>
    </collision>
    <collision name="arm_r_link3_coarse_1">
      <origin rpy="-0.0 0.0 -0.0" xyz="0.01489257800000002 -0.001605738900000001 0.2844047500000005"/>
      <geometry>
        <sphere radius="0.061628755000000014"/>
      </geometry>
    </collision>
  </link>
  <joint name="idx63_arm_r_joint3" type="revolute">
    <origin rpy="-1.5707963267948966 0 0" xyz="0 0 0"/>
    <parent link="arm_r_link2"/>
    <child link="arm_r_link3"/>
    <axis xyz="0 0 1"/>
    <limit effort="66" lower="-3.1067" upper="3.1067" velocity="3.1416"/>
  </joint>
  <link name="arm_r_link4">
    <inertial>
      <origin rpy="0 0 0" xyz="-0.0086935 0.045984 0.011135"/>
      <mass value="1.5332"/>
      <inertia ixx="0.0087075" ixy="-0.0012304" ixz="-1.947E-05" iyy="0.0023918" iyz="9.793E-05" izz="0.0082548"/>
    </inertial>
    <visual name="">
      <geometry>
        <mesh filename="package://genie_robot_description/meshes/arms/Link4_P6.STL"/>
      </geometry>
      <origin rpy="0 0 0" xyz="0 0 0"/>
      <material name="default"/>
    </visual>
    <collision name="arm_r_link4_coarse_0">
      <origin rpy="-0.0 0.0 -0.0" xyz="-0.003173828099999999 0.004589356499999994 -0.011833649999999894"/>
      <geometry>
        <sphere radius="0.06991342"/>
      </geometry>
    </collision>
    <collision name="arm_r_link4_coarse_1">
      <origin rpy="-0.0 0.0 -0.0" xyz="-0.004821777299999992 0.004589356499999994 0.011815094000000035"/>
      <geometry>
        <sphere radius="0.069075850000000004"/>
      </geometry>
    </collision>
    <collision name="arm_r_link4_coarse_2">
      <origin rpy="-0.0 0.0 -0.0" xyz="-0.012329101999999996 0.09249994000000004 0.003940582300000001"/>
      <geometry>
        <sphere radius="0.05453134999999996"/>
      </geometry>
    </collision>
  </link>
  <joint name="idx64_arm_r_joint4" type="revolute">
    <origin rpy="1.5707963267948966 0 0" xyz="0.018 0 0.287"/>
    <parent link="arm_r_link3"/>
    <child link="arm_r_link4"/>
    <axis xyz="0 0 1"/>
    <limit effort="66" lower="-2.5307" upper="1.0472" velocity="3.1416"/>
  </joint>
  <link name="arm_r_link5">
    <inertial>
      <origin rpy="0 0 0" xyz="-0.00036467 0.0001479 0.19902"/>
      <mass value="2.0095"/>
      <inertia ixx="0.08529" ixy="-3.491E-05" ixz="-0.0001918" iyy="0.084873" iyz="8.319E-05" izz="0.0021133"/>
    </inertial>
    <visual name="">
      <geometry>
        <mesh filename="package://genie_robot_description/meshes/arms/Link5_P6.STL"/>
      </geometry>
      <origin rpy="0 0 0" xyz="0 0 0"/>
      <material name="default"/>
    </visual>
    <collision name="arm_r_link5_coarse_0">
      <origin rpy="-0.0 0.0 -0.0" xyz="0.001464843800000002 0.02441250000000014 0.217128723000000035"/>
      <geometry>
        <sphere radius="0.0521019999999999"/>
      </geometry>
    </collision>
    <collision name="arm_r_link5_coarse_1">
      <origin rpy="-0.0 0.0 -0.0" xyz="-0.0015869140999999996 -0.02448128500000002 0.21791775999999984"/>
      <geometry>
        <sphere radius="0.05214000000001"/>
      </geometry>
    </collision>
    <collision name="arm_r_link5_coarse_2">
      <origin rpy="-0.0 0.0 -0.0" xyz="0.001464843800000002 0.02841250000000014 0.287128723000000035"/>
      <geometry>
        <sphere radius="0.0521019999999999"/>
      </geometry>
    </collision>
    <collision name="arm_r_link5_coarse_3">
      <origin rpy="-0.0 0.0 -0.0" xyz="-0.0015869140999999996 -0.02848128500000002 0.2891775999999984"/>
      <geometry>
        <sphere radius="0.05214000000001"/>
      </geometry>
    </collision>
    <collision name="arm_r_link5_coarse_4">
      <origin rpy="-0.0 0.0 -0.0" xyz="-0.0009765625000000072 0.0031794570000000027 0.1568145800000001"/>
      <geometry>
        <sphere radius="0.05447049"/>
      </geometry>
    </collision>
  </link>
  <joint name="idx65_arm_r_joint5" type="revolute">
    <origin rpy="-1.5707963267948966 0 0" xyz="-0.018 0 0"/>
    <parent link="arm_r_link4"/>
    <child link="arm_r_link5"/>
    <axis xyz="0 0 1"/>
    <limit effort="18" lower="-3.1067" upper="3.1067" velocity="3.1416"/>
  </joint>
  <link name="arm_r_link6">
    <inertial>
      <origin rpy="0 0 0" xyz="-0.004911 0.00027206 -8.14E-05"/>
      <mass value="0.67002"/>
      <inertia ixx="0.00048938" ixy="-2.3E-06" ixz="2.16E-06" iyy="0.0004162" iyz="6.3E-07" izz="0.00038542"/>
    </inertial>
    <visual name="">
      <geometry>
        <mesh filename="package://genie_robot_description/meshes/arms/Link6_P6.STL"/>
      </geometry>
      <origin rpy="0 0 0" xyz="0 0 0"/>
      <material name="default"/>
    </visual>
    <collision name="arm_r_link6_coarse_0">
      <origin rpy="-0.0 0.0 -0.0" xyz="1.4374967121801579e-18 -1.7293193529986862e-19 5.755390971698752e-19"/>
      <geometry>
        <sphere radius="0.052349735"/>
      </geometry>
    </collision>
  </link>
  <joint name="idx66_arm_r_joint6" type="revolute">
    <origin rpy="1.5707963267948966 0 0" xyz="0 0 0.314"/>
    <parent link="arm_r_link5"/>
    <child link="arm_r_link6"/>
    <axis xyz="0 0 1"/>
    <limit effort="18" lower="-1.0472" upper="1.0472" velocity="3.1416"/>
  </joint>
  <link name="arm_r_link7">
    <inertial>
      <origin rpy="0 0 0" xyz="0.044988 -4.226E-05 0.0055581"/>
      <mass value="0.31658"/>
      <inertia ixx="0.00038289" ixy="-7.4E-07" ixz="-1.403E-05" iyy="0.00133" iyz="-6.1E-07" izz="0.0011774"/>
    </inertial>
    <visual name="">
      <geometry>
        <mesh filename="package://genie_robot_description/meshes/arms/Link7_P6.STL"/>
      </geometry>
      <origin rpy="0 0 0" xyz="0 0 0"/>
      <material name="default"/>
    </visual>
    <collision name="arm_r_link7_coarse_0">
      <origin rpy="-0.0 0.0 -0.0" xyz="0.05914825400000002 0.0 0.0"/>
      <geometry>
        <sphere radius="0.04457995700000001"/>
      </geometry>
    </collision>
    <collision name="arm_r_link7_coarse_1">
      <origin rpy="-0.0 0.0 -0.0" xyz="0.0 0.0 0.02"/>
      <geometry>
        <sphere radius="0.04457995700000001"/>
      </geometry>
    </collision>
    <collision name="arm_r_link7_coarse_2">
      <origin rpy="-0.0 0.0 -0.0" xyz="0.0 0.0 -0.02"/>
      <geometry>
        <sphere radius="0.04457995700000001"/>
      </geometry>
    </collision>
  </link>
  <link name="arm_r_end_link"/>
  <joint name="idx67_arm_r_joint7" type="revolute">
    <origin rpy="1.5707963267948966 0 1.5707963267948966" xyz="0 0 0"/>
    <parent link="arm_r_link6"/>
    <child link="arm_r_link7"/>
    <axis xyz="0 0 1"/>
    <limit effort="18" lower="-1.5708" upper="1.5708" velocity="3.1416"/>
  </joint>
  <joint name="arm_r_end_joint" type="fixed">
    <origin rpy="3.141592653589793 -1.5707963267948966 0" xyz="0.088 0.0 0.0"/>
    <parent link="arm_r_link7"/>
    <child link="arm_r_end_link"/>
  </joint>
  <!-- Gripper L-->
  <link name="gripper_l_base_link">
    <inertial>
      <origin rpy="0 0 0" xyz="-0.00013356 1.5301E-05 0.03322"/>
      <mass value="0.23588"/>
      <inertia ixx="8.1548E-05" ixy="-1.2617E-08" ixz="-2.05E-07" iyy="5.6921E-05" iyz="6.6903E-08" izz="7.1611E-05"/>
    </inertial>
    <visual>
      <origin rpy="0 0 0" xyz="0 0 0"/>
      <geometry>
        <mesh filename="package://genie_robot_description/meshes/omnipicker/gripper_base_link.dae"/>
      </geometry>
      <!-- <material name="white" /> -->
    </visual>
    <collision>
      <origin rpy="0 0 0" xyz="0 0 0"/>
      <geometry>
        <mesh filename="package://genie_robot_description/meshes/omnipicker/gripper_base_link.dae"/>
      </geometry>
    </collision>
  </link>
  <link name="gripper_l_inner_link1">
    <inertial>
      <origin rpy="0 0 0" xyz="0.0094685 0.0068806 6.5437E-05"/>
      <mass value="0.025428"/>
      <inertia ixx="1.9574E-06" ixy="-4.2911E-07" ixz="-3.7111E-11" iyy="2.3919E-06" iyz="-3.008E-10" izz="1.5501E-06"/>
    </inertial>
    <visual>
      <origin rpy="0 0 0" xyz="0 0 0"/>
      <geometry>
        <mesh filename="package://genie_robot_description/meshes/omnipicker/inner_link1.dae"/>
      </geometry>
      <!-- <material name="orange" /> -->
    </visual>
    <collision>
      <origin rpy="0 0 0" xyz="0 0 0"/>
      <geometry>
        <mesh filename="package://genie_robot_description/meshes/omnipicker/inner_link1.dae"/>
      </geometry>
    </collision>
  </link>
  <joint name="idx31_gripper_l_inner_joint1" type="revolute">
    <origin rpy="-2.9951 -1.5707963267948966 -0.15964" xyz="0 -0.0195 0.0565"/>
    <parent link="gripper_l_base_link"/>
    <child link="gripper_l_inner_link1"/>
    <axis xyz="0 0 -1"/>
    <limit effort="10" lower="-0.7853981633974483" upper="0" velocity="10"/>
    <mimic joint="idx41_gripper_l_outer_joint1" multiplier="-1" offset="0"/>
  </joint>
  <link name="gripper_l_inner_link3">
    <inertial>
      <origin rpy="0 0 0" xyz="0.0088027 -0.007035 1.6424E-05"/>
      <mass value="0.0040132"/>
      <inertia ixx="1.0307E-07" ixy="5.7851E-08" ixz="9.5801E-11" iyy="1.1385E-07" iyz="-2.81E-11" izz="1.7009E-07"/>
    </inertial>
    <visual>
      <origin rpy="0 0 0" xyz="0 0 0"/>
      <geometry>
        <mesh filename="package://genie_robot_description/meshes/omnipicker/inner_link3.dae"/>
      </geometry>
      <!-- <material name="green" /> -->
    </visual>
    <collision>
      <origin rpy="0 0 0" xyz="0 0 0"/>
      <geometry>
        <mesh filename="package://genie_robot_description/meshes/omnipicker/inner_link3.dae"/>
      </geometry>
    </collision>
  </link>
  <joint name="idx32_gripper_l_inner_joint3" type="revolute">
    <origin rpy="0 0 0" xyz="0.030852 0.018551 0"/>
    <parent link="gripper_l_inner_link1"/>
    <child link="gripper_l_inner_link3"/>
    <axis xyz="0 0 -1"/>
    <limit effort="10" lower="-2" upper="2" velocity="10"/>
  </joint>
  <link name="gripper_l_inner_link4">
    <inertial>
      <origin rpy="0 0 0" xyz="0.012508 -0.0079729 9.4339E-05"/>
      <mass value="0.018029"/>
      <inertia ixx="1.1403E-06" ixy="5.5159E-07" ixz="-4.0096E-13" iyy="2.5704E-06" iyz="1.0951E-12" izz="2.3252E-06"/>
    </inertial>
    <visual>
      <origin rpy="0 0 0" xyz="0 0 0"/>
      <geometry>
        <mesh filename="package://genie_robot_description/meshes/omnipicker/inner_link4.dae"/>
      </geometry>
      <!-- <material name="white" /> -->
    </visual>
    <collision>
      <origin rpy="0 0 0" xyz="0 0 0"/>
      <geometry>
        <mesh filename="package://genie_robot_description/meshes/omnipicker/inner_link4.dae"/>
      </geometry>
    </collision>
  </link>
  <joint name="idx33_gripper_l_inner_joint4" type="revolute">
    <origin rpy="0 0 0" xyz="0.018118 -0.01574 0"/>
    <parent link="gripper_l_inner_link3"/>
    <child link="gripper_l_inner_link4"/>
    <axis xyz="0 0 -1"/>
    <limit effort="10" lower="-2" upper="2" velocity="10"/>
  </joint>
  <link name="gripper_l_inner_link2">
    <inertial>
      <origin rpy="0 0 0" xyz="0.014869 -0.0036066 0.00029307"/>
      <mass value="0.022591"/>
      <inertia ixx="4.3916E-06" ixy="1.114E-07" ixz="-4.9655E-12" iyy="4.737E-06" iyz="1.7121E-11" izz="6.0445E-07"/>
    </inertial>
    <visual>
      <origin rpy="0 0 0" xyz="0 0 0"/>
      <geometry>
        <mesh filename="package://genie_robot_description/meshes/omnipicker/inner_link2.dae"/>
      </geometry>
      <!-- <material name="blue" /> -->
    </visual>
    <collision>
      <origin rpy="0 0 0" xyz="0 0 0"/>
      <geometry>
        <mesh filename="package://genie_robot_description/meshes/omnipicker/inner_link2.dae"/>
      </geometry>
    </collision>
  </link>
  <joint name="idx39_gripper_l_inner_joint2" type="revolute">
    <origin rpy="-2.9951 -1.5707963267948966 -0.15964" xyz="0 -0.021633 0.07387"/>
    <parent link="gripper_l_base_link"/>
    <child link="gripper_l_inner_link2"/>
    <axis xyz="0 0 -1"/>
    <limit effort="10" lower="-2" upper="2" velocity="10"/>
  </joint>
  <link name="gripper_l_outer_link1">
    <inertial>
      <origin rpy="0 0 0" xyz="0.0095051 -0.0068479 6.8268E-05"/>
      <mass value="0.025428"/>
      <inertia ixx="1.9565E-06" ixy="4.2798E-07" ixz="2.3844E-10" iyy="2.3928E-06" iyz="-1.4454E-10" izz="1.5501E-06"/>
    </inertial>
    <visual>
      <origin rpy="0 0 0" xyz="0 0 0"/>
      <geometry>
        <mesh filename="package://genie_robot_description/meshes/omnipicker/outer_link1.dae"/>
      </geometry>
      <!-- <material name="orange" /> -->
    </visual>
    <collision>
      <origin rpy="0 0 0" xyz="0 0 0"/>
      <geometry>
        <mesh filename="package://genie_robot_description/meshes/omnipicker/outer_link1.dae"/>
      </geometry>
    </collision>
  </link>
  <joint name="idx41_gripper_l_outer_joint1" type="revolute">
    <origin rpy="-2.9951 -1.5707963267948966 -0.15964" xyz="0 0.0195 0.0565"/>
    <parent link="gripper_l_base_link"/>
    <child link="gripper_l_outer_link1"/>
    <axis xyz="0 0 -1"/>
    <limit effort="10" lower="0" upper="0.7853981633974483" velocity="10"/>
  </joint>
  <link name="gripper_l_outer_link3">
    <inertial>
      <origin rpy="0 0 0" xyz="0.0088027 0.007035 -1.6424E-05"/>
      <mass value="0.0040132"/>
      <inertia ixx="1.0307E-07" ixy="-5.7851E-08" ixz="-9.58E-11" iyy="1.1385E-07" iyz="-2.81E-11" izz="1.7009E-07"/>
    </inertial>
    <visual>
      <origin rpy="0 0 0" xyz="0 0 0"/>
      <geometry>
        <mesh filename="package://genie_robot_description/meshes/omnipicker/outer_link3.dae"/>
      </geometry>
      <!-- <material name="green" /> -->
    </visual>
    <collision>
      <origin rpy="0 0 0" xyz="0 0 0"/>
      <geometry>
        <mesh filename="package://genie_robot_description/meshes/omnipicker/outer_link3.dae"/>
      </geometry>
    </collision>
  </link>
  <joint name="idx42_gripper_l_outer_joint3" type="revolute">
    <origin rpy="0 0 0" xyz="0.030852 -0.018551 0"/>
    <parent link="gripper_l_outer_link1"/>
    <child link="gripper_l_outer_link3"/>
    <axis xyz="0 0 -1"/>
    <limit effort="10" lower="-2" upper="2" velocity="10"/>
  </joint>
  <link name="gripper_l_outer_link4">
    <inertial>
      <origin rpy="0 0 0" xyz="0.016206 0.0094593 4.7668E-05"/>
      <mass value="0.035835"/>
      <inertia ixx="8.5056E-06" ixy="-1.1363E-06" ixz="-4.2908E-11" iyy="1.1235E-05" iyz="-2.9251E-11" izz="4.6309E-06"/>
    </inertial>
    <visual>
      <origin rpy="0 0 0" xyz="0 0 0"/>
      <geometry>
        <mesh filename="package://genie_robot_description/meshes/omnipicker/outer_link4.dae"/>
      </geometry>
      <!-- <material name="white" /> -->
    </visual>
    <collision>
      <origin rpy="0 0 0" xyz="0 0 0"/>
      <geometry>
        <mesh filename="package://genie_robot_description/meshes/omnipicker/outer_link4.dae"/>
      </geometry>
    </collision>
  </link>
  <joint name="idx43_gripper_l_outer_joint4" type="revolute">
    <origin rpy="0 0 0" xyz="0.018118 0.01574 0"/>
    <parent link="gripper_l_outer_link3"/>
    <child link="gripper_l_outer_link4"/>
    <axis xyz="0 0 -1"/>
    <limit effort="10" lower="-2" upper="2" velocity="10"/>
  </joint>
  <link name="gripper_l_outer_link2">
    <inertial>
      <origin rpy="0 0 0" xyz="0.016268 0.0040555 0.00030323"/>
      <mass value="0.025142"/>
      <inertia ixx="5.887E-06" ixy="-1.1234E-07" ixz="2.1954E-11" iyy="6.236E-06" iyz="-9.473E-12" izz="6.2389E-07"/>
    </inertial>
    <visual>
      <origin rpy="0 0 0" xyz="0 0 0"/>
      <geometry>
        <mesh filename="package://genie_robot_description/meshes/omnipicker/outer_link2.dae"/>
      </geometry>
      <!-- <material name="blue" /> -->
    </visual>
    <collision>
      <origin rpy="0 0 0" xyz="0 0 0"/>
      <geometry>
        <mesh filename="package://genie_robot_description/meshes/omnipicker/outer_link2.dae"/>
      </geometry>
    </collision>
  </link>
  <joint name="idx49_gripper_l_outer_joint2" type="revolute">
    <origin rpy="-2.9951 -1.5707963267948966 -0.15964" xyz="0 0.021633 0.07387"/>
    <parent link="gripper_l_base_link"/>
    <child link="gripper_l_outer_link2"/>
    <axis xyz="0 0 -1"/>
    <limit effort="10" lower="-2" upper="2" velocity="10"/>
  </joint>
  <!-- Gripper Connector -->
  <joint name="idx51_ee_l_joint" type="fixed">
    <origin rpy="0 0 1.5707963267948966" xyz="0 0 0"/>
    <parent link="arm_l_end_link"/>
    <child link="gripper_l_base_link"/>
    <axis xyz="0 0 0"/>
  </joint>
  <link name="gripper_l_center_link">
    </link>
  <joint name="idx52_gripper_l_center_joint" type="fixed">
    <origin rpy="0 0 -1.5707963267948966" xyz="0.0 0.0 0.14308"/>
    <parent link="gripper_l_base_link"/>
    <child link="gripper_l_center_link"/>
  </joint>
  <!-- Gripper Finger Close-loop Structure -->
  <loop_joint name="idx53_gripper_l_outer_joint0" type="spherical">
    <link1 link="gripper_l_outer_link2" rpy="0 0 0" xyz="0.03123003 0.010280428 0"/>
    <link2 link="gripper_l_outer_link4" rpy="0 0 0" xyz="0 0.010280428 0"/>
    <axis xyz="0 0 1"/>
  </loop_joint>
  <loop_joint name="idx54_gripper_l_inner_joint0" type="spherical">
    <link1 link="gripper_l_inner_link2" rpy="0 0 0" xyz="0.03123003 -0.010280428 0"/>
    <link2 link="gripper_l_inner_link4" rpy="0 0 0" xyz="0 -0.010280428 0"/>
    <axis xyz="0 0 1"/>
  </loop_joint>
  <!-- Gripper R-->
  <link name="gripper_r_base_link">
    <inertial>
      <origin rpy="0 0 0" xyz="-0.00013356 1.5301E-05 0.03322"/>
      <mass value="0.23588"/>
      <inertia ixx="8.1548E-05" ixy="-1.2617E-08" ixz="-2.05E-07" iyy="5.6921E-05" iyz="6.6903E-08" izz="7.1611E-05"/>
    </inertial>
    <visual>
      <origin rpy="0 0 0" xyz="0 0 0"/>
      <geometry>
        <mesh filename="package://genie_robot_description/meshes/omnipicker/gripper_base_link.dae"/>
      </geometry>
      <!-- <material name="white" /> -->
    </visual>
    <collision>
      <origin rpy="0 0 0" xyz="0 0 0"/>
      <geometry>
        <mesh filename="package://genie_robot_description/meshes/omnipicker/gripper_base_link.dae"/>
      </geometry>
    </collision>
  </link>
  <link name="gripper_r_inner_link1">
    <inertial>
      <origin rpy="0 0 0" xyz="0.0094685 0.0068806 6.5437E-05"/>
      <mass value="0.025428"/>
      <inertia ixx="1.9574E-06" ixy="-4.2911E-07" ixz="-3.7111E-11" iyy="2.3919E-06" iyz="-3.008E-10" izz="1.5501E-06"/>
    </inertial>
    <visual>
      <origin rpy="0 0 0" xyz="0 0 0"/>
      <geometry>
        <mesh filename="package://genie_robot_description/meshes/omnipicker/inner_link1.dae"/>
      </geometry>
      <!-- <material name="orange" /> -->
    </visual>
    <collision>
      <origin rpy="0 0 0" xyz="0 0 0"/>
      <geometry>
        <mesh filename="package://genie_robot_description/meshes/omnipicker/inner_link1.dae"/>
      </geometry>
    </collision>
  </link>
  <joint name="idx71_gripper_r_inner_joint1" type="revolute">
    <origin rpy="-2.9951 -1.5707963267948966 -0.15964" xyz="0 -0.0195 0.0565"/>
    <parent link="gripper_r_base_link"/>
    <child link="gripper_r_inner_link1"/>
    <axis xyz="0 0 -1"/>
    <limit effort="10" lower="-0.7853981633974483" upper="0" velocity="10"/>
    <mimic joint="idx81_gripper_r_outer_joint1" multiplier="-1" offset="0"/>
  </joint>
  <link name="gripper_r_inner_link3">
    <inertial>
      <origin rpy="0 0 0" xyz="0.0088027 -0.007035 1.6424E-05"/>
      <mass value="0.0040132"/>
      <inertia ixx="1.0307E-07" ixy="5.7851E-08" ixz="9.5801E-11" iyy="1.1385E-07" iyz="-2.81E-11" izz="1.7009E-07"/>
    </inertial>
    <visual>
      <origin rpy="0 0 0" xyz="0 0 0"/>
      <geometry>
        <mesh filename="package://genie_robot_description/meshes/omnipicker/inner_link3.dae"/>
      </geometry>
      <!-- <material name="green" /> -->
    </visual>
    <collision>
      <origin rpy="0 0 0" xyz="0 0 0"/>
      <geometry>
        <mesh filename="package://genie_robot_description/meshes/omnipicker/inner_link3.dae"/>
      </geometry>
    </collision>
  </link>
  <joint name="idx72_gripper_r_inner_joint3" type="revolute">
    <origin rpy="0 0 0" xyz="0.030852 0.018551 0"/>
    <parent link="gripper_r_inner_link1"/>
    <child link="gripper_r_inner_link3"/>
    <axis xyz="0 0 -1"/>
    <limit effort="10" lower="-2" upper="2" velocity="10"/>
  </joint>
  <link name="gripper_r_inner_link4">
    <inertial>
      <origin rpy="0 0 0" xyz="0.012508 -0.0079729 9.4339E-05"/>
      <mass value="0.018029"/>
      <inertia ixx="1.1403E-06" ixy="5.5159E-07" ixz="-4.0096E-13" iyy="2.5704E-06" iyz="1.0951E-12" izz="2.3252E-06"/>
    </inertial>
    <visual>
      <origin rpy="0 0 0" xyz="0 0 0"/>
      <geometry>
        <mesh filename="package://genie_robot_description/meshes/omnipicker/inner_link4.dae"/>
      </geometry>
      <!-- <material name="white" /> -->
    </visual>
    <collision>
      <origin rpy="0 0 0" xyz="0 0 0"/>
      <geometry>
        <mesh filename="package://genie_robot_description/meshes/omnipicker/inner_link4.dae"/>
      </geometry>
    </collision>
  </link>
  <joint name="idx73_gripper_r_inner_joint4" type="revolute">
    <origin rpy="0 0 0" xyz="0.018118 -0.01574 0"/>
    <parent link="gripper_r_inner_link3"/>
    <child link="gripper_r_inner_link4"/>
    <axis xyz="0 0 -1"/>
    <limit effort="10" lower="-2" upper="2" velocity="10"/>
  </joint>
  <link name="gripper_r_inner_link2">
    <inertial>
      <origin rpy="0 0 0" xyz="0.014869 -0.0036066 0.00029307"/>
      <mass value="0.022591"/>
      <inertia ixx="4.3916E-06" ixy="1.114E-07" ixz="-4.9655E-12" iyy="4.737E-06" iyz="1.7121E-11" izz="6.0445E-07"/>
    </inertial>
    <visual>
      <origin rpy="0 0 0" xyz="0 0 0"/>
      <geometry>
        <mesh filename="package://genie_robot_description/meshes/omnipicker/inner_link2.dae"/>
      </geometry>
      <!-- <material name="blue" /> -->
    </visual>
    <collision>
      <origin rpy="0 0 0" xyz="0 0 0"/>
      <geometry>
        <mesh filename="package://genie_robot_description/meshes/omnipicker/inner_link2.dae"/>
      </geometry>
    </collision>
  </link>
  <joint name="idx79_gripper_r_inner_joint2" type="revolute">
    <origin rpy="-2.9951 -1.5707963267948966 -0.15964" xyz="0 -0.021633 0.07387"/>
    <parent link="gripper_r_base_link"/>
    <child link="gripper_r_inner_link2"/>
    <axis xyz="0 0 -1"/>
    <limit effort="10" lower="-2" upper="2" velocity="10"/>
  </joint>
  <link name="gripper_r_outer_link1">
    <inertial>
      <origin rpy="0 0 0" xyz="0.0095051 -0.0068479 6.8268E-05"/>
      <mass value="0.025428"/>
      <inertia ixx="1.9565E-06" ixy="4.2798E-07" ixz="2.3844E-10" iyy="2.3928E-06" iyz="-1.4454E-10" izz="1.5501E-06"/>
    </inertial>
    <visual>
      <origin rpy="0 0 0" xyz="0 0 0"/>
      <geometry>
        <mesh filename="package://genie_robot_description/meshes/omnipicker/outer_link1.dae"/>
      </geometry>
      <!-- <material name="orange" /> -->
    </visual>
    <collision>
      <origin rpy="0 0 0" xyz="0 0 0"/>
      <geometry>
        <mesh filename="package://genie_robot_description/meshes/omnipicker/outer_link1.dae"/>
      </geometry>
    </collision>
  </link>
  <joint name="idx81_gripper_r_outer_joint1" type="revolute">
    <origin rpy="-2.9951 -1.5707963267948966 -0.15964" xyz="0 0.0195 0.0565"/>
    <parent link="gripper_r_base_link"/>
    <child link="gripper_r_outer_link1"/>
    <axis xyz="0 0 -1"/>
    <limit effort="10" lower="0" upper="0.7853981633974483" velocity="10"/>
  </joint>
  <link name="gripper_r_outer_link3">
    <inertial>
      <origin rpy="0 0 0" xyz="0.0088027 0.007035 -1.6424E-05"/>
      <mass value="0.0040132"/>
      <inertia ixx="1.0307E-07" ixy="-5.7851E-08" ixz="-9.58E-11" iyy="1.1385E-07" iyz="-2.81E-11" izz="1.7009E-07"/>
    </inertial>
    <visual>
      <origin rpy="0 0 0" xyz="0 0 0"/>
      <geometry>
        <mesh filename="package://genie_robot_description/meshes/omnipicker/outer_link3.dae"/>
      </geometry>
      <!-- <material name="green" /> -->
    </visual>
    <collision>
      <origin rpy="0 0 0" xyz="0 0 0"/>
      <geometry>
        <mesh filename="package://genie_robot_description/meshes/omnipicker/outer_link3.dae"/>
      </geometry>
    </collision>
  </link>
  <joint name="idx82_gripper_r_outer_joint3" type="revolute">
    <origin rpy="0 0 0" xyz="0.030852 -0.018551 0"/>
    <parent link="gripper_r_outer_link1"/>
    <child link="gripper_r_outer_link3"/>
    <axis xyz="0 0 -1"/>
    <limit effort="10" lower="-2" upper="2" velocity="10"/>
  </joint>
  <link name="gripper_r_outer_link4">
    <inertial>
      <origin rpy="0 0 0" xyz="0.016206 0.0094593 4.7668E-05"/>
      <mass value="0.035835"/>
      <inertia ixx="8.5056E-06" ixy="-1.1363E-06" ixz="-4.2908E-11" iyy="1.1235E-05" iyz="-2.9251E-11" izz="4.6309E-06"/>
    </inertial>
    <visual>
      <origin rpy="0 0 0" xyz="0 0 0"/>
      <geometry>
        <mesh filename="package://genie_robot_description/meshes/omnipicker/outer_link4.dae"/>
      </geometry>
      <!-- <material name="white" /> -->
    </visual>
    <collision>
      <origin rpy="0 0 0" xyz="0 0 0"/>
      <geometry>
        <mesh filename="package://genie_robot_description/meshes/omnipicker/outer_link4.dae"/>
      </geometry>
    </collision>
  </link>
  <joint name="idx83_gripper_r_outer_joint4" type="revolute">
    <origin rpy="0 0 0" xyz="0.018118 0.01574 0"/>
    <parent link="gripper_r_outer_link3"/>
    <child link="gripper_r_outer_link4"/>
    <axis xyz="0 0 -1"/>
    <limit effort="10" lower="-2" upper="2" velocity="10"/>
  </joint>
  <link name="gripper_r_outer_link2">
    <inertial>
      <origin rpy="0 0 0" xyz="0.016268 0.0040555 0.00030323"/>
      <mass value="0.025142"/>
      <inertia ixx="5.887E-06" ixy="-1.1234E-07" ixz="2.1954E-11" iyy="6.236E-06" iyz="-9.473E-12" izz="6.2389E-07"/>
    </inertial>
    <visual>
      <origin rpy="0 0 0" xyz="0 0 0"/>
      <geometry>
        <mesh filename="package://genie_robot_description/meshes/omnipicker/outer_link2.dae"/>
      </geometry>
      <!-- <material name="blue" /> -->
    </visual>
    <collision>
      <origin rpy="0 0 0" xyz="0 0 0"/>
      <geometry>
        <mesh filename="package://genie_robot_description/meshes/omnipicker/outer_link2.dae"/>
      </geometry>
    </collision>
  </link>
  <joint name="idx89_gripper_r_outer_joint2" type="revolute">
    <origin rpy="-2.9951 -1.5707963267948966 -0.15964" xyz="0 0.021633 0.07387"/>
    <parent link="gripper_r_base_link"/>
    <child link="gripper_r_outer_link2"/>
    <axis xyz="0 0 -1"/>
    <limit effort="10" lower="-2" upper="2" velocity="10"/>
  </joint>
  <!-- Gripper Connector -->
  <joint name="idx91_ee_r_joint" type="fixed">
    <origin rpy="0 0 1.5707963267948966" xyz="0 0 0"/>
    <parent link="arm_r_end_link"/>
    <child link="gripper_r_base_link"/>
    <axis xyz="0 0 0"/>
  </joint>
  <link name="gripper_r_center_link">
    </link>
  <joint name="idx92_gripper_r_center_joint" type="fixed">
    <origin rpy="0 0 -1.5707963267948966" xyz="0.0 0.0 0.14308"/>
    <parent link="gripper_r_base_link"/>
    <child link="gripper_r_center_link"/>
  </joint>
  <!-- Gripper Finger Close-loop Structure -->
  <loop_joint name="idx93_gripper_r_outer_joint0" type="spherical">
    <link1 link="gripper_r_outer_link2" rpy="0 0 0" xyz="0.03123003 0.010280428 0"/>
    <link2 link="gripper_r_outer_link4" rpy="0 0 0" xyz="0 0.010280428 0"/>
    <axis xyz="0 0 1"/>
  </loop_joint>
  <loop_joint name="idx94_gripper_r_inner_joint0" type="spherical">
    <link1 link="gripper_r_inner_link2" rpy="0 0 0" xyz="0.03123003 -0.010280428 0"/>
    <link2 link="gripper_r_inner_link4" rpy="0 0 0" xyz="0 -0.010280428 0"/>
    <axis xyz="0 0 1"/>
  </loop_joint>
  <!-- Eastern Eggs -->
  <!-- All Together -->
</robot>
