<?xml version='1.0' encoding='ASCII'?>
<robot name="g1_description">
  <link name="base_link">
    <inertial>
      <origin xyz="-0.0134486971267798 0.00152103941353612 -0.0320076754329413" rpy="0.0 -0.0 0.0"/>
      <mass value="23.2085382238952"/>
      <inertia ixx="0.386955641760608" ixy="0.000135417314593726" ixz="0.00669301645720665" iyy="0.366800407621218" iyz="0.000105713634260505" izz="0.546852919828475"/>
    </inertial>
    <visual>
      <geometry>
        <mesh filename="package://g1_description/meshes/base_link.STL"/>
      </geometry>
      <origin xyz="0.0 0.0 0.0" rpy="0.0 -0.0 0.0"/>
      <material name="">
        <color rgba="0.8 0.4 0.0 1.0"/>
      </material>
    </visual>
    <!-- <collision>
      <geometry>
        <cylinder radius="0.3335115495543626" length="1.3037323951721191"/>
      </geometry>
      <origin xyz="8.351547857083084e-17 -7.739635460313724e-17 0.3585103750228882" rpy="3.141592653589793 -1.2246467991473532e-16 1.8849555921538759"/>
    </collision> -->
    <collision>
              <origin rpy="-0.0 0.0 -0.0" xyz="-0.10913086 -7.450581013257462e-09 0.51171875"/>
              <geometry>
                <box size="0.29833984 0.3376392 1.0"/>
              </geometry>
    </collision>
    <collision>
              <origin rpy="-0.0 0.0 -0.0" xyz="0.0 0.0 -0.14160156"/>
              <geometry>
                <box size="0.5996094 0.449 0.30273438"/>
              </geometry>
    </collision>
  </link>
  <link name="waist_lift_link">
    <inertial>
      <origin xyz="0.0338351537064605 -0.00248044044451858 0.000838431095422365" rpy="0.0 -0.0 0.0"/>
      <mass value="3.26275452360108"/>
      <inertia ixx="0.0128301877197417" ixy="8.24967996575627e-06" ixz="1.38254543337324e-05" iyy="0.006104110250297" iyz="-7.99392548994692e-06" izz="0.0111721084996867"/>
    </inertial>
    <visual>
      <geometry>
        <mesh filename="package://g1_description/meshes/waist_lift_link.STL"/>
      </geometry>
      <origin xyz="0.0 0.0 0.0" rpy="0.0 -0.0 0.0"/>
      <material name="">
        <color rgba="1.0 1.0 0.4 1.0"/>
      </material>
    </visual>
    <!-- <collision>
      <geometry>
        <cylinder radius="0.1713923977339912" length="0.1596960946917534"/>
      </geometry>
      <origin xyz="0.06465151068613234 -0.0001553023438145007 -0.00034801289439201355" rpy="0.0 -0.0 0.0"/>
    </collision> -->
    <collision>
              <origin rpy="-0.0 0.0 -0.0" xyz="0.10278320000000002 0.10397815999999999 -0.013671875"/>
              <geometry>
                <box size="0.16064453 0.05555534399999999 0.1328125"/>
              </geometry>
    </collision>
    <collision>
              <origin rpy="-0.0 0.0 -0.0" xyz="0.10180664 -0.10987759 0.0"/>
              <geometry>
                <box size="0.16259765999999998 0.04375648500000001 0.16015625"/>
              </geometry>
    </collision>
  </link>
  <link name="waist_pitch_link">
    <inertial>
      <origin xyz="0.193733558855111 -0.000484180179482319 -0.00124011422952511" rpy="0.0 -0.0 0.0"/>
      <mass value="7.53199207979272"/>
      <inertia ixx="0.016546682835947" ixy="0.000274441382484697" ixz="0.00102757387076422" iyy="0.0445441227006132" iyz="-0.000236858278708531" izz="0.0402036337794082"/>
    </inertial>
    <visual>
      <geometry>
        <mesh filename="package://g1_description/meshes/waist_pitch_link.STL"/>
      </geometry>
      <origin xyz="0.0 0.0 0.0" rpy="0.0 -0.0 -1.5708"/>
      <material name="">
        <color rgba="1.0 0.4 0.4 1.0"/>
      </material>
    </visual>
    <!-- <collision>
      <geometry>
        <cylinder radius="0.15597176841801771" length="0.5102232405035569"/>
      </geometry>
      <origin xyz="0.18634710465339227 0.023714452507238776 -0.010425811011294467" rpy="-3.141592653589793 -1.5140832644138762 3.0406723195106666"/>
    </collision> -->
    <collision>
      <origin rpy="0 0 0" xyz="0.0068359375 -0.00034356117 0.0"/>
      <geometry>
        <cylinder radius="0.09662318" length="0.08697056999999997" />
      </geometry>
    </collision>
    <collision>
      <origin xyz="0.0068359375 -0.00034356117 0.043485284999999985" />
      <geometry>
        <sphere radius="0.09662318" />
      </geometry>
    </collision>
    <collision>
      <origin xyz="0.0068359375 -0.00034356117 -0.043485284999999985" />
      <geometry>
        <sphere radius="0.09662318" />
      </geometry>
    </collision>

    <!-- <collision>
      <origin rpy="0 0 0" xyz="0.41796875 -0.010616422 -0.0014648438"/>
      <geometry>
        <cylinder radius="0.03805239" length="0.05081480000000001" />
      </geometry>
    </collision>
    <collision>
      <origin xyz="0.41796875 -0.010616422 0.023942556200000003" />
      <geometry>
        <sphere radius="0.03805239" />
      </geometry>
    </collision>
    <collision>
      <origin xyz="0.41796875 -0.010616422 -0.026872243800000004" />
      <geometry>
        <sphere radius="0.03805239" />
      </geometry>
    </collision> -->
    <collision>
              <origin rpy="-0.0 0.0 -1.5708" xyz="0.008 -0.248 0.0"/>
              <geometry>
                <box size="0.34570312 0.18107724 0.3125"/>
              </geometry>
    </collision>


  </link>
  <link name="head_yaw_link">
    <inertial>
      <origin xyz="0.0446068140025754 0.00241753143645124 0.0528373754603559" rpy="0.0 -0.0 0.0"/>
      <mass value="0.414342871921048"/>
      <inertia ixx="0.000158695728344024" ixy="-1.04590928109554e-06" ixz="-6.58530903139189e-06" iyy="0.000117742864399469" iyz="-2.65011299996072e-06" izz="0.000170947040827065"/>
    </inertial>
    <visual>
      <geometry>
        <mesh filename="package://g1_description/meshes/head_yaw_link.STL"/>
      </geometry>
      <origin xyz="0.0 0.0 0.0" rpy="0.0 -0.0 0.0"/>
      <material name="">
        <color rgba="1.0 0.4 0.4 1.0"/>
      </material>
    </visual>
    <!-- <collision>
      <geometry>
        <cylinder radius="0.06737420519838923" length="0.06017081262804641"/>
      </geometry>
      <origin xyz="0.03258458973890179 -0.0016069482300351198 0.03968031105048003" rpy="0.0 -0.6283185307179586 0.0"/>
    </collision> -->
  </link>
  <link name="head_pitch_link">
    <inertial>
      <origin xyz="0.0257009265816389 0.0316254080188787 -3.77390122592164e-05" rpy="0.0 -0.0 0.0"/>
      <mass value="0.707063977171202"/>
      <inertia ixx="0.00205409595373573" ixy="0.000347730118005016" ixz="-2.13857752451204e-06" iyy="0.00200357281313449" iyz="5.16150600423908e-08" izz="0.00184999028444405"/>
    </inertial>
    <visual>
      <geometry>
        <mesh filename="package://g1_description/meshes/head_pitch_link.STL"/>
      </geometry>
      <origin xyz="0.0 0.0 0.0" rpy="-3.1415853071795867 -0.0 0.0"/>
      <material name="">
        <color rgba="1.0 1.0 0.4 1.0"/>
      </material>
    </visual>
    <!-- <collision>
      <geometry>
        <cylinder radius="0.112343542935944" length="0.16301889374711614"/>
      </geometry>
      <origin xyz="0.01810361158417186 0.0291948459335663 0.0007398432879914022" rpy="-1.734723475976807e-18 -0.03166557953123136 -1.2570540743277054"/>
    </collision> -->
    <collision>
      <geometry>
        <sphere radius="0.11257068650657154"/>
      </geometry>
      <origin xyz="0.011500973396434619 -0.0252600143348118 0.0008537154007319386" rpy="0.0 -0.0 0.0"/>
    </collision>
  </link>
  <link name="arm_base_link"/>
  <link name="arm_left_base_link">
    <inertial>
      <origin xyz="-0.00020641 0.00057488 0.032296" rpy="0.0 -0.0 0.0"/>
      <mass value="0.37595"/>
      <inertia ixx="0.00024335" ixy="1.2188e-06" ixz="-2.4281e-06" iyy="0.00024039" iyz="6.6932e-06" izz="0.00032195"/>
    </inertial>
    <visual>
      <geometry>
        <mesh filename="package://g1_description/meshes/arm_left_base_link.STL"/>
      </geometry>
      <origin xyz="0.0 0.0 0.0" rpy="0.0 -0.0 0.0"/>
      <material name="">
        <color rgba="0.2 0.5 1.0 1.0"/>
      </material>
    </visual>
    <collision>
      <geometry>
        <cylinder radius="0.05426921699310094" length="0.09134995751082897"/>
      </geometry>
      <origin xyz="-0.0017106435846521925 0.0013720927967423996 0.02822502050548792" rpy="0.0 -0.0 0.0"/>
    </collision>
  </link>
  <link name="arm_left_link1">
    <inertial>
      <origin xyz="-0.0012655 -0.00043778 -0.018388" rpy="0.0 -0.0 0.0"/>
      <mass value="0.4936"/>
      <inertia ixx="0.00075396" ixy="6.6935e-06" ixz="6.1141e-06" iyy="0.00065755" iyz="1.2196e-06" izz="0.00031848"/>
    </inertial>
    <visual>
      <geometry>
        <mesh filename="package://g1_description/meshes/arm_left_link1.STL"/>
      </geometry>
      <origin xyz="0.0 0.0 0.0" rpy="0.0 -0.0 0.0"/>
      <material name="">
        <color rgba="1.0 0.5 1.0 1.0"/>
      </material>
    </visual>
    <collision>
      <geometry>
        <cylinder radius="0.05579268228774888" length="0.16642063483595848"/>
      </geometry>
      <origin xyz="0.0026814433577366636 0.0006133775157398935 -0.04071124829351902" rpy="0.0 -0.0 -1.2566370614359172"/>
    </collision>
  </link>
  <link name="arm_left_link2">
    <inertial>
      <origin xyz="5.3037e-05 -0.078258 0.0047084" rpy="0.0 -0.0 0.0"/>
      <mass value="0.46245"/>
      <inertia ixx="0.00065719" ixy="3.7112e-07" ixz="-3.6668e-06" iyy="0.00043459" iyz="-2.517e-05" izz="0.00072571"/>
    </inertial>
    <visual>
      <geometry>
        <mesh filename="package://g1_description/meshes/arm_left_link2.STL"/>
      </geometry>
      <origin xyz="0.0 0.0 0.0" rpy="0.0 -0.0 0.0"/>
      <material name="">
        <color rgba="1.0 1.0 0.4 1.0"/>
      </material>
    </visual>
    <!-- <collision>
      <geometry>
        <cylinder radius="0.09539540282042425" length="0.12052976340055466"/>
      </geometry>
      <origin xyz="-0.005072967269938958 -0.04716573845178604 0.007318001240491867" rpy="0.0 -0.0 0.0"/>
    </collision> -->
    <collision>
      <origin rpy="1.5708 0 0" xyz="-0.0 -0.044062052 0.0009765625"/>
      <geometry>
        <cylinder radius="0.06302423" length="0.18085919" />
      </geometry>
    </collision>
  </link>
  <link name="arm_left_link3">
    <inertial>
      <origin xyz="-0.0012032 0.0008714 -0.055265" rpy="0.0 -0.0 0.0"/>
      <mass value="0.50026"/>
      <inertia ixx="0.0013016" ixy="3.1401e-06" ixz="1.4255e-05" iyy="0.001427" iyz="2.4361e-05" izz="0.00033587"/>
    </inertial>
    <visual>
      <geometry>
        <mesh filename="package://g1_description/meshes/arm_left_link3.STL"/>
      </geometry>
      <origin xyz="0.0 0.0 0.0" rpy="0.0 -0.0 0.0"/>
      <material name="">
        <color rgba="0.4 1.0 0.4 1.0"/>
      </material>
    </visual>
    <collision>
      <geometry>
        <cylinder radius="0.05423258091998755" length="0.22069887816905975"/>
      </geometry>
      <origin xyz="-0.002745052027917949 0.000636008250640886 -0.07223940640687943" rpy="3.141592653589793 -1.2246467991473532e-16 2.5132741228718345"/>
    </collision>
  </link>
  <link name="arm_left_link4">
    <inertial>
      <origin xyz="3.7035e-05 -0.06248 0.0025377" rpy="0.0 -0.0 0.0"/>
      <mass value="0.27473"/>
      <inertia ixx="0.00029284" ixy="4.6615e-07" ixz="6.2359e-08" iyy="0.00018853" iyz="-1.1062e-06" izz="0.00031238"/>
    </inertial>
    <visual>
      <geometry>
        <mesh filename="package://g1_description/meshes/arm_left_link4.STL"/>
      </geometry>
      <origin xyz="0.0 0.0 0.0" rpy="0.0 -0.0 0.0"/>
      <material name="">
        <color rgba="0.4 1.0 1.0 1.0"/>
      </material>
    </visual>
    <!-- <collision>
      <geometry>
        <cylinder radius="0.059457016341923005" length="0.15945142768731196"/>
      </geometry>
      <origin xyz="-0.00026088334152999255 -0.03708382659993887 -0.0048890993323991395" rpy="-7.804845110301445e-23 -1.4028214567772328 -1.5707970308505024"/>
    </collision> -->
    <collision>
      <origin rpy="1.5708 0 0" xyz="-0.0 -0.03817895 -0.0043945312"/>
      <geometry>
        <cylinder radius="0.057891708" length="0.154955404" />
      </geometry>
    </collision>
  </link>
  <link name="arm_left_link5">
    <inertial>
      <origin xyz="-7.9404e-07 -0.00023094 -0.024143" rpy="0.0 -0.0 0.0"/>
      <mass value="0.25139"/>
      <inertia ixx="0.00023516" ixy="-1.3496e-09" ixz="-2.0314e-08" iyy="0.00028808" iyz="-1.2106e-05" izz="0.00013069"/>
    </inertial>
    <visual>
      <geometry>
        <mesh filename="package://g1_description/meshes/arm_left_link5.STL"/>
      </geometry>
      <origin xyz="0.0 0.0 0.0" rpy="0.0 -0.0 0.0"/>
      <material name="">
        <color rgba="0.0 0.5 1.0 1.0"/>
      </material>
    </visual>
    <collision>
      <geometry>
        <cylinder radius="0.045614576801007695" length="0.13452399894595146"/>
      </geometry>
      <origin xyz="0.00013161953185003987 -5.835551655943335e-05 -0.033305803313851357" rpy="0.0 -0.0 -0.6283185307179586"/>
    </collision>
  </link>
  <link name="arm_left_link6">
    <inertial>
      <origin xyz="1.769e-06 -0.086692 0.0025571" rpy="0.0 -0.0 0.0"/>
      <mass value="0.26634"/>
      <inertia ixx="0.00031434" ixy="-2.9254e-09" ixz="1.0017e-07" iyy="0.00014464" iyz="-2.0329e-05" izz="0.0003245"/>
    </inertial>
    <visual>
      <geometry>
        <mesh filename="package://g1_description/meshes/arm_left_link6.STL"/>
      </geometry>
      <origin xyz="0.0 0.0 0.0" rpy="0.0 -0.0 0.0"/>
      <material name="">
        <color rgba="0.8 1.0 0.8 1.0"/>
      </material>
    </visual>
    <collision>
      <geometry>
        <cylinder radius="0.048507387167967514" length="0.1816599826988493"/>
      </geometry>
      <origin xyz="0.0002549462426528953 -0.055477687883556816 -0.0019394332157672595" rpy="-5.990089690983079e-19 -1.4805425285141327 -1.5677635369963552"/>
    </collision>
  </link>
  <link name="arm_left_link7">
    <inertial>
      <origin xyz="-7.5113e-05 -0.00024521 -0.016705" rpy="0.0 -0.0 0.0"/>
      <mass value="0.06158"/>
      <inertia ixx="1.8407e-05" ixy="3.4796e-08" ixz="-3.2424e-09" iyy="1.818e-05" iyz="1.1327e-07" izz="2.8547e-05"/>
    </inertial>
    <visual>
      <geometry>
        <mesh filename="package://g1_description/meshes/arm_left_link7.STL"/>
      </geometry>
      <origin xyz="0.0 0.0 0.0" rpy="0.0 -0.0 0.0"/>
      <material name="">
        <color rgba="1.0 0.5 1.0 1.0"/>
      </material>
    </visual>
    <collision>
      <geometry>
        <cylinder radius="0.030799950382754494" length="0.045999998692423105"/>
      </geometry>
      <origin xyz="-4.552953707661759e-05 -0.002300474691790042 -0.02249999972991645" rpy="3.141592653589793 -1.2246467991473532e-16 3.141592653589793"/>
    </collision>
  </link>
  <link name="hand_left_base_link">
    <inertial>
      <origin xyz="0.0036691 0.0082806 0.059221" rpy="0.0 -0.0 0.0"/>
      <mass value="0.070229"/>
      <inertia ixx="5.5259e-05" ixy="-8.7205e-06" ixz="-7.9434e-06" iyy="6.2355e-05" iyz="-1.345e-05" izz="4.4874e-05"/>
    </inertial>
    <visual>
      <geometry>
        <mesh filename="package://g1_description/meshes/hand_left_base_link.STL"/>
      </geometry>
      <origin xyz="0.0 0.0 0.0" rpy="0.0 -0.0 0.0"/>
      <material name="">
        <color rgba="0.6 0.9 0.7 1.0"/>
      </material>
    </visual>
    <!-- <collision>
      <geometry>
        <cylinder radius="0.05352542175417151" length="0.2044629561714828"/>
      </geometry>
      <origin xyz="0.003067844437704177 0.023853258934742685 0.10123148025013506" rpy="0.0 -0.0 -0.6283185307179586"/>
    </collision> -->
    <collision>
      <origin rpy="0 0 0" xyz="0.024414062 0.045294166 0.076660156"/>
      <geometry>
        <cylinder radius="0.028545704" length="0.08180586199999998" />
      </geometry>
    </collision>
    <collision>
      <origin xyz="0.024414062 0.045294166 0.11756308699999998" />
      <geometry>
        <sphere radius="0.028545704" />
      </geometry>
    </collision>
    <collision>
      <origin xyz="0.024414062 0.045294166 0.035757225000000004" />
      <geometry>
        <sphere radius="0.028545704" />
      </geometry>
    </collision>

    <collision>
      <origin rpy="0 0 0" xyz="-0.034179688 0.004840106 0.14941406"/>
      <geometry>
        <cylinder radius="0.014200054" length="0.038534322" />
      </geometry>
    </collision>
    <collision>
      <origin xyz="-0.034179688 0.004840106 0.168681221" />
      <geometry>
        <sphere radius="0.014200054" />
      </geometry>
    </collision>
    <collision>
      <origin xyz="-0.034179688 0.004840106 0.13014689899999998" />
      <geometry>
        <sphere radius="0.014200054" />
      </geometry>
    </collision>

    <collision>
      <origin rpy="0 0 0" xyz="-0.013671875 0.00875093 0.16503906"/>
      <geometry>
        <cylinder radius="0.01649639" length="0.04600361" />
      </geometry>
    </collision>
    <collision>
      <origin xyz="-0.013671875 0.00875093 0.188040865" />
      <geometry>
        <sphere radius="0.01649639" />
      </geometry>
    </collision>
    <collision>
      <origin xyz="-0.013671875 0.00875093 0.14203725499999997" />
      <geometry>
        <sphere radius="0.01649639" />
      </geometry>
    </collision>

    <collision>
      <origin rpy="0 0 0" xyz="0.0107421875 0.010264128 0.17089844"/>
      <geometry>
        <cylinder radius="0.016917389" length="0.047535742" />
      </geometry>
    </collision>
    <collision>
      <origin xyz="0.0107421875 0.010264128 0.194666311" />
      <geometry>
        <sphere radius="0.016917389" />
      </geometry>
    </collision>
    <collision>
      <origin xyz="0.0107421875 0.010264128 0.14713056900000002" />
      <geometry>
        <sphere radius="0.016917389" />
      </geometry>
    </collision>

    <collision>
      <origin rpy="0 0 0" xyz="0.03125 0.012013525 0.16455078"/>
      <geometry>
        <cylinder radius="0.016514413" length="0.04696215000000001" />
      </geometry>
    </collision>
    <collision>
      <origin xyz="0.03125 0.012013525 0.18803185500000003" />
      <geometry>
        <sphere radius="0.016514413" />
      </geometry>
    </collision>
    <collision>
      <origin xyz="0.03125 0.012013525 0.141069705" />
      <geometry>
        <sphere radius="0.016514413" />
      </geometry>
    </collision>

    <collision>
      <origin rpy="0 0 0" xyz="-0.0078125 0.0102531165 0.057128906"/>
      <geometry>
        <cylinder radius="0.049380157" length="0.066830776" />
      </geometry>
    </collision>
    <collision>
      <origin xyz="-0.0078125 0.0102531165 0.090544294" />
      <geometry>
        <sphere radius="0.049380157" />
      </geometry>
    </collision>
    <collision>
      <origin xyz="-0.0078125 0.0102531165 0.023713518000000003" />
      <geometry>
        <sphere radius="0.049380157" />
      </geometry>
    </collision>
  </link>
  <link name="arm_right_base_link">
    <inertial>
      <origin xyz="0.00020641 -0.00057488 0.034396" rpy="0.0 -0.0 0.0"/>
      <mass value="0.37595"/>
      <inertia ixx="0.00024335" ixy="1.2188e-06" ixz="2.4281e-06" iyy="0.00024039" iyz="-6.6932e-06" izz="0.00032195"/>
    </inertial>
    <visual>
      <geometry>
        <mesh filename="package://g1_description/meshes/arm_right_base_link.STL"/>
      </geometry>
      <origin xyz="0.0 0.0 0.0" rpy="0.0 -0.0 0.0"/>
      <material name="">
        <color rgba="0.2 0.5 1.0 1.0"/>
      </material>
    </visual>
    <collision>
      <geometry>
        <cylinder radius="0.05447215073540005" length="0.0913499565795064"/>
      </geometry>
      <origin xyz="0.001163549527588341 -0.0020492302944608923 0.030325019266456366" rpy="0.0 -0.0 0.0"/>
    </collision>
  </link>
  <link name="arm_right_link1">
    <inertial>
      <origin xyz="0.0012679 -0.0001581 -0.018109" rpy="0.0 -0.0 0.0"/>
      <mass value="0.4936"/>
      <inertia ixx="0.00075396" ixy="-2.4144e-06" ixz="-1.8364e-06" iyy="0.0006605" iyz="1.2174e-06" izz="0.00031553"/>
    </inertial>
    <visual>
      <geometry>
        <mesh filename="package://g1_description/meshes/arm_right_link1.STL"/>
      </geometry>
      <origin xyz="0.0 0.0 0.0" rpy="0.0 -0.0 0.0"/>
      <material name="">
        <color rgba="1.0 0.5 1.0 1.0"/>
      </material>
    </visual>
    <collision>
      <geometry>
        <cylinder radius="0.0548390473201415" length="0.16642716526985168"/>
      </geometry>
      <origin xyz="0.00018724019569230644 -0.002004870648449318 -0.04071185737848282" rpy="-3.141592653589793 -1.2246467991473535e-16 1.2566370614359175"/>
    </collision>
  </link>
  <link name="arm_right_link2">
    <inertial>
      <origin xyz="-0.00044207 -0.082298 0.00019486" rpy="0.0 -0.0 0.0"/>
      <mass value="0.41662"/>
      <inertia ixx="0.00054592" ixy="4.7265e-06" ixz="2.4946e-06" iyy="0.00039507" iyz="-2.0629e-05" izz="0.00057791"/>
    </inertial>
    <visual>
      <geometry>
        <mesh filename="package://g1_description/meshes/arm_right_link2.STL"/>
      </geometry>
      <origin xyz="0.0 0.0 0.0" rpy="0.0 -0.0 0.0"/>
      <material name="">
        <color rgba="1.0 1.0 0.4 1.0"/>
      </material>
    </visual>
    <!-- <collision>
      <geometry>
        <cylinder radius="0.09834876232859342" length="0.12246305149106688"/>
      </geometry>
      <origin xyz="-0.005831453672209563 -0.04548139309674086 0.0019606223509298767" rpy="3.141592653589793 -1.2566370614359175 3.141592653589793"/>
    </collision> -->
    <collision>
      <origin rpy="1.5708 0 0" xyz="-0.0 -0.044062052 0.0009765625"/>
      <geometry>
        <cylinder radius="0.06302423" length="0.18085919" />
      </geometry>
    </collision>
  </link>
  <link name="arm_right_link3">
    <inertial>
      <origin xyz="0.0010558 4.4416e-05 -0.056128" rpy="0.0 -0.0 0.0"/>
      <mass value="0.49413"/>
      <inertia ixx="0.0013405" ixy="-6.8527e-07" ixz="-1.3381e-05" iyy="0.00142" iyz="2.8511e-05" izz="0.00037605"/>
    </inertial>
    <visual>
      <geometry>
        <mesh filename="package://g1_description/meshes/arm_right_link3.STL"/>
      </geometry>
      <origin xyz="0.0 0.0 0.0" rpy="0.0 -0.0 0.0"/>
      <material name="">
        <color rgba="0.4 1.0 0.4 1.0"/>
      </material>
    </visual>
    <collision>
      <geometry>
        <cylinder radius="0.05216156143823925" length="0.22061403840780258"/>
      </geometry>
      <origin xyz="0.0006559932284637068 -2.2628975236450855e-05 -0.07219303026795387" rpy="0.0 -0.0 0.0"/>
    </collision>
  </link>
  <link name="arm_right_link4">
    <inertial>
      <origin xyz="2.4212e-05 -0.06248 0.002536" rpy="0.0 -0.0 0.0"/>
      <mass value="0.27473"/>
      <inertia ixx="0.00029283" ixy="4.5586e-07" ixz="5.8042e-08" iyy="0.00018852" iyz="-1.116e-06" izz="0.00031238"/>
    </inertial>
    <visual>
      <geometry>
        <mesh filename="package://g1_description/meshes/arm_right_link4.STL"/>
      </geometry>
      <origin xyz="0.0 0.0 0.0" rpy="0.0 -0.0 0.0"/>
      <material name="">
        <color rgba="0.4 1.0 1.0 1.0"/>
      </material>
    </visual>
    <!-- <collision>
      <geometry>
        <cylinder radius="0.059100057415964594" length="0.15968133482849173"/>
      </geometry>
      <origin xyz="-0.00015434194495186828 -0.036933642681315174 -0.0047865253700190595" rpy="3.2841532836648795e-19 -1.4072057423466429 -1.5687318743005294"/>
    </collision> -->
    <collision>
      <origin rpy="1.5708 0 0" xyz="-0.0 -0.03817895 -0.0043945312"/>
      <geometry>
        <cylinder radius="0.057891708" length="0.154955404" />
      </geometry>
    </collision>
  </link>
  <link name="arm_right_link5">
    <inertial>
      <origin xyz="2.6223e-06 -0.00023041 -0.024141" rpy="0.0 -0.0 0.0"/>
      <mass value="0.25139"/>
      <inertia ixx="0.00023516" ixy="-6.5868e-09" ixz="-1.9428e-08" iyy="0.00028807" iyz="-1.2108e-05" izz="0.00013068"/>
    </inertial>
    <visual>
      <geometry>
        <mesh filename="package://g1_description/meshes/arm_right_link5.STL"/>
      </geometry>
      <origin xyz="0.0 0.0 0.0" rpy="0.0 -0.0 0.0"/>
      <material name="">
        <color rgba="0.0 0.5 1.0 1.0"/>
      </material>
    </visual>
    <collision>
      <geometry>
        <cylinder radius="0.04562028545392604" length="0.13423806056380272"/>
      </geometry>
      <origin xyz="-0.00022255510134868567 -4.227476414728204e-05 -0.03344946540892124" rpy="0.0 -0.0 0.0"/>
    </collision>
  </link>
  <link name="arm_right_link6">
    <inertial>
      <origin xyz="5.0382e-06 -0.086696 0.002556" rpy="0.0 -0.0 0.0"/>
      <mass value="0.26634"/>
      <inertia ixx="0.00031434" ixy="-1.2113e-09" ixz="1.0011e-07" iyy="0.00014464" iyz="-2.033e-05" izz="0.00032449"/>
    </inertial>
    <visual>
      <geometry>
        <mesh filename="package://g1_description/meshes/arm_right_link6.STL"/>
      </geometry>
      <origin xyz="0.0 0.0 0.0" rpy="0.0 -0.0 0.0"/>
      <material name="">
        <color rgba="0.8 1.0 0.8 1.0"/>
      </material>
    </visual>
    <collision>
      <geometry>
        <cylinder radius="0.04857149291994264" length="0.18272488500982115"/>
      </geometry>
      <origin xyz="-1.7782549414354032e-05 -0.05507596972928094 -0.0017447156928267265" rpy="0.0 -1.4835107730827122 -1.56897465223053"/>
    </collision>
  </link>
  <link name="arm_right_link7">
    <inertial>
      <origin xyz="-7.5134e-05 -0.00024521 -0.016705" rpy="0.0 -0.0 0.0"/>
      <mass value="0.06158"/>
      <inertia ixx="1.8407e-05" ixy="3.4818e-08" ixz="-3.2902e-09" iyy="1.818e-05" iyz="1.1326e-07" izz="2.8547e-05"/>
    </inertial>
    <visual>
      <geometry>
        <mesh filename="package://g1_description/meshes/arm_right_link7.STL"/>
      </geometry>
      <origin xyz="0.0 0.0 0.0" rpy="0.0 -0.0 0.0"/>
      <material name="">
        <color rgba="1.0 0.5 1.0 1.0"/>
      </material>
    </visual>
    <collision>
      <geometry>
        <cylinder radius="0.030799950382754494" length="0.045999998692423105"/>
      </geometry>
      <origin xyz="-4.552953707661759e-05 -0.002300474691790042 -0.02249999972991645" rpy="3.141592653589793 -1.2246467991473532e-16 3.141592653589793"/>
    </collision>
  </link>
  <link name="hand_right_base_link">
    <inertial>
      <origin xyz="0.0014587 -0.0031343 0.065888" rpy="0.0 -0.0 0.0"/>
      <mass value="0.053878"/>
      <inertia ixx="1.4051e-05" ixy="1.9716e-08" ixz="4.0724e-07" iyy="2.1078e-05" iyz="-8.9137e-07" izz="1.6258e-05"/>
    </inertial>
    <visual>
      <geometry>
        <mesh filename="package://g1_description/meshes/hand_right_base_link.STL"/>
      </geometry>
      <origin xyz="0.0 0.0 0.0" rpy="0.0 -0.0 0.0"/>
      <material name="">
        <color rgba="0.6 0.9 0.7 1.0"/>
      </material>
    </visual>
    <!-- <collision>
      <geometry>
        <cylinder radius="0.05352416864101575" length="0.20455829612910748"/>
      </geometry>
      <origin xyz="-0.0037500834808780817 0.022967480454015726 0.10127914790064096" rpy="0.0 -0.0 0.0"/>
    </collision> -->
    <collision>
      <origin rpy="0 0 0" xyz="-0.028320312 0.04919479 0.080566406"/>
      <geometry>
        <cylinder radius="0.02397075" length="0.07856832" />
      </geometry>
    </collision>
    <collision>
      <origin xyz="-0.028320312 0.04919479 0.11985056599999999" />
      <geometry>
        <sphere radius="0.02397075" />
      </geometry>
    </collision>
    <collision>
      <origin xyz="-0.028320312 0.04919479 0.041282245999999995" />
      <geometry>
        <sphere radius="0.02397075" />
      </geometry>
    </collision>

    <collision>
      <origin rpy="0 0 0" xyz="-0.030273438 0.012316402 0.16601562"/>
      <geometry>
        <cylinder radius="0.015784662" length="0.044762216" />
      </geometry>
    </collision>
    <collision>
      <origin xyz="-0.030273438 0.012316402 0.188396728" />
      <geometry>
        <sphere radius="0.015784662" />
      </geometry>
    </collision>
    <collision>
      <origin xyz="-0.030273438 0.012316402 0.143634512" />
      <geometry>
        <sphere radius="0.015784662" />
      </geometry>
    </collision>

    <collision>
      <origin rpy="0 0 0" xyz="-0.009765625 0.0074803308 0.16552734"/>
      <geometry>
        <cylinder radius="0.019696685" length="0.05159237500000001" />
      </geometry>
    </collision>
    <collision>
      <origin xyz="-0.009765625 0.0074803308 0.1913235275" />
      <geometry>
        <sphere radius="0.019696685" />
      </geometry>
    </collision>
    <collision>
      <origin xyz="-0.009765625 0.0074803308 0.13973115249999998" />
      <geometry>
        <sphere radius="0.019696685" />
      </geometry>
    </collision>

    <collision>
      <origin rpy="0 0 0" xyz="0.013671875 0.0063972175 0.16113281"/>
      <geometry>
        <cylinder radius="0.018407468" length="0.049951904" />
      </geometry>
    </collision>
    <collision>
      <origin xyz="0.013671875 0.0063972175 0.18610876199999998" />
      <geometry>
        <sphere radius="0.018407468" />
      </geometry>
    </collision>
    <collision>
      <origin xyz="0.013671875 0.0063972175 0.136156858" />
      <geometry>
        <sphere radius="0.018407468" />
      </geometry>
    </collision>

    <collision>
      <origin rpy="0 0 0" xyz="0.034179688 0.006229302 0.14990234"/>
      <geometry>
        <cylinder radius="0.01394582" length="0.037811990000000004" />
      </geometry>
    </collision>
    <collision>
      <origin xyz="0.034179688 0.006229302 0.168808335" />
      <geometry>
        <sphere radius="0.01394582" />
      </geometry>
    </collision>
    <collision>
      <origin xyz="0.034179688 0.006229302 0.130996345" />
      <geometry>
        <sphere radius="0.01394582" />
      </geometry>
    </collision>

    <collision>
      <origin rpy="0 0 0" xyz="-0.0 -0.0021199435 0.0625"/>
      <geometry>
        <cylinder radius="0.04400892" length="0.06341296" />
      </geometry>
    </collision>
    <collision>
      <origin xyz="-0.0 -0.0021199435 0.09420648000000001" />
      <geometry>
        <sphere radius="0.04400892" />
      </geometry>
    </collision>
    <collision>
      <origin xyz="-0.0 -0.0021199435 0.030793519999999998" />
      <geometry>
        <sphere radius="0.04400892" />
      </geometry>
    </collision>
  </link>
  <joint name="idx01_waist_lift_joint" type="prismatic">
    <parent link="base_link"/>
    <child link="waist_lift_link"/>
    <origin xyz="0.0 0.0 0.3485" rpy="0.0 -0.0 0.0"/>
    <axis xyz="0.0 0.0 1.0"/>
    <limit effort="100.0" velocity="0.1" lower="0.0" upper="0.55"/>
  </joint>
  <joint name="idx02_waist_pitch_joint" type="revolute">
    <parent link="waist_lift_link"/>
    <child link="waist_pitch_link"/>
    <origin xyz="0.131 0.0 0.0" rpy="-1.5708 -0.0 0.0"/>
    <axis xyz="0.0 0.0 1.0"/>
    <limit effort="100.0" velocity="0.5" lower="0.0" upper="1.5708"/>
  </joint>
  <joint name="idx03_head_yaw_joint" type="revolute">
    <parent link="waist_pitch_link"/>
    <child link="head_yaw_link"/>
    <origin xyz="0.0 -0.441 0.0" rpy="1.5708 -0.0 0.0"/>
    <axis xyz="0.0 0.0 1.0"/>
    <limit effort="50.0" velocity="1.0" lower="-1.5708" upper="1.5708"/>
  </joint>
  <joint name="idx04_head_pitch_joint" type="revolute">
    <parent link="head_yaw_link"/>
    <child link="head_pitch_link"/>
    <origin xyz="0.050238 0.0 0.060065" rpy="-1.5708 -0.0 0.0"/>
    <axis xyz="0.0 0.0 1.0"/>
    <limit effort="50.0" velocity="1.0" lower="-0.3488" upper="0.5236"/>
  </joint>
  <joint name="idx99_arm_base_joint" type="fixed">
    <parent link="waist_pitch_link"/>
    <child link="arm_base_link"/>
    <origin xyz="0.0 -0.305 0.0" rpy="1.5708 -0.0 0.0"/>
    <axis xyz="0.0 0.0 1.0"/>
  </joint>
  <joint name="arm_left_base_joint" type="fixed">
    <parent link="arm_base_link"/>
    <child link="arm_left_base_link"/>
    <origin xyz="0.0 0.025 0.0" rpy="-1.5708 -0.0 0.0"/>
    <axis xyz="1.0 0.0 0.0"/>
  </joint>
  <joint name="arm_right_base_joint" type="fixed">
    <parent link="arm_base_link"/>
    <child link="arm_right_base_link"/>
    <origin xyz="0.0 -0.025 0.0" rpy="-1.5707926535897934 -2.653589793355844e-06 3.141592653589793"/>
    <axis xyz="1.0 0.0 0.0"/>
  </joint>
  <joint name="idx05_left_arm_joint1" type="revolute">
    <parent link="arm_left_base_link"/>
    <child link="arm_left_link1"/>
    <origin xyz="0.0 0.0 0.1859" rpy="0.0 -0.0 0.0"/>
    <axis xyz="0.0 0.0 1.0"/>
    <limit effort="60.0" velocity="3.14" lower="-3.14" upper="3.14"/>
  </joint>
  <joint name="idx06_left_arm_joint2" type="revolute">
    <parent link="arm_left_link1"/>
    <child link="arm_left_link2"/>
    <origin xyz="0.0 0.0 0.0" rpy="-1.5708 -0.0 1.5708"/>
    <axis xyz="0.0 0.0 1.0"/>
    <limit effort="60.0" velocity="3.14" lower="-2.09" upper="2.09"/>
  </joint>
  <joint name="idx07_left_arm_joint3" type="revolute">
    <parent link="arm_left_link2"/>
    <child link="arm_left_link3"/>
    <origin xyz="0.0 -0.305 0.0" rpy="-1.5707926535897934 1.5707926535897934 3.141592653589793"/>
    <axis xyz="0.0 0.0 1.0"/>
    <limit effort="60.0" velocity="3.14" lower="-3.14" upper="3.14"/>
  </joint>
  <joint name="idx08_left_arm_joint4" type="revolute">
    <parent link="arm_left_link3"/>
    <child link="arm_left_link4"/>
    <origin xyz="0.0 0.0 0.0" rpy="-1.5708 -0.0 3.1415853071795867"/>
    <axis xyz="0.0 0.0 1.0"/>
    <limit effort="60.0" velocity="3.14" lower="-1.48" upper="1.48"/>
  </joint>
  <joint name="idx09_left_arm_joint5" type="revolute">
    <parent link="arm_left_link4"/>
    <child link="arm_left_link5"/>
    <origin xyz="0.0 -0.1975 0.0" rpy="-1.5708 -0.0 -3.1415853071795867"/>
    <axis xyz="0.0 0.0 1.0"/>
    <limit effort="30.0" velocity="3.14" lower="-3.14" upper="3.14"/>
  </joint>
  <joint name="idx10_left_arm_joint6" type="revolute">
    <parent link="arm_left_link5"/>
    <child link="arm_left_link6"/>
    <origin xyz="0.0 0.0 0.0" rpy="-1.5708 -0.0 0.0"/>
    <axis xyz="0.0 0.0 1.0"/>
    <limit effort="30.0" velocity="3.14" lower="-1.74" upper="1.74"/>
  </joint>
  <joint name="idx11_left_arm_joint7" type="revolute">
    <parent link="arm_left_link6"/>
    <child link="arm_left_link7"/>
    <origin xyz="0.0 -0.1805 0.0" rpy="1.5708 -0.0 0.0"/>
    <axis xyz="0.0 0.0 1.0"/>
    <limit effort="30.0" velocity="3.14" lower="-3.14" upper="3.14"/>
  </joint>
  <joint name="left_hand_joint" type="fixed">
    <parent link="arm_left_link7"/>
    <child link="hand_left_base_link"/>
    <origin xyz="0.0 0.0 0.0" rpy="0.0 -0.0 -0.5236"/>
    <axis xyz="0.0 0.0 0.0"/>
  </joint>
  <joint name="idx12_right_arm_joint1" type="revolute">
    <parent link="arm_right_base_link"/>
    <child link="arm_right_link1"/>
    <origin xyz="0.0 0.0 0.188" rpy="0.0 -0.0 0.0"/>
    <axis xyz="0.0 0.0 1.0"/>
    <limit effort="60.0" velocity="3.14" lower="-3.14" upper="3.14"/>
  </joint>
  <joint name="idx13_right_arm_joint2" type="revolute">
    <parent link="arm_right_link1"/>
    <child link="arm_right_link2"/>
    <origin xyz="0.0 0.0 0.0" rpy="-1.5708 -0.0 -1.5708"/>
    <axis xyz="0.0 0.0 1.0"/>
    <limit effort="60.0" velocity="3.14" lower="-2.09" upper="2.09"/>
  </joint>
  <joint name="idx14_right_arm_joint3" type="revolute">
    <parent link="arm_right_link2"/>
    <child link="arm_right_link3"/>
    <origin xyz="0.0 -0.305 0.0" rpy="-1.5707926535897934 -1.5707926535897934 3.141592653589793"/>
    <axis xyz="0.0 0.0 1.0"/>
    <limit effort="60.0" velocity="3.14" lower="-3.14" upper="3.14"/>
  </joint>
  <joint name="idx15_right_arm_joint4" type="revolute">
    <parent link="arm_right_link3"/>
    <child link="arm_right_link4"/>
    <origin xyz="0.0 0.0 0.0" rpy="-1.5708 -0.0 3.1415853071795867"/>
    <axis xyz="0.0 0.0 1.0"/>
    <limit effort="60.0" velocity="3.14" lower="-1.48" upper="1.48"/>
  </joint>
  <joint name="idx16_right_arm_joint5" type="revolute">
    <parent link="arm_right_link4"/>
    <child link="arm_right_link5"/>
    <origin xyz="0.0 -0.1975 0.0" rpy="-1.5708 -0.0 -3.1415853071795867"/>
    <axis xyz="0.0 0.0 1.0"/>
    <limit effort="30.0" velocity="3.14" lower="-3.14" upper="3.14"/>
  </joint>
  <joint name="idx17_right_arm_joint6" type="revolute">
    <parent link="arm_right_link5"/>
    <child link="arm_right_link6"/>
    <origin xyz="0.0 0.0 0.0" rpy="-1.5708 -0.0 0.0"/>
    <axis xyz="0.0 0.0 1.0"/>
    <limit effort="30.0" velocity="3.14" lower="-1.74" upper="1.74"/>
  </joint>
  <joint name="idx18_right_arm_joint7" type="revolute">
    <parent link="arm_right_link6"/>
    <child link="arm_right_link7"/>
    <origin xyz="0.0 -0.1805 0.0" rpy="1.5708 -0.0 0.0"/>
    <axis xyz="0.0 0.0 1.0"/>
    <limit effort="30.0" velocity="3.14" lower="-3.14" upper="3.14"/>
  </joint>
  <joint name="right_hand_joint" type="fixed">
    <parent link="arm_right_link7"/>
    <child link="hand_right_base_link"/>
    <origin xyz="0.0 0.0 0.0" rpy="0.0 -0.0 0.5236"/>
    <axis xyz="0.0 0.0 0.0"/>
  </joint>
</robot>
