<?xml version="1.0" ?>
<!-- =================================================================================== -->
<!-- |    This document was autogenerated by xacro from xacro/genie.robot.xacro        | -->
<!-- |    EDITING THIS FILE BY HAND IS NOT RECOMMENDED                                 | -->
<!-- =================================================================================== -->
<robot name="genie">
  <!-- coarse, fine, visual -->
  <!-- <xacro:arg name="robot_model" default="G1" />
  <xacro:arg name="robot_model" default="G1" /> -->
  <!-- robot -->
  <!-- <xacro:property name="mesh_dir" value="package://${package_name}/meshes" /> -->
  <!-- Material Definition -->
  <material name="black">
    <color rgba="0.0 0.0 0.0 1.0"/>
  </material>
  <material name="blue">
    <color rgba="0.0 0.0 0.8 1.0"/>
  </material>
  <material name="green">
    <color rgba="0.0 1.0 0.0 1.0"/>
  </material>
  <material name="grey">
    <color rgba="0.2 0.2 0.2 1.0"/>
  </material>
  <material name="orange">
    <color rgba="1.0 0.4235294117647059 0.0392156862745098 1.0"/>
  </material>
  <material name="brown">
    <color rgba="0.8705882352941177 0.8117647058823529 0.7647058823529411 1.0"/>
  </material>
  <material name="red">
    <color rgba="0.8 0.0 0.0 1.0"/>
  </material>
  <material name="white">
    <color rgba="1.0 1.0 1.0 1.0"/>
  </material>
  <!-- transparent is not working properly -->
  <material name="transparent">
    <color rgba="1.0 1.0 1.0 0.999"/>
  </material>
  <material name="default">
    <color rgba="0.752941176470588 0.752941176470588 0.752941176470588 1"/>
  </material>
  <!-- main xacro -->
  <!-- main xacro -->
  <!-- main xacro -->
  <!-- <xacro:macro name="arm_l" params="debug parent_link end_link"> -->
  <!-- properties -->
  <!-- Arm -->
  <!-- assemble robot -->
  <!-- properties -->
  <!-- Base -->
  <link name="base_link">
    <inertial>
      <origin rpy="0 0 0" xyz="0.00149 -0.002673 0.117552"/>
      <mass value="74"/>
      <inertia ixx="3.032489" ixy="-0.003519" ixz="0.010648" iyy="2.833502" iyz="-0.000989" izz="4.644149"/>
    </inertial>
    <visual>
      <origin rpy="0 0 0" xyz="0 0 0"/>
      <geometry>
        <mesh filename="package://genie_robot_description/meshes/G2/T1/base_link.fbx"/>
      </geometry>
    </visual>
    <collision name="base_link_coarse_0">
      <geometry>
        <box size="0.62673163 0.17409083 0.3258258"/>
      </geometry>
      <origin rpy="0.0 -0.0 0.0" xyz="0.011247277 -0.21094544 0.16291195"/>
    </collision>
    <collision name="base_link_coarse_1">
      <geometry>
        <box size="0.62667394 0.18714839 0.3258258"/>
      </geometry>
      <origin rpy="0.0 -0.0 0.0" xyz="0.011277318 0.20441666 0.16291195"/>
    </collision>
    <collision name="base_link_coarse_2">
      <geometry>
        <box size="0.6246023 0.23870158 0.06967827"/>
      </geometry>
      <origin rpy="0.0 -0.0 0.0" xyz="0.01230073 -0.01307106 0.11483914"/>
    </collision>
  </link>
  <link name="body_link1">
    <inertial>
      <origin rpy="0 0 0" xyz="-0.107323 -0.039185 0.050115"/>
      <mass value="14.129"/>
      <inertia ixx="0.151776" ixy="-0.023402" ixz="0.090707" iyy="0.276733" iyz="0.010903" izz="0.304201"/>
    </inertial>
    <visual>
      <origin rpy="0 0 0" xyz="0 0 0"/>
      <geometry>
        <mesh filename="package://genie_robot_description/meshes/G2/T1/body_link1.fbx"/>
      </geometry>
    </visual>
    <collision name="body_link1_coarse_0">
      <geometry>
        <box size="0.146916653064989 0.21210148364482734 0.4984007347291842"/>
      </geometry>
      <origin rpy="3.131859512133172 1.1132561689202216 3.1309874363998365" xyz="-0.15756349693645624 -0.0027857167676530476 0.07797823284372236"/>
    </collision>
  </link>
  <joint name="idx01_body_joint1" type="revolute">
    <origin rpy="0 0.0 0" xyz="0.102 0 0.144"/>
    <parent link="base_link"/>
    <child link="body_link1"/>
    <axis xyz="0 1 0"/>
    <limit effort="0" lower="0" upper="1.18" velocity="0"/>
  </joint>
  <link name="body_link2">
    <inertial>
      <origin rpy="0 0 0" xyz="0.014787 -0.004305 -4.7E-05"/>
      <mass value="8.5"/>
      <inertia ixx="0.037974" ixy="-0.00042" ixz="-0.000627" iyy="0.043889" iyz="-4.9E-05" izz="0.053192"/>
    </inertial>
    <visual>
      <origin rpy="0 0 0" xyz="0 0 0"/>
      <geometry>
        <mesh filename="package://genie_robot_description/meshes/G2/T1/body_link2.fbx"/>
      </geometry>
    </visual>
    <collision name="body_link2_coarse_0">
      <origin rpy="-0.0 0.0 -0.0" xyz="0.15452659 -0.0003606267299999938 0.0005599260300000047"/>
      <geometry>
        <box size="0.17897915999999997 0.14396027 0.14191318"/>
      </geometry>
    </collision>
    <collision name="body_link2_coarse_1">
      <origin rpy="-0.0 0.0 -0.0" xyz="0.007503151999999999 0.001936905099999997 0.0"/>
      <geometry>
        <box size="0.16681123 0.19921139 0.15199995"/>
      </geometry>
    </collision>
  </link>
  <joint name="idx02_body_joint2" type="revolute">
    <origin rpy="0 0.0 0" xyz="-0.32627 0 0.15214"/>
    <parent link="body_link1"/>
    <child link="body_link2"/>
    <axis xyz="0 1 0"/>
    <limit effort="0" lower="-2.23" upper="0" velocity="0"/>
  </joint>
  <link name="body_link3">
    <inertial>
      <origin rpy="0 0 0" xyz="0.090164 -0.000208 0.000106"/>
      <mass value="11.3"/>
      <inertia ixx="0.032314" ixy="0.000154" ixz="-0.000109" iyy="0.157458" iyz="-6.8E-05" izz="0.160611"/>
    </inertial>
    <visual>
      <origin rpy="0 0 0" xyz="0 0 0"/>
      <geometry>
        <mesh filename="package://genie_robot_description/meshes/G2/T1/body_link3.fbx"/>
      </geometry>
    </visual>
    <collision name="body_link3_coarse_0">
      <origin rpy="-0.0 0.0 -0.0" xyz="-0.0068293809999999955 -7.301568999973362e-07 1.394748699999615e-05"/>
      <geometry>
        <box size="0.21439385 0.13700145 0.13697219"/>
      </geometry>
    </collision>
    <collision name="body_link3_coarse_1">
      <origin rpy="-0.0 0.0 -0.0" xyz="0.17601156 -0.012499623000000001 0.0"/>
      <geometry>
        <box size="0.15228176000000002 0.17600076 0.15199995"/>
      </geometry>
    </collision>
  </link>
  <joint name="idx03_body_joint3" type="revolute">
    <origin rpy="0 0 0" xyz="0.22875 -0.0019 0"/>
    <parent link="body_link2"/>
    <child link="body_link3"/>
    <axis xyz="1 0 0"/>
    <limit effort="0" lower="-0.52" upper="0.52" velocity="0"/>
  </joint>
  <link name="body_link4">
    <inertial>
      <origin rpy="0 0 0" xyz="-0.00051665 -0.0075684 0.05319"/>
      <mass value="2.5631"/>
      <inertia ixx="0.024754" ixy="7.8E-05" ixz="0.000303" iyy="0.015703" iyz="-0.000687" izz="0.021641"/>
    </inertial>
    <visual>
      <origin rpy="0 0 0" xyz="0 0 0"/>
      <geometry>
        <mesh filename="package://genie_robot_description/meshes/G2/T1/body_link4.fbx"/>
      </geometry>
    </visual>
    <collision name="body_link4_coarse_0">
      <origin rpy="-0.0 0.0 -0.0" xyz="-2.6226043999960647e-06 -0.0024472474999999994 0.042441845000000006"/>
      <geometry>
        <box size="0.13012743 0.19439101 0.21517658"/>
      </geometry>
    </collision>
  </link>
  <joint name="idx04_body_joint4" type="revolute">
    <origin rpy="0 0 0" xyz="0.17625 0.0019 0"/>
    <parent link="body_link3"/>
    <child link="body_link4"/>
    <axis xyz="0 -1 0"/>
    <limit effort="0" lower="-3.19" upper="0.39" velocity="0"/>
  </joint>
  <link name="body_link5">
    <inertial>
      <origin rpy="0 0 0" xyz="-0.018295 0.00022303 0.20326"/>
      <mass value="17.326"/>
      <inertia ixx="0.324244" ixy="0.000839" ixz="0.025409" iyy="0.336475" iyz="0.000377" izz="0.148307"/>
    </inertial>
    <visual>
      <origin rpy="0 0 0" xyz="0 0 0"/>
      <geometry>
        <mesh filename="package://genie_robot_description/meshes/G2/T1/body_link5.fbx"/>
      </geometry>
    </visual>
    <collision name="body_link5_coarse_0">
      <origin rpy="-0.0 0.0 -0.0" xyz="0.0022273064000000037 3.695487999999525e-06 0.242803"/>
      <geometry>
        <box size="0.17862797 0.2499926 0.2571556"/>
      </geometry>
    </collision>
    <collision name="body_link5_coarse_1">
      <origin rpy="-0.0 0.0 -0.0" xyz="-0.12621355 -0.004532456399999996 0.23204112"/>
      <geometry>
        <box size="0.088994026 0.15906501 0.19257259999999998"/>
      </geometry>
    </collision>
    <collision name="body_link5_coarse_2">
      <origin rpy="-0.0 0.0 -0.0" xyz="0.12886572 0.0 0.26373816"/>
      <geometry>
        <box size="0.07847308999999998 0.074500084 0.10599135999999998"/>
      </geometry>
    </collision>
    <collision name="body_link5_coarse_3">
      <origin rpy="-0.0 0.0 -0.0" xyz="-0.00021123886000000425 1.1920928999487046e-07 0.054496765"/>
      <geometry>
        <box size="0.15000057 0.16199994 0.11851597"/>
      </geometry>
    </collision>
  </link>
  <joint name="idx05_body_joint5" type="revolute">
    <origin rpy="0 0 0" xyz="0.0002112 -0.0024 0.14475"/>
    <parent link="body_link4"/>
    <child link="body_link5"/>
    <axis xyz="0 0 1"/>
    <limit effort="0" lower="-3.2" upper="3.2" velocity="0"/>
  </joint>
  <!-- Arm -->
  <link name="arm_base_link"/>
  <joint name="idx20_arm_base_joint" type="fixed">
    <origin rpy="-1.5707963267948966 0 0" xyz="0.0 0.0 0.3085"/>
    <parent link="body_link5"/>
    <child link="arm_base_link"/>
    <axis xyz="0 0 0"/>
  </joint>
  <!-- Chassis -->
  <link name="chassis_link">
    <inertial>
      <origin rpy="0 0 0" xyz="-0.0018354 0.00048186 0.098072"/>
      <mass value="69.65"/>
      <inertia ixx="0.54948" ixy="-0.00025682" ixz="0.021942" iyy="0.94415" iyz="6.8345E-06" izz="1.2015"/>
    </inertial>
    <!-- <visual>
        <origin
          xyz="0 0 0"
          rpy="0 0 0" />
        <geometry>
          <mesh
            filename="${mesh_dir}/G2/chassis_link.STL" />
        </geometry>
        <material
          name="chassis_material">
          <color
            rgba="0.75294 0.75294 0.75294 1" />
        </material>
      </visual>
      <collision>
        <origin
          xyz="0 0 0"
          rpy="0 0 0" />
        <geometry>
          <mesh
            filename="${mesh_dir}/G2/chassis_link.STL" />
        </geometry>
      </collision> -->
  </link>
  <link name="chassis_lwheel_front_link1">
    <inertial>
      <origin rpy="0 0 0" xyz="4.8347E-05 -0.021386 -0.055149"/>
      <mass value="0.59301"/>
      <inertia ixx="0.001129" ixy="-6.1014E-07" ixz="-1.4058E-06" iyy="0.00087934" iyz="-0.00039606" izz="0.00056331"/>
    </inertial>
    <visual>
      <origin rpy="0 0 0" xyz="0 0 0"/>
      <geometry>
        <mesh filename="package://genie_robot_description/meshes/G2/T1/zuoqianxuan.fbx"/>
      </geometry>
    </visual>
    <!-- <collision>
        <origin
          xyz="0 0 0"
          rpy="0 0 0" />
        <geometry>
          <mesh
            filename="${mesh_dir}/G2/T1/zuoqianxuan.fbx" />
        </geometry>
      </collision> -->
  </link>
  <joint name="idx111_chassis_lwheel_front_joint1" type="revolute">
    <origin rpy="0 0 0" xyz="0.23 0.218 0.16675"/>
    <parent link="chassis_link"/>
    <child link="chassis_lwheel_front_link1"/>
    <axis xyz="0 0 1"/>
    <limit effort="10" lower="-2.97" upper="2.97" velocity="10"/>
  </joint>
  <link name="chassis_lwheel_front_link2">
    <inertial>
      <origin rpy="0 0 0" xyz="-2.3442E-06 -0.0013086 1.0892E-05"/>
      <mass value="3.6283"/>
      <inertia ixx="0.0058835" ixy="2.2411E-07" ixz="3.433E-08" iyy="0.010779" iyz="3.6966E-07" izz="0.0058842"/>
    </inertial>
    <visual>
      <origin rpy="0 0 0" xyz="0 0 0"/>
      <geometry>
        <mesh filename="package://genie_robot_description/meshes/G2/T1/zuoqianxing.fbx"/>
      </geometry>
    </visual>
    <!-- <collision>
        <origin
          xyz="0 0 0"
          rpy="${PI_2} 0 0" />
        <geometry>
          <cylinder radius="0.07" length="0.04" />
        </geometry>
      </collision> -->
  </link>
  <joint name="idx112_chassis_lwheel_front_joint2" type="continuous">
    <origin rpy="0 0 0" xyz="0 -5E-05 -0.13675"/>
    <parent link="chassis_lwheel_front_link1"/>
    <child link="chassis_lwheel_front_link2"/>
    <axis xyz="0 1 0"/>
    <limit effort="10" lower="0" upper="0" velocity="10"/>
  </joint>
  <link name="chassis_rwheel_front_link1">
    <inertial>
      <origin rpy="0 0 0" xyz="-4.8347E-05 0.021386 -0.055149"/>
      <mass value="0.59301"/>
      <inertia ixx="0.001129" ixy="-6.1014E-07" ixz="1.4058E-06" iyy="0.00087934" iyz="0.00039606" izz="0.00056331"/>
    </inertial>
    <visual>
      <origin rpy="0 0 0" xyz="0 0 0"/>
      <geometry>
        <mesh filename="package://genie_robot_description/meshes/G2/T1/youqianxuan.fbx"/>
      </geometry>
    </visual>
    <!-- <collision>
        <origin
          xyz="0 0 0"
          rpy="0 0 0" />
        <geometry>
          <mesh
            filename="${mesh_dir}/GG2/T1/youqianxuan.fbx" />
        </geometry>
      </collision> -->
  </link>
  <joint name="idx131_chassis_rwheel_front_joint1" type="revolute">
    <origin rpy="0 0 0" xyz="0.23 -0.218 0.16675"/>
    <parent link="chassis_link"/>
    <child link="chassis_rwheel_front_link1"/>
    <axis xyz="0 0 1"/>
    <limit effort="10" lower="-2.97" upper="2.97" velocity="10"/>
  </joint>
  <link name="chassis_rwheel_front_link2">
    <inertial>
      <origin rpy="0 0 0" xyz="2.3442E-06 0.0013086 1.0892E-05"/>
      <mass value="3.6283"/>
      <inertia ixx="0.0058835" ixy="2.2411E-07" ixz="-3.433E-08" iyy="0.010779" iyz="-3.6966E-07" izz="0.0058842"/>
    </inertial>
    <visual>
      <origin rpy="0 0 0" xyz="0 0 0"/>
      <geometry>
        <mesh filename="package://genie_robot_description/meshes/G2/T1/youqianxing.fbx"/>
      </geometry>
    </visual>
    <!-- <collision>
        <origin
          xyz="0 0 0"
          rpy="${PI_2} 0 0" />
        <geometry>
          <cylinder radius="0.07" length="0.04" />
        </geometry>
      </collision> -->
  </link>
  <joint name="idx132_chassis_rwheel_front_joint2" type="continuous">
    <origin rpy="0 0 0" xyz="0 5E-05 -0.13675"/>
    <parent link="chassis_rwheel_front_link1"/>
    <child link="chassis_rwheel_front_link2"/>
    <axis xyz="0 1 0"/>
    <limit effort="10" lower="0" upper="0" velocity="10"/>
  </joint>
  <link name="chassis_rwheel_rear_link1">
    <inertial>
      <origin rpy="0 0 0" xyz="-4.8347E-05 0.021386 -0.055149"/>
      <mass value="0.59301"/>
      <inertia ixx="0.001129" ixy="-6.1014E-07" ixz="1.4058E-06" iyy="0.00087934" iyz="0.00039606" izz="0.00056331"/>
    </inertial>
    <visual>
      <origin rpy="0 0 0" xyz="0 0 0"/>
      <geometry>
        <mesh filename="package://genie_robot_description/meshes/G2/T1/youhouxuan.fbx"/>
      </geometry>
    </visual>
    <!-- <collision>
        <origin
          xyz="0 0 0"
          rpy="0 0 0" />
        <geometry>
          <mesh
            filename="${mesh_dir}/G2/T1/youhouxuan.fbx" />
        </geometry>
      </collision> -->
  </link>
  <joint name="idx141_chassis_rwheel_rear_joint1" type="revolute">
    <origin rpy="0 0 0" xyz="-0.23 -0.218 0.16675"/>
    <parent link="chassis_link"/>
    <child link="chassis_rwheel_rear_link1"/>
    <axis xyz="0 0 1"/>
    <limit effort="10" lower="-2.97" upper="2.97" velocity="10"/>
  </joint>
  <link name="chassis_rwheel_rear_link2">
    <inertial>
      <origin rpy="0 0 0" xyz="2.3442E-06 0.0013086 1.0892E-05"/>
      <mass value="3.6283"/>
      <inertia ixx="0.0058835" ixy="2.2411E-07" ixz="-3.433E-08" iyy="0.010779" iyz="-3.6966E-07" izz="0.0058842"/>
    </inertial>
    <visual>
      <origin rpy="0 0 0" xyz="0 0 0"/>
      <geometry>
        <mesh filename="package://genie_robot_description/meshes/G2/T1/youhouxing.fbx"/>
      </geometry>
    </visual>
    <!-- <collision>
        <origin
          xyz="0 0 0"
          rpy="${PI_2} 0 0" />
        <geometry>
          <cylinder radius="0.07" length="0.04" />
        </geometry>
      </collision> -->
  </link>
  <joint name="idx142_chassis_rwheel_rear_joint2" type="continuous">
    <origin rpy="0 0 0" xyz="0 5E-05 -0.13675"/>
    <parent link="chassis_rwheel_rear_link1"/>
    <child link="chassis_rwheel_rear_link2"/>
    <axis xyz="0 1 0"/>
    <limit effort="10" lower="0" upper="0" velocity="10"/>
  </joint>
  <link name="chassis_lwheel_rear_link1">
    <inertial>
      <origin rpy="0 0 0" xyz="4.8347E-05 -0.021386 -0.055149"/>
      <mass value="0.59301"/>
      <inertia ixx="0.001129" ixy="-6.1014E-07" ixz="-1.4058E-06" iyy="0.00087934" iyz="-0.00039606" izz="0.00056331"/>
    </inertial>
    <visual>
      <origin rpy="0 0 0" xyz="0 0 0"/>
      <geometry>
        <mesh filename="package://genie_robot_description/meshes/G2/T1/zuohouxuan.fbx"/>
      </geometry>
    </visual>
    <!-- <collision>
        <origin
          xyz="0 0 0"
          rpy="0 0 0" />
        <geometry>
          <mesh
            filename="${mesh_dir}/G2/T1/zuohouxuan.fbx" />
        </geometry>
      </collision> -->
  </link>
  <joint name="idx121_chassis_lwheel_rear_joint1" type="revolute">
    <origin rpy="0 0 0" xyz="-0.23 0.218 0.16675"/>
    <parent link="chassis_link"/>
    <child link="chassis_lwheel_rear_link1"/>
    <axis xyz="0 0 1"/>
    <limit effort="10" lower="-2.97" upper="2.97" velocity="10"/>
  </joint>
  <link name="chassis_lwheel_rear_link2">
    <inertial>
      <origin rpy="0 0 0" xyz="-2.3442E-06 -0.0013086 1.0892E-05"/>
      <mass value="3.6283"/>
      <inertia ixx="0.0058835" ixy="2.2411E-07" ixz="3.433E-08" iyy="0.010779" iyz="3.6966E-07" izz="0.0058842"/>
    </inertial>
    <visual>
      <origin rpy="0 0 0" xyz="0 0 0"/>
      <geometry>
        <mesh filename="package://genie_robot_description/meshes/G2/T1/zuohouxing.fbx"/>
      </geometry>
    </visual>
    <!-- <collision>
        <origin
          xyz="0 0 0"
          rpy="${PI_2} 0 0" />
        <geometry>
          <cylinder radius="0.07" length="0.04" />
        </geometry>
      </collision> -->
  </link>
  <joint name="idx122_chassis_lwheel_rear_joint2" type="continuous">
    <origin rpy="0 0 0" xyz="0 -5E-05 -0.13675"/>
    <parent link="chassis_lwheel_rear_link1"/>
    <child link="chassis_lwheel_rear_link2"/>
    <axis xyz="0 1 0"/>
    <limit effort="10" lower="0" upper="0" velocity="10"/>
  </joint>
  <joint name="idx100_chassis_base_joint" type="fixed">
    <origin rpy="0 0 0" xyz="0 0 0"/>
    <parent link="base_link"/>
    <child link="chassis_link"/>
  </joint>
  <!-- Head -->
  <link name="head_base_link"/>
  <joint name="idx10_head_base_joint" type="fixed">
    <origin rpy="0 0 0" xyz="-0.013211 0 0.35976"/>
    <parent link="body_link5"/>
    <child link="head_base_link"/>
    <axis xyz="0 0 0"/>
  </joint>
  <link name="head_link1">
    <inertial>
      <origin rpy="0 0 0" xyz="0.0049863 1.3573E-09 0.13188"/>
      <mass value="0.29497"/>
      <inertia ixx="0.000842" ixy="0" ixz="-0.000128" iyy="0.00087" iyz="0" izz="0.000126"/>
    </inertial>
    <visual>
      <origin rpy="0 0 0" xyz="0 0 0"/>
      <geometry>
        <mesh filename="package://genie_robot_description/meshes/G2/T1/head_link1.fbx"/>
      </geometry>
    </visual>
    <collision name="head_link1_coarse_0">
      <origin rpy="-0.0 0.0 -0.0" xyz="-0.0008687973000000015 0.00011444092000000017 0.08756709"/>
      <geometry>
        <box size="0.053949356 0.052459717 0.10913419999999999"/>
      </geometry>
    </collision>
    <collision name="head_link1_coarse_1">
      <origin rpy="-0.0 0.0 -0.0" xyz="0.0298028 -0.0004730224599999999 0.17724355"/>
      <geometry>
        <box size="0.029593468000000005 0.05860901 0.06831196"/>
      </geometry>
    </collision>
  </link>
  <joint name="idx11_head_joint1" type="revolute">
    <origin rpy="0 0 0" xyz="0 0 0"/>
    <parent link="head_base_link"/>
    <child link="head_link1"/>
    <axis xyz="0 0 1"/>
    <limit effort="0" lower="-3.14" upper="3.14" velocity="0"/>
  </joint>
  <link name="head_link2">
    <inertial>
      <origin rpy="0 0 0" xyz="-0.031307 -0.0003235 -0.00019793"/>
      <mass value="0.34548"/>
      <inertia ixx="0.000179" ixy="-3E-06" ixz="-1E-06" iyy="0.000146" iyz="0" izz="0.000189"/>
    </inertial>
    <visual>
      <origin rpy="0 0 0" xyz="0 0 0"/>
      <geometry>
        <mesh filename="package://genie_robot_description/meshes/G2/T1/head_link2.fbx"/>
      </geometry>
    </visual>
    <collision name="head_link2_coarse_0">
      <origin rpy="-0.0 0.0 -0.0" xyz="-0.012349606 -0.04070282 0.0040000677"/>
      <geometry>
        <box size="0.012000083999999998 0.016403198000000008 0.01699996"/>
      </geometry>
    </collision>
    <collision name="head_link2_coarse_1">
      <origin rpy="-0.0 0.0 -0.0" xyz="-0.027349949 0.0 5.066394800000082e-05"/>
      <geometry>
        <box size="0.06199932 0.06500244 0.05789876"/>
      </geometry>
    </collision>
  </link>
  <joint name="idx12_head_joint2" type="revolute">
    <origin rpy="0 0 0" xyz="0.03735 0 0.183"/>
    <parent link="head_link1"/>
    <child link="head_link2"/>
    <axis xyz="-1 0 0"/>
    <limit effort="0" lower="-0.35" upper="0.35" velocity="0"/>
  </joint>
  <link name="head_link3">
    <inertial>
      <origin rpy="0 0 0" xyz="0.031207 -0.002346 0.034439"/>
      <mass value="1.88"/>
      <inertia ixx="0.006816" ixy="-0.000139" ixz="0.002671" iyy="0.009005" iyz="0.000143" izz="0.00568"/>
    </inertial>
    <visual>
      <origin rpy="0 0 0" xyz="0 0 0"/>
      <geometry>
        <mesh filename="package://genie_robot_description/meshes/G2/T1/head_link3.fbx"/>
      </geometry>
    </visual>
    <collision name="head_link3_coarse_0">
      <origin rpy="-0.0 0.0 -0.0" xyz="-0.013225079 -0.002861023000000004 0.11197662"/>
      <geometry>
        <box size="0.13921642 0.15089417 0.030090331999999997"/>
      </geometry>
    </collision>
    <collision name="head_link3_coarse_1">
      <origin rpy="-0.0 0.0 -0.0" xyz="0.08184695 -0.004905700700000001 -0.027374268"/>
      <geometry>
        <box size="0.05158186000000001 0.1085968 0.052001953000000004"/>
      </geometry>
    </collision>
    <collision name="head_link3_coarse_2">
      <origin rpy="-0.0 0.0 -0.0" xyz="0.034275055 -0.0023956299000000014 0.04024887"/>
      <geometry>
        <box size="0.14655018 0.12200928 0.10849762"/>
      </geometry>
    </collision>
  </link>
  <joint name="idx13_head_joint3" type="revolute">
    <origin rpy="0 0 0" xyz="-0.03735 0.0024 0"/>
    <parent link="head_link2"/>
    <child link="head_link3"/>
    <axis xyz="0 1 0"/>
    <limit effort="0" lower="-0.52" upper="0.52" velocity="0"/>
  </joint>
  <!-- properties -->
  <!-- Arm -->
  <link name="arm_l_link1">
    <inertial>
      <origin rpy="0 0 0" xyz="1.875E-05 0.006003 0.1438"/>
      <mass value="2.0926"/>
      <inertia ixx="0.00515643" ixy="2.62E-06" ixz="3.78E-06" iyy="0.0055553" iyz="0.00038404" izz="0.00198037"/>
    </inertial>
    <visual name="default_visual">
      <geometry>
        <mesh filename="package://genie_robot_description/meshes/arm/Link1_P6.STL"/>
      </geometry>
      <origin rpy="0 0 0" xyz="0 0 0"/>
      <material name="default"/>
    </visual>
    <collision name="arm_l_link1_coarse_0">
      <origin rpy="-0.0 0.0 -0.0" xyz="-0.0004959106400000004 -1.945484272123522e-19 0.17853164999999982"/>
      <geometry>
        <sphere radius="0.06300305"/>
      </geometry>
    </collision>
    <collision name="arm_l_link1_coarse_1">
      <origin rpy="-0.0 0.0 -0.0" xyz="-0.009067535000000005 -0.004526614999999998 0.12142944"/>
      <geometry>
        <sphere radius="0.06310095999999998"/>
      </geometry>
    </collision>
  </link>
  <joint name="idx21_arm_l_joint1" type="revolute">
    <origin rpy="0 0 0" xyz="0 0 0.069"/>
    <parent link="arm_base_link"/>
    <child link="arm_l_link1"/>
    <axis xyz="0 0 1"/>
    <limit effort="108" lower="-3.1067" upper="3.1067" velocity="3.1416"/>
  </joint>
  <link name="arm_l_link2">
    <inertial>
      <origin rpy="0 0 0" xyz="-7.03E-06 0.05542 0.010995"/>
      <mass value="1.9432"/>
      <inertia ixx="0.01035460" ixy="-5.59E-06" ixz="2.06E-06" iyy="0.00316139" iyz="-0.00119042" izz="0.00953530"/>
    </inertial>
    <visual name="default_visual">
      <geometry>
        <mesh filename="package://genie_robot_description/meshes/arm/Link2_P6.STL"/>
      </geometry>
      <origin rpy="0 0 0" xyz="0 0 0"/>
      <material name="default"/>
    </visual>
    <collision name="arm_l_link2_coarse_0">
      <origin rpy="-0.0 0.0 -0.0" xyz="-0.004974365200000007 0.006954193000000001 -0.01338499999999954"/>
      <geometry>
        <sphere radius="0.07498259999999999"/>
      </geometry>
    </collision>
    <collision name="arm_l_link2_coarse_1">
      <origin rpy="-0.0 0.0 -0.0" xyz="-0.004501343000000002 0.0072174069999999925 0.01335839199999999"/>
      <geometry>
        <sphere radius="0.074983405"/>
      </geometry>
    </collision>
    <collision name="arm_l_link2_coarse_2">
      <origin rpy="-0.0 0.0 -0.0" xyz="0.0010223389000000094 0.1094703699999999 0.0012550354000000002"/>
      <geometry>
        <sphere radius="0.06165532800000009"/>
      </geometry>
    </collision>
  </link>
  <joint name="idx22_arm_l_joint2" type="revolute">
    <origin rpy="1.5708 0 0" xyz="0 0 0.1745"/>
    <parent link="arm_l_link1"/>
    <child link="arm_l_link2"/>
    <axis xyz="0 0 1"/>
    <limit effort="108" lower="-2.0944" upper="2.0944" velocity="3.1416"/>
  </joint>
  <link name="arm_l_link3">
    <inertial>
      <origin rpy="0 0 0" xyz="0.0087411 0.0019043 0.23487"/>
      <mass value="1.6913"/>
      <inertia ixx="0.00650115" ixy="3.338E-05" ixz="0.00079318" iyy="0.00689453" iyz="0.00017675" izz="0.00164437"/>
    </inertial>
    <visual name="default_visual">
      <geometry>
        <mesh filename="package://genie_robot_description/meshes/arm/Link3_P6.STL"/>
      </geometry>
      <origin rpy="0 0 0" xyz="0 0 0"/>
      <material name="default"/>
    </visual>
    <!-- <collision name="arm_l_link3_coarse_0">
          <geometry>
            <sphere radius="0.073823" />
          </geometry>
          <origin xyz="-0.002493036787214638 -0.0 0.19334736154660487"
            rpy="0.0 -0.0 0.0" />
        </collision>
        <collision name="arm_l_link3_coarse_1">
          <geometry>
            <sphere radius="0.070649" />
          </geometry>
          <origin xyz="0.015268963212785362 0.0 0.26469536154660483"
            rpy="0.0 -0.0 0.0" />
        </collision> -->
    <collision name="arm_l_link3_coarse_0">
      <origin rpy="-0.0 0.0 -0.0" xyz="0.0007324219000000129 -0.00011956971000000159 0.19502639999999993"/>
      <geometry>
        <sphere radius="0.06603523000000001"/>
      </geometry>
    </collision>
    <collision name="arm_l_link3_coarse_1">
      <origin rpy="-0.0 0.0 -0.0" xyz="0.01489257800000002 -0.001605738900000001 0.2844047500000005"/>
      <geometry>
        <sphere radius="0.061628755000000014"/>
      </geometry>
    </collision>
  </link>
  <joint name="idx23_arm_l_joint3" type="revolute">
    <origin rpy="-1.5708 0 0" xyz="0 0 0"/>
    <parent link="arm_l_link2"/>
    <child link="arm_l_link3"/>
    <axis xyz="0 0 1"/>
    <limit effort="66" lower="-3.1067" upper="3.1067" velocity="3.1416"/>
  </joint>
  <link name="arm_l_link4">
    <inertial>
      <origin rpy="0 0 0" xyz="-0.0086935 0.045984 0.011135"/>
      <mass value="1.5332"/>
      <inertia ixx="0.00527549" ixy="-0.00061752" ixz="0.00012895" iyy="0.00208586" iyz="-6.871E-04" izz="0.00489695"/>
    </inertial>
    <visual name="default_visual">
      <geometry>
        <mesh filename="package://genie_robot_description/meshes/arm/Link4_P6.STL"/>
      </geometry>
      <origin rpy="0 0 0" xyz="0 0 0"/>
      <material name="default"/>
    </visual>
    <collision name="arm_l_link4_coarse_0">
      <origin rpy="-0.0 0.0 -0.0" xyz="-0.003173828099999999 0.004589356499999994 -0.011833649999999894"/>
      <geometry>
        <sphere radius="0.06991342"/>
      </geometry>
    </collision>
    <collision name="arm_l_link4_coarse_1">
      <origin rpy="-0.0 0.0 -0.0" xyz="-0.004821777299999992 0.004589356499999994 0.011815094000000035"/>
      <geometry>
        <sphere radius="0.069075850000000004"/>
      </geometry>
    </collision>
    <collision name="arm_l_link4_coarse_2">
      <origin rpy="-0.0 0.0 -0.0" xyz="-0.012329101999999996 0.09249994000000004 0.003940582300000001"/>
      <geometry>
        <sphere radius="0.05453134999999996"/>
      </geometry>
    </collision>
  </link>
  <joint name="idx24_arm_l_joint4" type="revolute">
    <origin rpy="1.5708 0 0" xyz="0.018 0 0.287"/>
    <parent link="arm_l_link3"/>
    <child link="arm_l_link4"/>
    <axis xyz="0 0 1"/>
    <limit effort="66" lower="-2.5307" upper="1.0472" velocity="3.1416"/>
  </joint>
  <link name="arm_l_link5">
    <inertial>
      <origin rpy="0 0 0" xyz="-0.00036467 0.0001479 0.19902"/>
      <mass value="2.0095"/>
      <inertia ixx="0.00569595" ixy="-3.48E-05" ixz="-4.596E-05" iyy="0.00527845" iyz="2.404E-05" izz="0.00211298"/>
    </inertial>
    <visual name="default_visual">
      <geometry>
        <mesh filename="package://genie_robot_description/meshes/arm/Link5_P6.STL"/>
      </geometry>
      <origin rpy="0 0 0" xyz="0 0 0"/>
      <material name="default"/>
    </visual>
    <collision name="arm_l_link5_coarse_0">
      <origin rpy="-0.0 0.0 -0.0" xyz="0.001464843800000002 0.02441250000000014 0.217128723000000035"/>
      <geometry>
        <sphere radius="0.0521019999999999"/>
      </geometry>
    </collision>
    <collision name="arm_l_link5_coarse_1">
      <origin rpy="-0.0 0.0 -0.0" xyz="-0.0015869140999999996 -0.02448128500000002 0.21791775999999984"/>
      <geometry>
        <sphere radius="0.05214000000001"/>
      </geometry>
    </collision>
    <collision name="arm_l_link5_coarse_2">
      <origin rpy="-0.0 0.0 -0.0" xyz="0.001464843800000002 0.02841250000000014 0.287128723000000035"/>
      <geometry>
        <sphere radius="0.0521019999999999"/>
      </geometry>
    </collision>
    <collision name="arm_l_link5_coarse_3">
      <origin rpy="-0.0 0.0 -0.0" xyz="-0.0015869140999999996 -0.02848128500000002 0.2891775999999984"/>
      <geometry>
        <sphere radius="0.05214000000001"/>
      </geometry>
    </collision>
    <collision name="arm_l_link5_coarse_4">
      <origin rpy="-0.0 0.0 -0.0" xyz="-0.0009765625000000072 0.0031794570000000027 0.1568145800000001"/>
      <geometry>
        <sphere radius="0.05447049"/>
      </geometry>
    </collision>
  </link>
  <joint name="idx25_arm_l_joint5" type="revolute">
    <origin rpy="-1.5708 0 0" xyz="-0.018 0 0"/>
    <parent link="arm_l_link4"/>
    <child link="arm_l_link5"/>
    <axis xyz="0 0 1"/>
    <limit effort="18" lower="-3.1067" upper="3.1067" velocity="3.1416"/>
  </joint>
  <link name="arm_l_link6">
    <inertial>
      <origin rpy="0 0 0" xyz="-0.004911 0.00027206 -8.14E-05"/>
      <mass value="0.67002"/>
      <inertia ixx="0.00048932" ixy="-1.41E-06" ixz="1.89E-06" iyy="0.00040004" iyz="6.4E-07" izz="0.00036921"/>
    </inertial>
    <visual name="default_visual">
      <geometry>
        <mesh filename="package://genie_robot_description/meshes/arm/Link6_P6.STL"/>
      </geometry>
      <origin rpy="0 0 0" xyz="0 0 0"/>
      <material name="default"/>
    </visual>
    <collision name="arm_l_link6_coarse_0">
      <origin rpy="-0.0 0.0 -0.0" xyz="1.4374967121801579e-18 -1.7293193529986862e-19 5.755390971698752e-19"/>
      <geometry>
        <sphere radius="0.052349735"/>
      </geometry>
    </collision>
  </link>
  <joint name="idx26_arm_l_joint6" type="revolute">
    <origin rpy="1.5708 0 0" xyz="0 0 0.314"/>
    <parent link="arm_l_link5"/>
    <child link="arm_l_link6"/>
    <axis xyz="0 0 1"/>
    <limit effort="18" lower="-1.0472" upper="1.0472" velocity="3.1416"/>
  </joint>
  <link name="arm_l_link7">
    <inertial>
      <origin rpy="0 0 0" xyz="0.04513370 0.00004672 0.00607482"/>
      <mass value="0.31657"/>
      <inertia ixx="0.00037121" ixy="4.6E-07" ixz="-8.646E-05" iyy="0.00067341" iyz="-5.1E-07" izz="0.00053248"/>
    </inertial>
    <visual name="default_visual">
      <geometry>
        <mesh filename="package://genie_robot_description/meshes/arm/Link7_P6.STL"/>
      </geometry>
      <origin rpy="0 0 0" xyz="0 0 0"/>
      <material name="default"/>
    </visual>
    <collision name="arm_l_link7_coarse_0">
      <origin rpy="-0.0 0.0 -0.0" xyz="0.05914825400000002 0.0 0.0"/>
      <geometry>
        <sphere radius="0.04457995700000001"/>
      </geometry>
    </collision>
    <collision name="arm_l_link7_coarse_1">
      <origin rpy="-0.0 0.0 -0.0" xyz="0.0 0.0 0.02"/>
      <geometry>
        <sphere radius="0.04457995700000001"/>
      </geometry>
    </collision>
    <collision name="arm_l_link7_coarse_2">
      <origin rpy="-0.0 0.0 -0.0" xyz="0.0 0.0 -0.02"/>
      <geometry>
        <sphere radius="0.04457995700000001"/>
      </geometry>
    </collision>
  </link>
  <joint name="idx27_arm_l_joint7" type="revolute">
    <origin rpy="1.5708 0 1.5708" xyz="0 0 0"/>
    <parent link="arm_l_link6"/>
    <child link="arm_l_link7"/>
    <axis xyz="0 0 1"/>
    <limit effort="18" lower="-1.5708" upper="1.5708" velocity="3.1416"/>
  </joint>
  <link name="arm_l_end_link"/>
  <joint name="arm_l_end_joint" type="fixed">
    <origin rpy="3.1416 -1.5708 0" xyz="0.088 0.0 0.0"/>
    <parent link="arm_l_link7"/>
    <child link="arm_l_end_link"/>
  </joint>
  <!-- properties -->
  <!-- Arm -->
  <link name="arm_r_link1">
    <inertial>
      <origin rpy="0 0 0" xyz="1.875E-05 0.006003 0.1438"/>
      <mass value="2.0926"/>
      <inertia ixx="0.00515643" ixy="2.62E-06" ixz="3.78E-06" iyy="0.0055553" iyz="0.00038404" izz="0.00198037"/>
    </inertial>
    <visual name="default_visual">
      <geometry>
        <mesh filename="package://genie_robot_description/meshes/arm/Link1_P6.STL"/>
      </geometry>
      <origin rpy="0 0 0" xyz="0 0 0"/>
      <material name="default"/>
    </visual>
    <collision name="arm_r_link1_coarse_0">
      <origin rpy="-0.0 0.0 -0.0" xyz="-0.0004959106400000004 -1.945484272123522e-19 0.17853164999999982"/>
      <geometry>
        <sphere radius="0.06300305"/>
      </geometry>
    </collision>
    <collision name="arm_r_link1_coarse_1">
      <origin rpy="-0.0 0.0 -0.0" xyz="-0.009067535000000005 -0.004526614999999998 0.12142944"/>
      <geometry>
        <sphere radius="0.06310095999999998"/>
      </geometry>
    </collision>
  </link>
  <joint name="idx61_arm_r_joint1" type="revolute">
    <origin rpy="3.141592653589793 0 0" xyz="0 0 -0.069"/>
    <parent link="arm_base_link"/>
    <child link="arm_r_link1"/>
    <axis xyz="0 0 1"/>
    <limit effort="108" lower="-3.1067" upper="3.1067" velocity="3.1416"/>
  </joint>
  <link name="arm_r_link2">
    <inertial>
      <origin rpy="0 0 0" xyz="-7.03E-06 0.05542 0.010995"/>
      <mass value="1.9432"/>
      <inertia ixx="0.01035460" ixy="-5.59E-06" ixz="2.06E-06" iyy="0.00316139" iyz="-0.00119042" izz="0.00953530"/>
    </inertial>
    <visual name="default_visual">
      <geometry>
        <mesh filename="package://genie_robot_description/meshes/arm/Link2_P6.STL"/>
      </geometry>
      <origin rpy="0 0 0" xyz="0 0 0"/>
      <material name="default"/>
    </visual>
    <collision name="arm_r_link2_coarse_0">
      <origin rpy="-0.0 0.0 -0.0" xyz="-0.004974365200000007 0.006954193000000001 -0.01338499999999954"/>
      <geometry>
        <sphere radius="0.07498259999999999"/>
      </geometry>
    </collision>
    <collision name="arm_r_link2_coarse_1">
      <origin rpy="-0.0 0.0 -0.0" xyz="-0.004501343000000002 0.0072174069999999925 0.01335839199999999"/>
      <geometry>
        <sphere radius="0.074983405"/>
      </geometry>
    </collision>
    <collision name="arm_r_link2_coarse_2">
      <origin rpy="-0.0 0.0 -0.0" xyz="0.0010223389000000094 0.1094703699999999 0.0012550354000000002"/>
      <geometry>
        <sphere radius="0.06165532800000009"/>
      </geometry>
    </collision>
  </link>
  <joint name="idx62_arm_r_joint2" type="revolute">
    <origin rpy="1.5707963267948966 0 0" xyz="0 0 0.1745"/>
    <parent link="arm_r_link1"/>
    <child link="arm_r_link2"/>
    <axis xyz="0 0 1"/>
    <limit effort="108" lower="-2.0944" upper="2.0944" velocity="3.1416"/>
  </joint>
  <link name="arm_r_link3">
    <inertial>
      <origin rpy="0 0 0" xyz="0.0087411 0.0019043 0.23487"/>
      <mass value="1.6913"/>
      <inertia ixx="0.00650115" ixy="3.338E-05" ixz="0.00079318" iyy="0.00689453" iyz="0.00017675" izz="0.00164437"/>
    </inertial>
    <visual name="default_visual">
      <geometry>
        <mesh filename="package://genie_robot_description/meshes/arm/Link3_P6.STL"/>
      </geometry>
      <origin rpy="0 0 0" xyz="0 0 0"/>
      <material name="default"/>
    </visual>
    <collision name="arm_r_link3_coarse_0">
      <origin rpy="-0.0 0.0 -0.0" xyz="0.0007324219000000129 -0.00011956971000000159 0.19502639999999993"/>
      <geometry>
        <sphere radius="0.06603523000000001"/>
      </geometry>
    </collision>
    <collision name="arm_r_link3_coarse_1">
      <origin rpy="-0.0 0.0 -0.0" xyz="0.01489257800000002 -0.001605738900000001 0.2844047500000005"/>
      <geometry>
        <sphere radius="0.061628755000000014"/>
      </geometry>
    </collision>
  </link>
  <joint name="idx63_arm_r_joint3" type="revolute">
    <origin rpy="-1.5707963267948966 0 0" xyz="0 0 0"/>
    <parent link="arm_r_link2"/>
    <child link="arm_r_link3"/>
    <axis xyz="0 0 1"/>
    <limit effort="66" lower="-3.1067" upper="3.1067" velocity="3.1416"/>
  </joint>
  <link name="arm_r_link4">
    <inertial>
      <origin rpy="0 0 0" xyz="-0.0086935 0.045984 0.011135"/>
      <mass value="1.5332"/>
      <inertia ixx="0.00527549" ixy="-0.00061752" ixz="0.00012895" iyy="0.00208586" iyz="-6.871E-04" izz="0.00489695"/>
    </inertial>
    <visual name="default_visual">
      <geometry>
        <mesh filename="package://genie_robot_description/meshes/arm/Link4_P6.STL"/>
      </geometry>
      <origin rpy="0 0 0" xyz="0 0 0"/>
      <material name="default"/>
    </visual>
    <collision name="arm_r_link4_coarse_0">
      <origin rpy="-0.0 0.0 -0.0" xyz="-0.003173828099999999 0.004589356499999994 -0.011833649999999894"/>
      <geometry>
        <sphere radius="0.06991342"/>
      </geometry>
    </collision>
    <collision name="arm_r_link4_coarse_1">
      <origin rpy="-0.0 0.0 -0.0" xyz="-0.004821777299999992 0.004589356499999994 0.011815094000000035"/>
      <geometry>
        <sphere radius="0.069075850000000004"/>
      </geometry>
    </collision>
    <collision name="arm_r_link4_coarse_2">
      <origin rpy="-0.0 0.0 -0.0" xyz="-0.012329101999999996 0.09249994000000004 0.003940582300000001"/>
      <geometry>
        <sphere radius="0.05453134999999996"/>
      </geometry>
    </collision>
  </link>
  <joint name="idx64_arm_r_joint4" type="revolute">
    <origin rpy="1.5707963267948966 0 0" xyz="0.018 0 0.287"/>
    <parent link="arm_r_link3"/>
    <child link="arm_r_link4"/>
    <axis xyz="0 0 1"/>
    <limit effort="66" lower="-2.5307" upper="1.0472" velocity="3.1416"/>
  </joint>
  <link name="arm_r_link5">
    <inertial>
      <origin rpy="0 0 0" xyz=" 0.00036663 -0.00041429 0.19889130 "/>
      <mass value="1.9854"/>
      <inertia ixx="0.00567529" ixy="-0.00003473" ixz="0.00004594" iyy="0.00526345" iyz="-0.00002975" izz="0.00209504"/>
    </inertial>
    <visual name="default_visual">
      <geometry>
        <mesh filename="package://genie_robot_description/meshes/arm/Link5_P6.STL"/>
      </geometry>
      <origin rpy="0 0 0" xyz="0 0 0"/>
      <material name="default"/>
    </visual>
    <collision name="arm_r_link5_coarse_0">
      <origin rpy="-0.0 0.0 -0.0" xyz="0.001464843800000002 0.02441250000000014 0.217128723000000035"/>
      <geometry>
        <sphere radius="0.0521019999999999"/>
      </geometry>
    </collision>
    <collision name="arm_r_link5_coarse_1">
      <origin rpy="-0.0 0.0 -0.0" xyz="-0.0015869140999999996 -0.02448128500000002 0.21791775999999984"/>
      <geometry>
        <sphere radius="0.05214000000001"/>
      </geometry>
    </collision>
    <collision name="arm_r_link5_coarse_2">
      <origin rpy="-0.0 0.0 -0.0" xyz="0.001464843800000002 0.02841250000000014 0.287128723000000035"/>
      <geometry>
        <sphere radius="0.0521019999999999"/>
      </geometry>
    </collision>
    <collision name="arm_r_link5_coarse_3">
      <origin rpy="-0.0 0.0 -0.0" xyz="-0.0015869140999999996 -0.02848128500000002 0.2891775999999984"/>
      <geometry>
        <sphere radius="0.05214000000001"/>
      </geometry>
    </collision>
    <collision name="arm_r_link5_coarse_4">
      <origin rpy="-0.0 0.0 -0.0" xyz="-0.0009765625000000072 0.0031794570000000027 0.1568145800000001"/>
      <geometry>
        <sphere radius="0.05447049"/>
      </geometry>
    </collision>
  </link>
  <joint name="idx65_arm_r_joint5" type="revolute">
    <origin rpy="-1.5707963267948966 0 0" xyz="-0.018 0 0"/>
    <parent link="arm_r_link4"/>
    <child link="arm_r_link5"/>
    <axis xyz="0 0 1"/>
    <limit effort="18" lower="-3.1067" upper="3.1067" velocity="3.1416"/>
  </joint>
  <link name="arm_r_link6">
    <inertial>
      <origin rpy="0 0 0" xyz=" -0.00458177 -0.00027029 0.00009098"/>
      <mass value=" 0.64594816"/>
      <inertia ixx="0.00047709" ixy="0.00000139" ixz="-0.00000196" iyy="0.00039190" iyz="0.00000071" izz="0.00036115"/>
    </inertial>
    <visual name="default_visual">
      <geometry>
        <mesh filename="package://genie_robot_description/meshes/arm/Link6_P6.STL"/>
      </geometry>
      <origin rpy="0 0 0" xyz="0 0 0"/>
      <material name="default"/>
    </visual>
    <collision name="arm_r_link6_coarse_0">
      <origin rpy="-0.0 0.0 -0.0" xyz="1.4374967121801579e-18 -1.7293193529986862e-19 5.755390971698752e-19"/>
      <geometry>
        <sphere radius="0.052349735"/>
      </geometry>
    </collision>
  </link>
  <joint name="idx66_arm_r_joint6" type="revolute">
    <origin rpy="1.5707963267948966 0 0" xyz="0 0 0.314"/>
    <parent link="arm_r_link5"/>
    <child link="arm_r_link6"/>
    <axis xyz="0 0 1"/>
    <limit effort="18" lower="-1.0472" upper="1.0472" velocity="3.1416"/>
  </joint>
  <link name="arm_r_link7">
    <inertial>
      <origin rpy="0 0 0" xyz=" 0.04513370 0.00004672 0.00607482"/>
      <mass value="0.31658"/>
      <inertia ixx="0.00037121" ixy="4.6E-07" ixz="-8.646E-05" iyy="0.00067341" iyz="-5.1E-07" izz="0.00053248"/>
    </inertial>
    <visual name="default_visual">
      <geometry>
        <mesh filename="package://genie_robot_description/meshes/arm/Link7_P6.STL"/>
      </geometry>
      <origin rpy="0 0 0" xyz="0 0 0"/>
      <material name="default"/>
    </visual>
    <collision name="arm_r_link7_coarse_0">
      <origin rpy="-0.0 0.0 -0.0" xyz="0.05914825400000002 0.0 0.0"/>
      <geometry>
        <sphere radius="0.04457995700000001"/>
      </geometry>
    </collision>
    <collision name="arm_r_link7_coarse_1">
      <origin rpy="-0.0 0.0 -0.0" xyz="0.0 0.0 0.02"/>
      <geometry>
        <sphere radius="0.04457995700000001"/>
      </geometry>
    </collision>
    <collision name="arm_r_link7_coarse_2">
      <origin rpy="-0.0 0.0 -0.0" xyz="0.0 0.0 -0.02"/>
      <geometry>
        <sphere radius="0.04457995700000001"/>
      </geometry>
    </collision>
  </link>
  <link name="arm_r_end_link"/>
  <joint name="idx67_arm_r_joint7" type="revolute">
    <origin rpy="1.5707963267948966 0 1.5707963267948966" xyz="0 0 0"/>
    <parent link="arm_r_link6"/>
    <child link="arm_r_link7"/>
    <axis xyz="0 0 1"/>
    <limit effort="18" lower="-1.5708" upper="1.5708" velocity="3.1416"/>
  </joint>
  <joint name="arm_r_end_joint" type="fixed">
    <origin rpy="3.141592653589793 -1.5707963267948966 0" xyz="0.088 0.0 0.0"/>
    <parent link="arm_r_link7"/>
    <child link="arm_r_end_link"/>
  </joint>
  <!-- Eastern Eggs -->
  <!-- All Together -->
</robot>
