<?xml version="1.0"?>
<robot xmlns:xacro="http://www.ros.org/wiki/xacro">

  <!-- main xacro -->
  <xacro:macro name="arm_l"
    params="parent_link xyz_offset rpy_offset end_link collision_type mesh_dir app">
    <!-- properties -->

    <!-- Arm -->
    <link name="arm_l_link1">
      <inertial>
        <origin xyz="1.875e-05 0.006003 0.1438" rpy="0 0 0" />
        <mass value="2.0926" />
        <inertia ixx="0.0052452089" iyy="0.0045556503" izz="0.0023798641" ixy="0" ixz="0" iyz="0" />
      </inertial>
      <visual name="default_visual">
        <geometry>
          <mesh filename="${mesh_dir}/arm/crs/arm_link1.dae" />
        </geometry>
        <origin xyz="0 0 0" rpy="0 0 0" />
      </visual>
      <xacro:if value="${collision_type == 'visual'}">
        <collision name="arm_l_link1_visual_0">
          <origin
            xyz="0 0 0"
            rpy="0 0 0" />
          <geometry>
            <mesh filename="${mesh_dir}/arm/crs/arm_link1.STL" />
          </geometry>
        </collision>
      </xacro:if>
      <xacro:if value="${collision_type == 'fine'}">
        <collision name="arm_l_link1_convex_0">
          <geometry>
            <mesh filename="${mesh_dir}/arm/crs/convex/arm_l_link1_fine_0.STL" />
          </geometry>
        </collision>
        <collision_checking>
          <convex name="arm_l_link1_convex_0" />
        </collision_checking>
      </xacro:if>
      <xacro:if value="${collision_type == 'coarse'}">
        <collision name="arm_l_link1_coarse_0">
          <origin rpy="-0.0 0.0 -0.0"
            xyz="-0.0004959106400000004 -1.945484272123522e-19 0.17853164999999982" />
          <geometry>
            <sphere radius="0.06300305" />
          </geometry>
        </collision>
        <collision name="arm_l_link1_coarse_1">
          <origin rpy="-0.0 0.0 -0.0" xyz="-0.009067535000000005 -0.004526614999999998 0.12142944" />
          <geometry>
            <sphere radius="0.06310095999999998" />
          </geometry>
        </collision>
      </xacro:if>
    </link>
    <joint name="idx21_arm_l_joint1" type="revolute">
      <origin
        xyz="${xyz_offset}"
        rpy="${rpy_offset}" />
      <parent link="${parent_link}" />
      <child link="arm_l_link1" />
      <axis
        xyz="0 0 1" />
      <limit
        lower="-3.0718"
        upper="3.0718"
        effort="108"
        velocity="3.9" />
      <dynamics friction="1.0" />
      <drive stiffness="40000" damping="600" />
    </joint>
    <link name="arm_l_link2">
      <inertial>
        <origin xyz="-7.03e-06 0.05542 0.010995" rpy="0 0 0" />
        <mass value="1.9432" />
        <inertia ixx="0.007789243" iyy="0.0042862232" izz="0.0095856918" ixy="0" ixz="0" iyz="0" />
      </inertial>
      <visual name="default_visual">
        <geometry>
          <mesh filename="${mesh_dir}/arm/crs/arm_link2.dae" />
        </geometry>
        <origin xyz="0 0 0" rpy="0 0 0" />
      </visual>
      <xacro:if value="${collision_type == 'visual'}">
        <collision name="arm_l_link2_visual_0">
          <origin
            xyz="0 0 0"
            rpy="0 0 0" />
          <geometry>
            <mesh filename="${mesh_dir}/arm/crs/arm_link2.STL" />
          </geometry>
        </collision>
      </xacro:if>
      <xacro:if value="${collision_type == 'coarse'}">
        <collision name="arm_l_link2_coarse_0">
          <origin rpy="-0.0 0.0 -0.0"
            xyz="-0.004974365200000007 0.006954193000000001 -0.01338499999999954" />
          <geometry>
            <sphere radius="0.07498259999999999" />
          </geometry>
        </collision>
        <collision name="arm_l_link2_coarse_1">
          <origin rpy="-0.0 0.0 -0.0"
            xyz="-0.004501343000000002 0.0072174069999999925 0.01335839199999999" />
          <geometry>
            <sphere radius="0.074983405" />
          </geometry>
        </collision>
        <collision name="arm_l_link2_coarse_2">
          <origin rpy="-0.0 0.0 -0.0"
            xyz="0.0010223389000000094 0.1094703699999999 0.0012550354000000002" />
          <geometry>
            <sphere radius="0.06165532800000009" />
          </geometry>
        </collision>
      </xacro:if>
      <xacro:if value="${collision_type == 'fine'}">
        <collision name="arm_l_link2_convex_0">
          <geometry>
            <mesh filename="${mesh_dir}/arm/crs/convex/arm_l_link2_fine_0.STL" />
          </geometry>
        </collision>
        <collision_checking>
          <convex name="arm_l_link2_convex_0" />
        </collision_checking>
      </xacro:if>
    </link>
    <joint name="idx22_arm_l_joint2" type="revolute">
      <origin
        xyz="0 0 0.1745"
        rpy="1.5708 0 0" />
      <parent link="arm_l_link1" />
      <child link="arm_l_link2" />
      <axis
        xyz="0 0 1" />
      <limit
        lower="-2.0595"
        upper="2.0595"
        effort="108"
        velocity="3.9" />
      <dynamics friction="1.0" />
      <drive stiffness="40000" damping="600" />
    </joint>
    <link name="arm_l_link3">
      <inertial>
        <origin xyz="0.0087411 0.0019043 0.23487" rpy="-0.018380291 0.1667572 0.020828085" />
        <mass value="1.6913" />
        <inertia ixx="0.0061092806" iyy="0.0057534002" izz="0.0016597756" ixy="0" ixz="0" iyz="0" />
      </inertial>
      <visual name="default_visual">
        <geometry>
          <mesh filename="${mesh_dir}/arm/crs/arm_link3.dae" />
        </geometry>
        <origin xyz="0 0 0" rpy="0 0 0" />
      </visual>
      <xacro:if value="${collision_type == 'visual'}">
        <collision name="arm_l_link3_visual_0">
          <origin
            xyz="0 0 0"
            rpy="0 0 0" />
          <geometry>
            <mesh filename="${mesh_dir}/arm/crs/arm_link3.STL" />
          </geometry>
        </collision>
      </xacro:if>
      <xacro:if value="${collision_type == 'coarse'}">
        <!-- <collision name="arm_l_link3_coarse_0">
          <geometry>
            <sphere radius="0.073823" />
          </geometry>
          <origin xyz="-0.002493036787214638 -0.0 0.19334736154660487"
            rpy="0.0 -0.0 0.0" />
        </collision>
        <collision name="arm_l_link3_coarse_1">
          <geometry>
            <sphere radius="0.070649" />
          </geometry>
          <origin xyz="0.015268963212785362 0.0 0.26469536154660483"
            rpy="0.0 -0.0 0.0" />
        </collision> -->
        <collision name="arm_l_link3_coarse_0">
          <origin rpy="-0.0 0.0 -0.0"
            xyz="0.0007324219000000129 -0.00011956971000000159 0.19502639999999993" />
          <geometry>
            <sphere radius="0.06603523000000001" />
          </geometry>
        </collision>
        <collision name="arm_l_link3_coarse_1">
          <origin rpy="-0.0 0.0 -0.0"
            xyz="0.01489257800000002 -0.001605738900000001 0.2844047500000005" />
          <geometry>
            <sphere radius="0.061628755000000014" />
          </geometry>
        </collision>
      </xacro:if>
      <xacro:if value="${collision_type == 'fine'}">
        <collision name="arm_l_link3_convex_0">
          <geometry>
            <mesh filename="${mesh_dir}/arm/crs/convex/arm_l_link3_fine_0.STL" />
          </geometry>
        </collision>
        <collision_checking>
          <convex name="arm_l_link3_convex_0" />
        </collision_checking>
      </xacro:if>
    </link>
    <joint name="idx23_arm_l_joint3" type="revolute">
      <origin
        xyz="0 0 0"
        rpy="-1.5708 0 0" />
      <parent link="arm_l_link2" />
      <child link="arm_l_link3" />
      <axis
        xyz="0 0 1" />
      <limit
        lower="-3.0718"
        upper="3.0718"
        effort="35"
        velocity="3.6" />
      <dynamics friction="0.5" />
      <drive stiffness="15000" damping="220" />
    </joint>
    <link name="arm_l_link4">
      <inertial>
        <origin xyz="-0.0086935 0.045984 0.011135" rpy="0.043831293 0.019779245 0.21300632" />
        <mass value="1.5332" />
        <inertia ixx="0.0042228843" iyy="0.0027991604" izz="0.0054013017" ixy="0" ixz="0" iyz="0" />
      </inertial>
      <visual name="default_visual">
        <geometry>
          <mesh filename="${mesh_dir}/arm/crs/arm_link4.dae" />
        </geometry>
        <origin xyz="0 0 0" rpy="0 0 0" />
      </visual>
      <xacro:if value="${collision_type == 'visual'}">
        <collision name="arm_l_link4_visual_0">
          <origin
            xyz="0 0 0"
            rpy="0 0 0" />
          <geometry>
            <mesh filename="${mesh_dir}/arm/crs/arm_link4.STL" />
          </geometry>
        </collision>
      </xacro:if>
      <xacro:if value="${collision_type == 'coarse'}">
        <collision name="arm_l_link4_coarse_0">
          <origin rpy="-0.0 0.0 -0.0"
            xyz="-0.003173828099999999 0.004589356499999994 -0.011833649999999894" />
          <geometry>
            <sphere radius="0.06991342" />
          </geometry>
        </collision>
        <collision name="arm_l_link4_coarse_1">
          <origin rpy="-0.0 0.0 -0.0"
            xyz="-0.004821777299999992 0.004589356499999994 0.011815094000000035" />
          <geometry>
            <sphere radius="0.069075850000000004" />
          </geometry>
        </collision>
        <collision name="arm_l_link4_coarse_2">
          <origin rpy="-0.0 0.0 -0.0"
            xyz="-0.012329101999999996 0.09249994000000004 0.003940582300000001" />
          <geometry>
            <sphere radius="0.05453134999999996" />
          </geometry>
        </collision>
      </xacro:if>
      <xacro:if value="${collision_type == 'fine'}">
        <collision name="arm_l_link4_convex_0">
          <geometry>
            <mesh filename="${mesh_dir}/arm/crs/convex/arm_l_link4_fine_0.STL" />
          </geometry>
        </collision>
        <collision_checking>
          <convex name="arm_l_link4_convex_0" />
        </collision_checking>
      </xacro:if>
    </link>
    <joint name="idx24_arm_l_joint4" type="revolute">
      <origin
        xyz="0.018 0 0.287"
        rpy="1.5708 0 0" />
      <parent link="arm_l_link3" />
      <child link="arm_l_link4" />
      <axis
        xyz="0 0 1" />
      <limit
        lower="-2.4959"
        upper="1.0123"
        effort="35"
        velocity="3.6" />
      <dynamics friction="0.5" />
      <drive stiffness="15000" damping="220" />
    </joint>
    <link name="arm_l_link5">
      <inertial>
        <origin xyz="-0.00036467 0.0001479 0.19902" rpy="0 0 0" />
        <mass value="2.0095" />
        <inertia ixx="0.0060028039" iyy="0.0053007461" izz="0.0025501492" ixy="0" ixz="0" iyz="0" />
      </inertial>
      <visual name="default_visual">
        <geometry>
          <mesh filename="${mesh_dir}/arm/crs/arm_link5.dae" />
        </geometry>
        <origin xyz="0 0 0" rpy="0 0 0" />
      </visual>
      <xacro:if value="${collision_type == 'visual'}">
        <collision name="arm_l_link5_visual_0">
          <origin
            xyz="0 0 0"
            rpy="0 0 0" />
          <geometry>
            <mesh filename="${mesh_dir}/arm/crs/arm_link5.STL" />
          </geometry>
        </collision>
      </xacro:if>
      <xacro:if value="${collision_type == 'coarse'}">
        <collision name="arm_l_link5_coarse_0">
          <origin rpy="-0.0 0.0 -0.0"
            xyz="0.001464843800000002 0.02441250000000014 0.217128723000000035" />
          <geometry>
            <sphere radius="0.0521019999999999" />
          </geometry>
        </collision>
        <collision name="arm_l_link5_coarse_1">
          <origin rpy="-0.0 0.0 -0.0"
            xyz="-0.0015869140999999996 -0.02448128500000002 0.21791775999999984" />
          <geometry>
            <sphere radius="0.05214000000001" />
          </geometry>
        </collision>
        <collision name="arm_l_link5_coarse_2">
          <origin rpy="-0.0 0.0 -0.0"
            xyz="0.001464843800000002 0.02841250000000014 0.287128723000000035" />
          <geometry>
            <sphere radius="0.0521019999999999" />
          </geometry>
        </collision>
        <collision name="arm_l_link5_coarse_3">
          <origin rpy="-0.0 0.0 -0.0"
            xyz="-0.0015869140999999996 -0.02848128500000002 0.2891775999999984" />
          <geometry>
            <sphere radius="0.05214000000001" />
          </geometry>
        </collision>
        <collision name="arm_l_link5_coarse_4">
          <origin rpy="-0.0 0.0 -0.0"
            xyz="-0.0009765625000000072 0.0031794570000000027 0.1568145800000001" />
          <geometry>
            <sphere radius="0.05447049" />
          </geometry>
        </collision>
      </xacro:if>
      <xacro:if value="${collision_type == 'fine'}">
        <collision name="arm_l_link5_convex_0">
          <geometry>
            <mesh filename="${mesh_dir}/arm/crs/convex/arm_l_link5_fine_0.STL" />
          </geometry>
        </collision>
        <collision_checking>
          <convex name="arm_l_link5_convex_0" />
        </collision_checking>
      </xacro:if>
    </link>
    <joint name="idx25_arm_l_joint5" type="revolute">
      <origin
        xyz="-0.018 0 0"
        rpy="-1.5708 0 0" />
      <parent link="arm_l_link4" />
      <child link="arm_l_link5" />
      <axis
        xyz="0 0 1" />
      <limit
        lower="-3.0718"
        upper="3.0718"
        effort="35"
        velocity="4.7" />
      <dynamics friction="0.5" />
      <drive stiffness="15000" damping="220" />
    </joint>
    <link name="arm_l_link6">
      <inertial>
        <origin xyz="-0.004911 0.00027206 -8.14e-05" rpy="0 0 0" />
        <mass value="0.67002" />
        <inertia ixx="0.00050262523" iyy="0.00045220222" izz="0.00042586034" ixy="0" ixz="0" iyz="0" />
      </inertial>
      <visual name="default_visual">
        <geometry>
          <mesh filename="${mesh_dir}/arm/crs/arm_link6.dae" />
        </geometry>
        <origin xyz="0 0 0" rpy="0 0 0" />
      </visual>
      <xacro:if value="${collision_type == 'visual'}">
        <collision name="arm_l_link6_visual_0">
          <origin
            xyz="0 0 0"
            rpy="0 0 0" />
          <geometry>
            <mesh filename="${mesh_dir}/arm/crs/arm_link6.STL" />
          </geometry>
        </collision>
      </xacro:if>
      <xacro:if value="${collision_type == 'coarse'}">
        <collision name="arm_l_link6_coarse_0">
          <origin rpy="-0.0 0.0 -0.0"
            xyz="1.4374967121801579e-18 -1.7293193529986862e-19 5.755390971698752e-19" />
          <geometry>
            <sphere radius="0.052349735" />
          </geometry>
        </collision>
      </xacro:if>
      <xacro:if value="${collision_type == 'fine'}">
        <collision name="arm_l_link6_convex_0">
          <geometry>
            <mesh filename="${mesh_dir}/arm/crs/convex/arm_l_link6_fine_0.STL" />
          </geometry>
        </collision>
        <collision_checking>
          <convex name="arm_l_link6_convex_0" />
        </collision_checking>
      </xacro:if>
    </link>
    <joint name="idx26_arm_l_joint6" type="revolute">
      <origin
        xyz="0 0 0.314"
        rpy="1.5708 0 0" />
      <parent link="arm_l_link5" />
      <child link="arm_l_link6" />
      <axis
        xyz="0 0 1" />
      <limit
        lower="-1.0123"
        upper="1.0123"
        effort="18"
        velocity="4.7" />
      <dynamics friction="0.2" />
      <drive stiffness="8000" damping="100" />
    </joint>
    <link name="arm_l_link7">
      <inertial>
        <origin xyz="0.0451337 4.672e-05 0.00607482" rpy="-0.00014482803 0.26364697 0.00078168277" />
        <mass value="0.31657" />
        <inertia ixx="0.0004220241" iyy="0.00084798611" izz="0.00064047202" ixy="0" ixz="0" iyz="0" />
      </inertial>
      <visual name="default_visual">
        <geometry>
          <mesh filename="${mesh_dir}/arm/crs/arm_link7.dae" />
        </geometry>
        <origin xyz="0 0 0" rpy="0 0 0" />
      </visual>
      <xacro:if value="${collision_type == 'visual'}">
        <collision name="arm_l_link7_visual_0">
          <origin
            xyz="0 0 0"
            rpy="0 0 0" />
          <geometry>
            <mesh filename="${mesh_dir}/arm/crs/arm_link7.STL" />
          </geometry>
        </collision>
      </xacro:if>
      <xacro:if value="${collision_type == 'coarse'}">
        <collision name="arm_l_link7_coarse_0">
          <origin rpy="-0.0 0.0 -0.0" xyz="0.05914825400000002 0.0 0.0" />
          <geometry>
            <sphere radius="0.04457995700000001" />
          </geometry>
        </collision>
        <collision name="arm_l_link7_coarse_1">
          <origin rpy="-0.0 0.0 -0.0" xyz="0.0 0.0 0.02" />
          <geometry>
            <sphere radius="0.04457995700000001" />
          </geometry>
        </collision>
        <collision name="arm_l_link7_coarse_2">
          <origin rpy="-0.0 0.0 -0.0" xyz="0.0 0.0 -0.02" />
          <geometry>
            <sphere radius="0.04457995700000001" />
          </geometry>
        </collision>
      </xacro:if>
      <xacro:if value="${collision_type == 'fine'}">
        <collision name="arm_l_link7_convex_0">
          <geometry>
            <mesh filename="${mesh_dir}/arm/crs/convex/arm_l_link7_fine_0.STL" />
          </geometry>
        </collision>
        <collision_checking>
          <convex name="arm_l_link7_convex_0" />
        </collision_checking>
      </xacro:if>
    </link>
    <joint name="idx27_arm_l_joint7" type="revolute">
      <origin
        xyz="0 0 0"
        rpy="1.5708 0 1.5708" />
      <parent link="arm_l_link6" />
      <child link="arm_l_link7" />
      <axis
        xyz="0 0 1" />
      <limit
        lower="-1.5359"
        upper="1.5359"
        effort="18"
        velocity="4.7" />
      <dynamics friction="0.2" />
      <drive stiffness="8000" damping="100" />
    </joint>
    <link name="${end_link}">
      <inertial>
        <origin xyz="0 0 0" rpy="0 0 0" />
        <mass value="0.001" />
        <inertia ixx="1e-6" iyy="1e-6" izz="1e-6" ixy="0" ixz="0" iyz="0" />
      </inertial>
    </link>
    <joint name='arm_l_end_joint' type='fixed'>
      <origin xyz="0.095 0.0 0.0" rpy="3.1416 -1.5708 0" />
      <parent link="arm_l_link7" />
      <child link="${end_link}" />
    </joint>

  </xacro:macro>

  <!-- main xacro -->
  <xacro:macro name="arm_r"
    params="parent_link xyz_offset rpy_offset end_link collision_type mesh_dir app">
    <!-- properties -->

    <!-- Arm -->
    <link name="arm_r_link1">
      <inertial>
        <origin xyz="1.875e-05 0.006003 0.1438" rpy="0 0 0" />
        <mass value="2.0926" />
        <inertia ixx="0.0052452089" iyy="0.0045556503" izz="0.0023798641" ixy="0" ixz="0" iyz="0" />
      </inertial>
      <visual name="default_visual">
        <geometry>
          <mesh filename="${mesh_dir}/arm/crs/arm_link1.dae" />
        </geometry>
        <origin xyz="0 0 0" rpy="0 0 0" />
      </visual>
      <xacro:if value="${collision_type == 'visual'}">
        <collision name="arm_r_link1_visual_0">
          <origin
            xyz="0 0 0"
            rpy="0 0 0" />
          <geometry>
            <mesh filename="${mesh_dir}/arm/crs/arm_link1.STL" />
          </geometry>
        </collision>
      </xacro:if>
      <xacro:if value="${collision_type == 'coarse'}">
        <collision name="arm_r_link1_coarse_0">
          <origin rpy="-0.0 0.0 -0.0"
            xyz="-0.0004959106400000004 -1.945484272123522e-19 0.17853164999999982" />
          <geometry>
            <sphere radius="0.06300305" />
          </geometry>
        </collision>
        <collision name="arm_r_link1_coarse_1">
          <origin rpy="-0.0 0.0 -0.0" xyz="-0.009067535000000005 -0.004526614999999998 0.12142944" />
          <geometry>
            <sphere radius="0.06310095999999998" />
          </geometry>
        </collision>
      </xacro:if>
      <xacro:if value="${collision_type == 'fine'}">
        <collision name="arm_r_link1_convex_0">
          <geometry>
            <mesh filename="${mesh_dir}/arm/crs/convex/arm_r_link1_fine_0.STL" />
          </geometry>
        </collision>
        <collision_checking>
          <convex name="arm_r_link1_convex_0" />
        </collision_checking>
      </xacro:if>
    </link>
    <joint name="idx61_arm_r_joint1" type="revolute">
      <origin
        xyz="${xyz_offset}"
        rpy="${rpy_offset}" />
      <parent link="${parent_link}" />
      <child link="arm_r_link1" />
      <axis xyz="0 0 1" />
      <limit
        lower="-3.0718"
        upper="3.0718"
        effort="108"
        velocity="3.9" />
      <dynamics friction="1.0" />
      <drive stiffness="40000" damping="600" />
    </joint>
    <link name="arm_r_link2">
      <inertial>
        <origin xyz="-7.03e-06 0.05542 0.010995" rpy="0 0 0" />
        <mass value="1.9432" />
        <inertia ixx="0.007789243" iyy="0.0042862232" izz="0.0095856918" ixy="0" ixz="0" iyz="0" />
      </inertial>
      <visual name="default_visual">
        <geometry>
          <mesh filename="${mesh_dir}/arm/crs/arm_link2.dae" />
        </geometry>
        <origin xyz="0 0 0" rpy="0 0 0" />
      </visual>
      <xacro:if value="${collision_type == 'visual'}">
        <collision name="arm_r_link2_visual_0">
          <origin
            xyz="0 0 0"
            rpy="0 0 0" />
          <geometry>
            <mesh filename="${mesh_dir}/arm/crs/arm_link2.STL" />
          </geometry>
        </collision>
      </xacro:if>
      <xacro:if value="${collision_type == 'coarse'}">
        <collision name="arm_r_link2_coarse_0">
          <origin rpy="-0.0 0.0 -0.0"
            xyz="-0.004974365200000007 0.006954193000000001 -0.01338499999999954" />
          <geometry>
            <sphere radius="0.07498259999999999" />
          </geometry>
        </collision>
        <collision name="arm_r_link2_coarse_1">
          <origin rpy="-0.0 0.0 -0.0"
            xyz="-0.004501343000000002 0.0072174069999999925 0.01335839199999999" />
          <geometry>
            <sphere radius="0.074983405" />
          </geometry>
        </collision>
        <collision name="arm_r_link2_coarse_2">
          <origin rpy="-0.0 0.0 -0.0"
            xyz="0.0010223389000000094 0.1094703699999999 0.0012550354000000002" />
          <geometry>
            <sphere radius="0.06165532800000009" />
          </geometry>
        </collision>
      </xacro:if>
      <xacro:if value="${collision_type == 'fine'}">
        <collision name="arm_r_link2_convex_0">
          <geometry>
            <mesh filename="${mesh_dir}/arm/crs/convex/arm_r_link2_fine_0.STL" />
          </geometry>
        </collision>
        <collision_checking>
          <convex name="arm_r_link2_convex_0" />
        </collision_checking>
      </xacro:if>
    </link>
    <joint name="idx62_arm_r_joint2" type="revolute">
      <origin
        xyz="0 0 0.1745"
        rpy="${PI_2} 0 0" />
      <parent link="arm_r_link1" />
      <child link="arm_r_link2" />
      <axis
        xyz="0 0 1" />
      <limit
        lower="-2.0595"
        upper="2.0595"
        effort="108"
        velocity="3.9" />
      <dynamics friction="1.0" />
      <drive stiffness="40000" damping="600" />
    </joint>
    <link name="arm_r_link3">
      <inertial>
        <origin xyz="0.0087411 0.0019043 0.23487" rpy="-0.018380291 0.1667572 0.020828085" />
        <mass value="1.6913" />
        <inertia ixx="0.0061092806" iyy="0.0057534002" izz="0.0016597756" ixy="0" ixz="0" iyz="0" />
      </inertial>
      <visual name="default_visual">
        <geometry>
          <mesh filename="${mesh_dir}/arm/crs/arm_link3.dae" />
        </geometry>
        <origin xyz="0 0 0" rpy="0 0 0" />
      </visual>
      <xacro:if value="${collision_type == 'visual'}">
        <collision name="arm_r_link3_visual_0">
          <origin
            xyz="0 0 0"
            rpy="0 0 0" />
          <geometry>
            <mesh filename="${mesh_dir}/arm/crs/arm_link3.STL" />
          </geometry>
        </collision>
      </xacro:if>
      <xacro:if value="${collision_type == 'coarse'}">
        <collision name="arm_r_link3_coarse_0">
          <origin rpy="-0.0 0.0 -0.0"
            xyz="0.0007324219000000129 -0.00011956971000000159 0.19502639999999993" />
          <geometry>
            <sphere radius="0.06603523000000001" />
          </geometry>
        </collision>
        <collision name="arm_r_link3_coarse_1">
          <origin rpy="-0.0 0.0 -0.0"
            xyz="0.01489257800000002 -0.001605738900000001 0.2844047500000005" />
          <geometry>
            <sphere radius="0.061628755000000014" />
          </geometry>
        </collision>
      </xacro:if>
      <xacro:if value="${collision_type == 'fine'}">
        <collision name="arm_r_link3_convex_0">
          <geometry>
            <mesh filename="${mesh_dir}/arm/crs/convex/arm_r_link3_fine_0.STL" />
          </geometry>
        </collision>
        <collision_checking>
          <convex name="arm_r_link3_convex_0" />
        </collision_checking>
      </xacro:if>
    </link>
    <joint name="idx63_arm_r_joint3" type="revolute">
      <origin
        xyz="0 0 0"
        rpy="-${PI_2} 0 0" />
      <parent link="arm_r_link2" />
      <child link="arm_r_link3" />
      <axis
        xyz="0 0 1" />
      <limit
        lower="-3.0718"
        upper="3.0718"
        effort="35"
        velocity="3.6" />
      <dynamics friction="0.5" />
      <drive stiffness="15000" damping="220" />
    </joint>
    <link name="arm_r_link4">
      <inertial>
        <origin xyz="-0.0086935 0.045984 0.011135" rpy="0.043831293 0.019779245 0.21300632" />
        <mass value="1.5332" />
        <inertia ixx="0.0042228843" iyy="0.0027991604" izz="0.0054013017" ixy="0" ixz="0" iyz="0" />
      </inertial>
      <visual name="default_visual">
        <geometry>
          <mesh filename="${mesh_dir}/arm/crs/arm_link4.dae" />
        </geometry>
        <origin xyz="0 0 0" rpy="0 0 0" />
      </visual>
      <xacro:if value="${collision_type == 'visual'}">
        <collision name="arm_r_link4_visual_0">
          <origin
            xyz="0 0 0"
            rpy="0 0 0" />
          <geometry>
            <mesh filename="${mesh_dir}/arm/crs/arm_link4.STL" />
          </geometry>
        </collision>
      </xacro:if>
      <xacro:if value="${collision_type == 'coarse'}">
        <collision name="arm_r_link4_coarse_0">
          <origin rpy="-0.0 0.0 -0.0"
            xyz="-0.003173828099999999 0.004589356499999994 -0.011833649999999894" />
          <geometry>
            <sphere radius="0.06991342" />
          </geometry>
        </collision>
        <collision name="arm_r_link4_coarse_1">
          <origin rpy="-0.0 0.0 -0.0"
            xyz="-0.004821777299999992 0.004589356499999994 0.011815094000000035" />
          <geometry>
            <sphere radius="0.069075850000000004" />
          </geometry>
        </collision>
        <collision name="arm_r_link4_coarse_2">
          <origin rpy="-0.0 0.0 -0.0"
            xyz="-0.012329101999999996 0.09249994000000004 0.003940582300000001" />
          <geometry>
            <sphere radius="0.05453134999999996" />
          </geometry>
        </collision>
      </xacro:if>
      <xacro:if value="${collision_type == 'fine'}">
        <collision name="arm_r_link4_convex_0">
          <geometry>
            <mesh filename="${mesh_dir}/arm/crs/convex/arm_r_link4_fine_0.STL" />
          </geometry>
        </collision>
        <collision_checking>
          <convex name="arm_r_link4_convex_0" />
        </collision_checking>
      </xacro:if>
    </link>
    <joint name="idx64_arm_r_joint4" type="revolute">
      <origin
        xyz="0.018 0 0.287"
        rpy="${PI_2} 0 0" />
      <parent link="arm_r_link3" />
      <child link="arm_r_link4" />
      <axis
        xyz="0 0 1" />
      <limit
        lower="-2.4959"
        upper="1.0123"
        effort="35"
        velocity="3.6" />
      <dynamics friction="0.5" />
      <drive stiffness="15000" damping="220" />
    </joint>
    <link name="arm_r_link5">
      <inertial>
        <origin xyz="0.00036663 -0.00041429 0.1988913" rpy="0 0 0" />
        <mass value="1.9854" />
        <inertia ixx="0.0059280599" iyy="0.0052364793" izz="0.002517512" ixy="0" ixz="0" iyz="0" />
      </inertial>
      <visual name="default_visual">
        <geometry>
          <mesh filename="${mesh_dir}/arm/crs/arm_link5.dae" />
        </geometry>
        <origin xyz="0 0 0" rpy="0 0 0" />
      </visual>
      <xacro:if value="${collision_type == 'visual'}">
        <collision name="arm_r_link5_visual_0">
          <origin
            xyz="0 0 0"
            rpy="0 0 0" />
          <geometry>
            <mesh filename="${mesh_dir}/arm/crs/arm_link5.STL" />
          </geometry>
        </collision>
      </xacro:if>
      <xacro:if value="${collision_type == 'coarse'}">
        <collision name="arm_r_link5_coarse_0">
          <origin rpy="-0.0 0.0 -0.0"
            xyz="0.001464843800000002 0.02441250000000014 0.217128723000000035" />
          <geometry>
            <sphere radius="0.0521019999999999" />
          </geometry>
        </collision>
        <collision name="arm_r_link5_coarse_1">
          <origin rpy="-0.0 0.0 -0.0"
            xyz="-0.0015869140999999996 -0.02448128500000002 0.21791775999999984" />
          <geometry>
            <sphere radius="0.05214000000001" />
          </geometry>
        </collision>
        <collision name="arm_r_link5_coarse_2">
          <origin rpy="-0.0 0.0 -0.0"
            xyz="0.001464843800000002 0.02841250000000014 0.287128723000000035" />
          <geometry>
            <sphere radius="0.0521019999999999" />
          </geometry>
        </collision>
        <collision name="arm_r_link5_coarse_3">
          <origin rpy="-0.0 0.0 -0.0"
            xyz="-0.0015869140999999996 -0.02848128500000002 0.2891775999999984" />
          <geometry>
            <sphere radius="0.05214000000001" />
          </geometry>
        </collision>
        <collision name="arm_r_link5_coarse_4">
          <origin rpy="-0.0 0.0 -0.0"
            xyz="-0.0009765625000000072 0.0031794570000000027 0.1568145800000001" />
          <geometry>
            <sphere radius="0.05447049" />
          </geometry>
        </collision>
      </xacro:if>
      <xacro:if value="${collision_type == 'fine'}">
        <collision name="arm_r_link5_convex_0">
          <geometry>
            <mesh filename="${mesh_dir}/arm/crs/convex/arm_r_link5_fine_0.STL" />
          </geometry>
        </collision>
        <collision_checking>
          <convex name="arm_r_link5_convex_0" />
        </collision_checking>
      </xacro:if>
    </link>
    <joint name="idx65_arm_r_joint5" type="revolute">
      <origin
        xyz="-0.018 0 0"
        rpy="-${PI_2} 0 0" />
      <parent link="arm_r_link4" />
      <child link="arm_r_link5" />
      <axis
        xyz="0 0 1" />
      <limit
        lower="-3.0718"
        upper="3.0718"
        effort="35"
        velocity="4.7" />
      <dynamics friction="0.5" />
      <drive stiffness="15000" damping="220" />
    </joint>
    <link name="arm_r_link6">
      <inertial>
        <origin xyz="-0.00458177 -0.00027029 9.098e-05" rpy="0 0 0" />
        <mass value="0.64594816" />
        <inertia ixx="0.00048449366" iyy="0.00043524004" izz="0.00040988625" ixy="0" ixz="0" iyz="0" />
      </inertial>
      <visual name="default_visual">
        <geometry>
          <mesh filename="${mesh_dir}/arm/crs/arm_link6.dae" />
        </geometry>
        <origin xyz="0 0 0" rpy="0 0 0" />
      </visual>
      <xacro:if value="${collision_type == 'visual'}">
        <collision name="arm_r_link6_visual_0">
          <origin
            xyz="0 0 0"
            rpy="0 0 0" />
          <geometry>
            <mesh filename="${mesh_dir}/arm/crs/arm_link6.STL" />
          </geometry>
        </collision>
      </xacro:if>
      <xacro:if value="${collision_type == 'coarse'}">
        <collision name="arm_r_link6_coarse_0">
          <origin rpy="-0.0 0.0 -0.0"
            xyz="1.4374967121801579e-18 -1.7293193529986862e-19 5.755390971698752e-19" />
          <geometry>
            <sphere radius="0.052349735" />
          </geometry>
        </collision>
      </xacro:if>
      <xacro:if value="${collision_type == 'fine'}">
        <collision name="arm_r_link6_convex_0">
          <geometry>
            <mesh filename="${mesh_dir}/arm/crs/convex/arm_r_link6_fine_0.STL" />
          </geometry>
        </collision>
        <collision_checking>
          <convex name="arm_r_link6_convex_0" />
        </collision_checking>
      </xacro:if>
    </link>
    <joint name="idx66_arm_r_joint6" type="revolute">
      <origin
        xyz="0 0 0.314"
        rpy="${PI_2} 0 0" />
      <parent link="arm_r_link5" />
      <child link="arm_r_link6" />
      <axis
        xyz="0 0 1" />
      <limit
        lower="-1.0123"
        upper="1.0123"
        effort="18"
        velocity="4.7" />
      <dynamics friction="0.2" />
      <drive stiffness="8000" damping="100" />
    </joint>
    <link name="arm_r_link7">
      <inertial>
        <origin xyz="0.0451337 4.672e-05 0.00607482" rpy="-0.00014482803 0.26364697 0.00078168277" />
        <mass value="0.31658" />
        <inertia ixx="0.00042203743" iyy="0.00084801289" izz="0.00064049225" ixy="0" ixz="0" iyz="0" />
      </inertial>
      <visual name="default_visual">
        <geometry>
          <mesh filename="${mesh_dir}/arm/crs/arm_link7.dae" />
        </geometry>
        <origin xyz="0 0 0" rpy="0 0 0" />
      </visual>
      <xacro:if value="${collision_type == 'visual'}">
        <collision name="arm_r_link7_visual_0">
          <origin
            xyz="0 0 0"
            rpy="0 0 0" />
          <geometry>
            <mesh filename="${mesh_dir}/arm/crs/arm_link7.STL" />
          </geometry>
        </collision>
      </xacro:if>
      <xacro:if value="${collision_type == 'coarse'}">
        <collision name="arm_r_link7_coarse_0">
          <origin rpy="-0.0 0.0 -0.0" xyz="0.05914825400000002 0.0 0.0" />
          <geometry>
            <sphere radius="0.04457995700000001" />
          </geometry>
        </collision>
        <collision name="arm_r_link7_coarse_1">
          <origin rpy="-0.0 0.0 -0.0" xyz="0.0 0.0 0.02" />
          <geometry>
            <sphere radius="0.04457995700000001" />
          </geometry>
        </collision>
        <collision name="arm_r_link7_coarse_2">
          <origin rpy="-0.0 0.0 -0.0" xyz="0.0 0.0 -0.02" />
          <geometry>
            <sphere radius="0.04457995700000001" />
          </geometry>
        </collision>
      </xacro:if>
      <xacro:if value="${collision_type == 'fine'}">
        <collision name="arm_r_link7_convex_0">
          <geometry>
            <mesh filename="${mesh_dir}/arm/crs/convex/arm_r_link7_fine_0.STL" />
          </geometry>
        </collision>
        <collision_checking>
          <convex name="arm_r_link7_convex_0" />
        </collision_checking>
      </xacro:if>
    </link>
    <link name="${end_link}">
      <inertial>
        <origin xyz="0 0 0" rpy="0 0 0" />
        <mass value="0.001" />
        <inertia ixx="1e-6" iyy="1e-6" izz="1e-6" ixy="0" ixz="0" iyz="0" />
      </inertial>
    </link>
    <joint name="idx67_arm_r_joint7" type="revolute">
      <origin
        xyz="0 0 0"
        rpy="${PI_2} 0 ${PI_2}" />
      <parent link="arm_r_link6" />
      <child link="arm_r_link7" />
      <axis
        xyz="0 0 1" />
      <limit
        lower="-1.5359"
        upper="1.5359"
        effort="18"
        velocity="4.7" />
      <dynamics friction="0.2" />
      <drive stiffness="8000" damping="100" />
    </joint>
    <joint name='arm_r_end_joint' type='fixed'>
      <origin xyz="0.095 0.0 0.0" rpy="${PI} -${PI_2} 0" />
      <parent link="arm_r_link7" />
      <child link="${end_link}" />
    </joint>

  </xacro:macro>
</robot>
