<?xml version="1.0"?>
<robot xmlns:xacro="http://www.ros.org/wiki/xacro">

  <!-- main xacro -->
  <xacro:macro name="arm_l"
    params="parent_link xyz_offset rpy_offset end_link collision_type mesh_dir app">
    <!-- properties -->

    <!-- Arm -->
    <link name="arm_l_link1">
      <inertial>
        <origin xyz="-0.000184301 0.001568154 0.172803911" rpy="0 0 0" />
        <mass value="2.17" />
        <inertia ixx="0.0045684858" iyy="0.0038299629" izz="0.0036068582" ixy="0" ixz="0" iyz="0" />
      </inertial>
      <visual name="default_visual">
        <geometry>
          <mesh filename="${mesh_dir}/arm/crsB/arm_l_link1.dae" />
        </geometry>
        <origin xyz="0 0 0" rpy="0 0 0" />
        <material_override>
          <roughness>0.45</roughness>
          <metallic>0.0</metallic>
        </material_override>
      </visual>
      <xacro:if value="${collision_type == 'visual'}">
        <collision name="arm_l_link1_visual_0">
          <origin
            xyz="0 0 0"
            rpy="0 0 0" />
          <geometry>
            <mesh filename="${mesh_dir}/arm/crsB/arm_l_link1.STL" />
          </geometry>
        </collision>
      </xacro:if>
      <xacro:if value="${collision_type == 'fine' or collision_type == 'coarse'}">
        <collision name="arm_l_link1_convex_0">
          <geometry>
            <mesh filename="${mesh_dir}/arm/crsB/convex/arm_l_link1.STL" />
          </geometry>
        </collision>
        <collision_checking>
          <convex name="arm_l_link1_convex_0" />
        </collision_checking>
      </xacro:if>
    </link>
    <joint name="idx21_arm_l_joint1" type="revolute">
      <origin
        xyz="${xyz_offset}"
        rpy="${rpy_offset}" />
      <parent link="${parent_link}" />
      <child link="arm_l_link1" />
      <axis
        xyz="0 0 1" />
      <limit
        lower="-3.0718"
        upper="3.0718"
        effort="108"
        velocity="3.05" />
      <dynamics friction="1.0" />
      <drive stiffness="40000" damping="600" />
    </joint>
    <link name="arm_l_link2">
      <inertial>
        <origin xyz="-1.6932e-05 0.106689462 -0.00179469" rpy="0 0 0" />
        <mass value="1.9" />
        <inertia ixx="0.0092901245" iyy="0.0040692426" izz="0.011083094" ixy="0" ixz="0" iyz="0" />
      </inertial>
      <visual name="default_visual">
        <geometry>
          <mesh filename="${mesh_dir}/arm/crsB/arm_l_link2.dae" />
        </geometry>
        <origin xyz="0 0 0" rpy="0 0 0" />
        <material_override>
          <roughness>0.62</roughness>
          <metallic>0.66</metallic>
        </material_override>
      </visual>
      <xacro:if value="${collision_type == 'visual'}">
        <collision name="arm_l_link2_visual_0">
          <origin
            xyz="0 0 0"
            rpy="0 0 0" />
          <geometry>
            <mesh filename="${mesh_dir}/arm/crsB/arm_l_link2.STL" />
          </geometry>
        </collision>
      </xacro:if>
      <xacro:if value="${collision_type == 'fine' or collision_type == 'coarse'}">
        <collision name="arm_l_link2_convex_0">
          <geometry>
            <mesh filename="${mesh_dir}/arm/crsB/convex/arm_l_link2.STL" />
          </geometry>
        </collision>
        <collision_checking>
          <convex name="arm_l_link2_convex_0" />
        </collision_checking>
      </xacro:if>
    </link>
    <joint name="idx22_arm_l_joint2" type="revolute">
      <origin
        xyz="0 0 0.1745"
        rpy="1.5708 0 0" />
      <parent link="arm_l_link1" />
      <child link="arm_l_link2" />
      <axis
        xyz="0 0 1" />
      <limit
        lower="-2.0595"
        upper="2.0595"
        effort="108"
        velocity="3.05" />
      <dynamics friction="1.0" />
      <drive stiffness="40000" damping="600" />
    </joint>
    <link name="arm_l_link3">
      <inertial>
        <origin xyz="0.008226598 -0.001273425 0.311389109" rpy="-3.295742e-05 0.121305 0.023560788" />
        <mass value="1.86" />
        <inertia ixx="0.0097378904" iyy="0.0091706347" izz="0.0025401782" ixy="0" ixz="0" iyz="0" />
      </inertial>
      <visual name="default_visual">
        <geometry>
          <mesh filename="${mesh_dir}/arm/crsB/arm_l_link3.dae" />
        </geometry>
        <origin xyz="0 0 0" rpy="0 0 0" />
        <material_override>
          <roughness>0.62</roughness>
          <metallic>0.66</metallic>
        </material_override>
      </visual>
      <xacro:if value="${collision_type == 'visual'}">
        <collision name="arm_l_link3_visual_0">
          <origin xyz="0 0 0" rpy="0 0 0" />
          <geometry>
            <mesh filename="${mesh_dir}/arm/crsB/arm_l_link3.STL" />
          </geometry>
        </collision>
      </xacro:if>
      <xacro:if value="${collision_type == 'fine' or collision_type == 'coarse'}">
        <collision name="arm_l_link3_convex_0">
          <origin xyz="0 0 0" rpy="0 0 0" />
          <geometry>
            <mesh filename="${mesh_dir}/arm/crsB/convex/arm_l_link3.STL" />
          </geometry>
        </collision>
        <collision_checking>
          <convex name="arm_l_link3_convex_0" />
        </collision_checking>
      </xacro:if>
    </link>
    <joint name="idx23_arm_l_joint3" type="revolute">
      <origin
        xyz="0 0 0"
        rpy="-1.5708 0 0" />
      <parent link="arm_l_link2" />
      <child link="arm_l_link3" />
      <axis
        xyz="0 0 1" />
      <limit
        lower="-3.0718"
        upper="3.0718"
        effort="35"
        velocity="3.76" />
      <dynamics friction="0.5" />
      <drive stiffness="15000" damping="220" />
    </joint>
    <link name="arm_l_link4">
      <inertial>
        <origin xyz="-0.009241652 0.084042407 0.002171786" rpy="0 0 0" />
        <mass value="1.027" />
        <inertia ixx="0.0030622237" iyy="0.0018678507" izz="0.0038286479" ixy="0" ixz="0" iyz="0" />
      </inertial>
      <visual name="default_visual">
        <geometry>
          <mesh filename="${mesh_dir}/arm/crsB/arm_l_link4.dae" />
        </geometry>
        <origin xyz="0 0 0" rpy="0 0 0" />
        <material_override>
          <roughness>0.62</roughness>
          <metallic>0.66</metallic>
        </material_override>
      </visual>
      <xacro:if value="${collision_type == 'visual'}">
        <collision name="arm_l_link4_visual_0">
          <origin
            xyz="0 0 0"
            rpy="0 0 0" />
          <geometry>
            <mesh filename="${mesh_dir}/arm/crsB/arm_l_link4.STL" />
          </geometry>
        </collision>
      </xacro:if>
      <xacro:if value="${collision_type == 'fine' or collision_type == 'coarse'}">
        <collision name="arm_l_link4_convex_0">
          <geometry>
            <mesh filename="${mesh_dir}/arm/crsB/convex/arm_l_link4.STL" />
          </geometry>
        </collision>
        <collision_checking>
          <convex name="arm_l_link4_convex_0" />
        </collision_checking>
      </xacro:if>
    </link>
    <joint name="idx24_arm_l_joint4" type="revolute">
      <origin
        xyz="0.0105 0 0.332"
        rpy="1.5708 0 0" />
      <parent link="arm_l_link3" />
      <child link="arm_l_link4" />
      <axis
        xyz="0 0 1" />
      <limit
        lower="-2.4959"
        upper="1.0123"
        effort="35"
        velocity="3.76" />
      <dynamics friction="0.5" />
      <drive stiffness="15000" damping="220" />
    </joint>
    <link name="arm_l_link5">
      <inertial>
        <origin xyz="-0.000756035 0.000722914 0.191236396" rpy="0 0 0" />
        <mass value="1.276" />
        <inertia ixx="0.0026521167" iyy="0.0020061801" izz="0.0018550889" ixy="0" ixz="0" iyz="0" />
      </inertial>
      <visual name="default_visual">
        <geometry>
          <mesh filename="${mesh_dir}/arm/crsB/arm_l_link5.dae" />
        </geometry>
        <origin xyz="0 0 0" rpy="0 0 0" />
        <material_override>
          <roughness>0.62</roughness>
          <metallic>0.66</metallic>
        </material_override>
      </visual>
      <xacro:if value="${collision_type == 'visual'}">
        <collision name="arm_l_link5_visual_0">
          <origin
            xyz="0 0 0"
            rpy="0 0 0" />
          <geometry>
            <mesh filename="${mesh_dir}/arm/crsB/arm_l_link5.STL" />
          </geometry>
        </collision>
      </xacro:if>
      <xacro:if value="${collision_type == 'fine' or collision_type == 'coarse'}">
        <collision name="arm_l_link5_convex_0">
          <geometry>
            <mesh filename="${mesh_dir}/arm/crsB/convex/arm_l_link5.STL" />
          </geometry>
        </collision>
        <collision_checking>
          <convex name="arm_l_link5_convex_0" />
        </collision_checking>
      </xacro:if>
    </link>
    <joint name="idx25_arm_l_joint5" type="revolute">
      <origin
        xyz="-0.0105 0 0"
        rpy="-1.5708 0 0" />
      <parent link="arm_l_link4" />
      <child link="arm_l_link5" />
      <axis
        xyz="0 0 1" />
      <limit
        lower="-3.0718"
        upper="3.0718"
        effort="35"
        velocity="3.35" />
      <dynamics friction="0.5" />
      <drive stiffness="15000" damping="220" />
    </joint>
    <link name="arm_l_link6">
      <inertial>
        <origin xyz="-0.003932433 6.1837e-05 -0.000158947" rpy="0 0 0" />
        <mass value="0.813" />
        <inertia ixx="0.00061048339" iyy="0.000847455" izz="0.00079808869" ixy="0" ixz="0" iyz="0" />
      </inertial>
      <visual name="default_visual">
        <geometry>
          <mesh filename="${mesh_dir}/arm/crsB/arm_l_link6.dae" />
        </geometry>
        <origin xyz="0 0 0" rpy="0 0 0" />
        <material_override>
          <roughness>0.45</roughness>
          <metallic>0.0</metallic>
        </material_override>
      </visual>
      <xacro:if value="${collision_type == 'visual'}">
        <collision name="arm_l_link6_visual_0">
          <origin
            xyz="0 0 0"
            rpy="0 0 0" />
          <geometry>
            <mesh filename="${mesh_dir}/arm/crsB/arm_l_link6.STL" />
          </geometry>
        </collision>
      </xacro:if>
      <xacro:if value="${collision_type == 'fine' or collision_type == 'coarse'}">
        <collision name="arm_l_link6_convex_0">
          <geometry>
            <mesh filename="${mesh_dir}/arm/crsB/convex/arm_l_link6.STL" />
          </geometry>
        </collision>
        <collision_checking>
          <convex name="arm_l_link6_convex_0" />
        </collision_checking>
      </xacro:if>
    </link>
    <joint name="idx26_arm_l_joint6" type="revolute">
      <origin
        xyz="0 0 0.278"
        rpy="1.5708 0 0" />
      <parent link="arm_l_link5" />
      <child link="arm_l_link6" />
      <axis
        xyz="0 0 1" />
      <limit
        lower="-1.0123"
        upper="1.0123"
        effort="18"
        velocity="3.35" />
      <dynamics friction="0.2" />
      <drive stiffness="8000" damping="100" />
    </joint>
    <link name="arm_l_link7">
      <inertial>
        <origin xyz="0.052854064 0.000277108 -0.001539537"
          rpy="0.0021841338 0.74085621 0.0051921926" />
        <mass value="0.312" />
        <inertia ixx="0.00066707346" iyy="0.00048288787" izz="0.00033761546" ixy="0" ixz="0" iyz="0" />
      </inertial>
      <visual name="default_visual">
        <geometry>
          <mesh filename="${mesh_dir}/arm/crsB/arm_l_link7.dae" />
        </geometry>
        <origin xyz="0 0 0" rpy="0 0 0" />
        <material_override>
          <roughness>0.45</roughness>
          <metallic>0.0</metallic>
        </material_override>
      </visual>
      <xacro:if value="${collision_type == 'visual'}">
        <collision name="arm_l_link7_visual_0">
          <origin
            xyz="0 0 0"
            rpy="0 0 0" />
          <geometry>
            <mesh filename="${mesh_dir}/arm/crsB/arm_l_link7.STL" />
          </geometry>
        </collision>
      </xacro:if>
      <xacro:if value="${collision_type == 'fine' or collision_type == 'coarse'}">
        <collision name="arm_l_link7_convex_0">
          <geometry>
            <mesh filename="${mesh_dir}/arm/crsB/convex/arm_l_link7.STL" />
          </geometry>
        </collision>
        <collision_checking>
          <convex name="arm_l_link7_convex_0" />
        </collision_checking>
      </xacro:if>
    </link>
    <joint name="idx27_arm_l_joint7" type="revolute">
      <origin
        xyz="0 0 0"
        rpy="1.5708 0 1.5708" />
      <parent link="arm_l_link6" />
      <child link="arm_l_link7" />
      <axis
        xyz="0 0 1" />
      <limit
        lower="-1.5359"
        upper="1.5359"
        effort="18"
        velocity="3.35" />
      <dynamics friction="0.2" />
      <drive stiffness="8000" damping="100" />
    </joint>
    <link name="${end_link}">
      <inertial>
        <origin xyz="0 0 0" rpy="0 0 0" />
        <mass value="0.001" />
        <inertia ixx="1e-6" iyy="1e-6" izz="1e-6" ixy="0" ixz="0" iyz="0" />
      </inertial>
    </link>
    <joint name='arm_l_end_joint' type='fixed'>
      <origin xyz="0.09 0.0 0.0" rpy="${PI} -${PI_2} 0" />
      <parent link="arm_l_link7" />
      <child link="${end_link}" />
    </joint>

  </xacro:macro>

  <!-- main xacro -->
  <xacro:macro name="arm_r"
    params="parent_link xyz_offset rpy_offset end_link collision_type mesh_dir app">
    <!-- properties -->

    <!-- Arm -->
    <link name="arm_r_link1">
      <inertial>
        <origin xyz="0.000186337 -0.001542822 0.172784077" rpy="0 0 0" />
        <mass value="2.17" />
        <inertia ixx="0.0045671038" iyy="0.0038292523" izz="0.003606189" ixy="0" ixz="0" iyz="0" />
      </inertial>
      <visual name="default_visual">
        <geometry>
          <mesh filename="${mesh_dir}/arm/crsB/arm_r_link1.dae" />
        </geometry>
        <origin xyz="0 0 0" rpy="0 0 0" />
        <material_override>
          <roughness>0.45</roughness>
          <metallic>0.0</metallic>
        </material_override>
      </visual>
      <xacro:if value="${collision_type == 'visual'}">
        <collision name="arm_r_link1_visual_0">
          <origin
            xyz="0 0 0"
            rpy="0 0 0" />
          <geometry>
            <mesh filename="${mesh_dir}/arm/crsB/arm_r_link1.STL" />
          </geometry>
        </collision>
      </xacro:if>
      <xacro:if value="${collision_type == 'fine' or collision_type == 'coarse'}">
        <collision name="arm_r_link1_convex_0">
          <geometry>
            <mesh filename="${mesh_dir}/arm/crsB/convex/arm_r_link1.STL" />
          </geometry>
        </collision>
        <collision_checking>
          <convex name="arm_r_link1_convex_0" />
        </collision_checking>
      </xacro:if>
    </link>
    <joint name="idx61_arm_r_joint1" type="revolute">
      <origin
        xyz="${xyz_offset}"
        rpy="${rpy_offset}" />
      <parent link="${parent_link}" />
      <child link="arm_r_link1" />
      <axis xyz="0 0 1" />
      <limit
        lower="-3.0718"
        upper="3.0718"
        effort="108"
        velocity="3.05" />
      <dynamics friction="1.0" />
      <drive stiffness="40000" damping="600" />
    </joint>
    <link name="arm_r_link2">
      <inertial>
        <origin xyz="1.6928e-05 0.106691378 0.001794536" rpy="0 0 0" />
        <mass value="1.9" />
        <inertia ixx="0.0092902802" iyy="0.004069242" izz="0.011083249" ixy="0" ixz="0" iyz="0" />
      </inertial>
      <visual name="default_visual">
        <geometry>
          <mesh filename="${mesh_dir}/arm/crsB/arm_r_link2.dae" />
        </geometry>
        <origin xyz="0 0 0" rpy="0 0 0" />
        <material_override>
          <roughness>0.62</roughness>
          <metallic>0.66</metallic>
        </material_override>
      </visual>
      <xacro:if value="${collision_type == 'visual'}">
        <collision name="arm_r_link2_visual_0">
          <origin
            xyz="0 0 0"
            rpy="0 0 0" />
          <geometry>
            <mesh filename="${mesh_dir}/arm/crsB/arm_r_link2.STL" />
          </geometry>
        </collision>
      </xacro:if>
      <xacro:if value="${collision_type == 'fine' or collision_type == 'coarse'}">
        <collision name="arm_r_link2_convex_0">
          <geometry>
            <mesh filename="${mesh_dir}/arm/crsB/convex/arm_r_link2.STL" />
          </geometry>
        </collision>
        <collision_checking>
          <convex name="arm_r_link2_convex_0" />
        </collision_checking>
      </xacro:if>
    </link>
    <joint name="idx62_arm_r_joint2" type="revolute">
      <origin
        xyz="0 0 0.1745"
        rpy="${PI_2} 0 0" />
      <parent link="arm_r_link1" />
      <child link="arm_r_link2" />
      <axis
        xyz="0 0 1" />
      <limit
        lower="-2.0595"
        upper="2.0595"
        effort="108"
        velocity="3.05" />
      <dynamics friction="1.0" />
      <drive stiffness="40000" damping="600" />
    </joint>
    <link name="arm_r_link3">
      <inertial>
        <origin xyz="0.009022338 0.000900475 0.312063927"
          rpy="0.00026345619 0.12734597 -0.038029706" />
        <mass value="1.86" />
        <inertia ixx="0.0098256538" iyy="0.0092532856" izz="0.0025417526" ixy="0" ixz="0" iyz="0" />
      </inertial>
      <visual name="default_visual">
        <geometry>
          <mesh filename="${mesh_dir}/arm/crsB/arm_r_link3.dae" />
        </geometry>
        <origin xyz="0 0 0" rpy="0 0 0" />
        <material_override>
          <roughness>0.62</roughness>
          <metallic>0.66</metallic>
        </material_override>
      </visual>
      <xacro:if value="${collision_type == 'visual'}">
        <collision name="arm_r_link3_visual_0">
          <origin xyz="0 0 0" rpy="0 0 0" />
          <geometry>
            <mesh filename="${mesh_dir}/arm/crsB/arm_r_link3.STL" />
          </geometry>
        </collision>
      </xacro:if>

      <xacro:if value="${collision_type == 'fine' or collision_type == 'coarse'}">
        <collision name="arm_r_link3_convex_0">
          <origin xyz="0 0 0" rpy="0 0 0" />
          <geometry>
            <mesh filename="${mesh_dir}/arm/crsB/convex/arm_r_link3.STL" />
          </geometry>
        </collision>
        <collision_checking>
          <convex name="arm_r_link3_convex_0" />
        </collision_checking>
      </xacro:if>
    </link>
    <joint name="idx63_arm_r_joint3" type="revolute">
      <origin
        xyz="0 0 0"
        rpy="-${PI_2} 0 0" />
      <parent link="arm_r_link2" />
      <child link="arm_r_link3" />
      <axis
        xyz="0 0 1" />
      <limit
        lower="-3.0718"
        upper="3.0718"
        effort="35"
        velocity="3.76" />
      <dynamics friction="0.5" />
      <drive stiffness="15000" damping="220" />
    </joint>
    <link name="arm_r_link4">
      <inertial>
        <origin xyz="-0.009272377 0.084042199 -0.00216935" rpy="0 0 0" />
        <mass value="1.027" />
        <inertia ixx="0.0030622132" iyy="0.0018676121" izz="0.0038284061" ixy="0" ixz="0" iyz="0" />
      </inertial>
      <visual name="default_visual">
        <geometry>
          <mesh filename="${mesh_dir}/arm/crsB/arm_r_link4.dae" />
        </geometry>
        <origin xyz="0 0 0" rpy="0 0 0" />
        <material_override>
          <roughness>0.62</roughness>
          <metallic>0.66</metallic>
        </material_override>
      </visual>
      <xacro:if value="${collision_type == 'visual'}">
        <collision name="arm_r_link4_visual_0">
          <origin
            xyz="0 0 0"
            rpy="0 0 0" />
          <geometry>
            <mesh filename="${mesh_dir}/arm/crsB/arm_r_link4.STL" />
          </geometry>
        </collision>
      </xacro:if>

      <xacro:if value="${collision_type == 'fine' or collision_type == 'coarse'}">
        <collision name="arm_r_link4_convex_0">
          <geometry>
            <mesh filename="${mesh_dir}/arm/crsB/convex/arm_r_link4.STL" />
          </geometry>
        </collision>
        <collision_checking>
          <convex name="arm_r_link4_convex_0" />
        </collision_checking>
      </xacro:if>
    </link>
    <joint name="idx64_arm_r_joint4" type="revolute">
      <origin
        xyz="0.0105 0 0.332"
        rpy="${PI_2} 0 0" />
      <parent link="arm_r_link3" />
      <child link="arm_r_link4" />
      <axis
        xyz="0 0 1" />
      <limit
        lower="-2.4959"
        upper="1.0123"
        effort="35"
        velocity="3.76" />
      <dynamics friction="0.5" />
      <drive stiffness="15000" damping="220" />
    </joint>
    <link name="arm_r_link5">
      <inertial>
        <origin xyz="-0.000776373 -0.000803696 0.191266219" rpy="0 0 0" />
        <mass value="1.276" />
        <inertia ixx="0.0026524324" iyy="0.0020063812" izz="0.0018552827" ixy="0" ixz="0" iyz="0" />
      </inertial>
      <visual name="default_visual">
        <geometry>
          <mesh filename="${mesh_dir}/arm/crsB/arm_r_link5.dae" />
        </geometry>
        <origin xyz="0 0 0" rpy="0 0 0" />
        <material_override>
          <roughness>0.62</roughness>
          <metallic>0.66</metallic>
        </material_override>
      </visual>
      <xacro:if value="${collision_type == 'visual'}">
        <collision name="arm_r_link5_visual_0">
          <origin
            xyz="0 0 0"
            rpy="0 0 0" />
          <geometry>
            <mesh filename="${mesh_dir}/arm/crsB/arm_r_link5.STL" />
          </geometry>
        </collision>
      </xacro:if>

      <xacro:if value="${collision_type == 'fine' or collision_type == 'coarse'}">
        <collision name="arm_r_link5_convex_0">
          <geometry>
            <mesh filename="${mesh_dir}/arm/crsB/convex/arm_r_link5.STL" />
          </geometry>
        </collision>
        <collision_checking>
          <convex name="arm_r_link5_convex_0" />
        </collision_checking>
      </xacro:if>
    </link>
    <joint name="idx65_arm_r_joint5" type="revolute">
      <origin
        xyz="-0.0105 0 0"
        rpy="-${PI_2} 0 0" />
      <parent link="arm_r_link4" />
      <child link="arm_r_link5" />
      <axis
        xyz="0 0 1" />
      <limit
        lower="-3.0718"
        upper="3.0718"
        effort="35"
        velocity="3.35" />
      <dynamics friction="0.5" />
      <drive stiffness="15000" damping="220" />
    </joint>
    <link name="arm_r_link6">
      <inertial>
        <origin xyz="-0.003932145 -6.0365e-05 0.000158935" rpy="0 0 0" />
        <mass value="0.813" />
        <inertia ixx="0.00061048324" iyy="0.00084745225" izz="0.0007980861" ixy="0" ixz="0" iyz="0" />
      </inertial>
      <visual name="default_visual">
        <geometry>
          <mesh filename="${mesh_dir}/arm/crsB/arm_r_link6.dae" />
        </geometry>
        <origin xyz="0 0 0" rpy="0 0 0" />
        <material_override>
          <roughness>0.45</roughness>
          <metallic>0.0</metallic>
        </material_override>
      </visual>
      <xacro:if value="${collision_type == 'visual'}">
        <collision name="arm_r_link6_visual_0">
          <origin
            xyz="0 0 0"
            rpy="0 0 0" />
          <geometry>
            <mesh filename="${mesh_dir}/arm/crsB/arm_r_link6.STL" />
          </geometry>
        </collision>
      </xacro:if>

      <xacro:if value="${collision_type == 'fine' or collision_type == 'coarse'}">
        <collision name="arm_r_link6_convex_0">
          <geometry>
            <mesh filename="${mesh_dir}/arm/crsB/convex/arm_r_link6.STL" />
          </geometry>
        </collision>
        <collision_checking>
          <convex name="arm_r_link6_convex_0" />
        </collision_checking>
      </xacro:if>
    </link>
    <joint name="idx66_arm_r_joint6" type="revolute">
      <origin
        xyz="0 0 0.278"
        rpy="${PI_2} 0 0" />
      <parent link="arm_r_link5" />
      <child link="arm_r_link6" />
      <axis
        xyz="0 0 1" />
      <limit
        lower="-1.0123"
        upper="1.0123"
        effort="18"
        velocity="3.35" />
      <dynamics friction="0.2" />
      <drive stiffness="8000" damping="100" />
    </joint>
    <link name="arm_r_link7">
      <inertial>
        <origin xyz="0.052862978 -0.000632229 -0.00134628"
          rpy="-0.00048989154 0.7396867 -0.0047170399" />
        <mass value="0.312" />
        <inertia ixx="0.00066747328" iyy="0.00048334854" izz="0.00033778095" ixy="0" ixz="0" iyz="0" />
      </inertial>
      <visual name="default_visual">
        <geometry>
          <mesh filename="${mesh_dir}/arm/crsB/arm_r_link7.dae" />
        </geometry>
        <origin xyz="0 0 0" rpy="0 0 0" />
        <material_override>
          <roughness>0.45</roughness>
          <metallic>0.0</metallic>
        </material_override>
      </visual>
      <xacro:if value="${collision_type == 'visual'}">
        <collision name="arm_r_link7_visual_0">
          <origin
            xyz="0 0 0"
            rpy="0 0 0" />
          <geometry>
            <mesh filename="${mesh_dir}/arm/crsB/arm_r_link7.STL" />
          </geometry>
        </collision>
      </xacro:if>

      <xacro:if value="${collision_type == 'fine' or collision_type == 'coarse'}">
        <collision name="arm_r_link7_convex_0">
          <geometry>
            <mesh filename="${mesh_dir}/arm/crsB/convex/arm_r_link7.STL" />
          </geometry>
        </collision>
        <collision_checking>
          <convex name="arm_r_link7_convex_0" />
        </collision_checking>
      </xacro:if>
    </link>
    <link name="${end_link}">
      <inertial>
        <origin xyz="0 0 0" rpy="0 0 0" />
        <mass value="0.001" />
        <inertia ixx="1e-6" iyy="1e-6" izz="1e-6" ixy="0" ixz="0" iyz="0" />
      </inertial>
    </link>
    <joint name="idx67_arm_r_joint7" type="revolute">
      <origin
        xyz="0 0 0"
        rpy="${PI_2} 0 ${PI_2}" />
      <parent link="arm_r_link6" />
      <child link="arm_r_link7" />
      <axis
        xyz="0 0 1" />
      <limit
        lower="-1.5359"
        upper="1.5359"
        effort="18"
        velocity="3.35" />
      <dynamics friction="0.2" />
      <drive stiffness="8000" damping="100" />
    </joint>
    <joint name='arm_r_end_joint' type='fixed'>
      <origin xyz="0.09 0.0 0.0" rpy="${PI} -${PI_2} 0" />
      <parent link="arm_r_link7" />
      <child link="${end_link}" />
    </joint>

  </xacro:macro>
</robot>
