<?xml version="1.0" encoding="utf-8"?>
<!--
  Piper robot description (no gripper).

  Adapted from piper_ros/piper_description/urdf/piper_no_gripper_description.xacro
  with mesh paths rewritten to package://genie_sim_robot_model/robots/agilex/piper/meshes/.

  Original: SolidWorks URDF Exporter
  6-DOF revolute arm only (no gripper links)

  Conventions (aligned with arx_x5, single-arm flavor):
    - Links/joints renamed from link1..6 / joint1..6 to arm_link1..6 /
      arm_joint1..6 to match the arx_x5 family.
    - Mesh files renamed link*.STL -> arm_link*.STL.
    - After arm_link6: arm_end_link (massless placeholder, identity-
      fixed) so the wrist tip has a stable named anchor, matching arx_x5.
-->
<robot name="piper"
  xmlns:xacro="http://www.ros.org/wiki/xacro">

  <xacro:property name="mesh_dir" value="package://genie_sim_robot_model/robots/agilex/piper/meshes" />

  <!-- world is the URDF root. The 1mm guide-sphere <visual> flips the
       Isaac Sim 6.0 URDF→USD converter's is_ghost_link check to False
       so it authors body0=parent_link on every joint. See
       genie_sim_robot_model/AGENTS.md → "Non-ghost root link pattern". -->
  <link name="world">
    <visual>
      <origin xyz="0 0 0" rpy="0 0 0"/>
      <geometry><sphere radius="0.001"/></geometry>
    </visual>
  </link>
  <joint name="fixed_base_joint" type="fixed">
    <parent link="world"/>
    <child link="base_link"/>
  </joint>

  <!-- base_link is intentionally an empty link so it can serve as the KDL
       root: kdl_parser rejects a root link that carries inertia. The
       visual / collision / inertial payload is moved to base_link_inertia,
       a child of base_link via an identity-transform fixed joint. The
       kinematic chain (arm_joint1 ...) still hangs off base_link, so no
       downstream link/joint names change. -->
  <link name="base_link" />
  <link name="base_link_inertia">
    <inertial>
      <origin xyz="-0.00473641164191482 2.56829134630247E-05 0.041451518036016" rpy="0 0 0" />
      <mass value="1.02" />
      <inertia ixx="0.00267433" ixy="-0.00000073" ixz="-0.00017389" iyy="0.00282612" iyz="0.0000004" izz="0.00089624" />
    </inertial>
    <visual>
      <origin xyz="0 0 0" rpy="0 0 0" />
      <geometry><mesh filename="${mesh_dir}/base_link.STL" /></geometry>
      <material name=""><color rgba="0.79216 0.81961 0.93333 1" /></material>
    </visual>
    <collision>
      <origin xyz="0 0 0" rpy="0 0 0" />
      <geometry><mesh filename="${mesh_dir}/base_link.STL" /></geometry>
    </collision>
  </link>
  <joint name="base_link-base_link_inertia" type="fixed">
    <origin xyz="0 0 0" rpy="0 0 0" />
    <parent link="base_link" />
    <child link="base_link_inertia" />
  </joint>

  <link name="arm_link1">
    <inertial>
      <origin xyz="0.000121504734057468 0.000104632162460536 -0.00438597309559853" rpy="0 0 0" />
      <mass value="0.71" />
      <inertia ixx="0.00048916" ixy="-0.00000036" ixz="-0.00000224" iyy="0.00040472" iyz="-0.00000242" izz="0.00043982" />
    </inertial>
    <visual>
      <origin xyz="0 0 0" rpy="0 0 0" />
      <geometry><mesh filename="${mesh_dir}/arm_link1.STL" /></geometry>
      <material name=""><color rgba="0.79216 0.81961 0.93333 1" /></material>
    </visual>
    <collision>
      <origin xyz="0 0 0" rpy="0 0 0" />
      <geometry><mesh filename="${mesh_dir}/arm_link1.STL" /></geometry>
    </collision>
  </link>
  <joint name="arm_joint1" type="revolute">
    <origin xyz="0 0 0.123" rpy="0 0 0" />
    <parent link="base_link" />
    <child link="arm_link1" />
    <axis xyz="0 0 1" />
    <limit lower="-2.618" upper="2.168" effort="100" velocity="5" />
  </joint>

  <link name="arm_link2">
    <inertial>
      <origin xyz="0.198666145229743 -0.010926924140076 0.00142121714502687" rpy="0 0 0" />
      <mass value="1.17" />
      <inertia ixx="0.00116918" ixy="-0.00180037" ixz="0.00025146" iyy="0.06785384" iyz="-0.00000455" izz="0.06774489" />
    </inertial>
    <visual>
      <origin xyz="0 0 0" rpy="0 0 0" />
      <geometry><mesh filename="${mesh_dir}/arm_link2.STL" /></geometry>
      <material name=""><color rgba="0.79216 0.81961 0.93333 1" /></material>
    </visual>
    <collision>
      <origin xyz="0 0 0" rpy="0 0 0" />
      <geometry><mesh filename="${mesh_dir}/arm_link2.STL" /></geometry>
    </collision>
  </link>
  <joint name="arm_joint2" type="revolute">
    <origin xyz="0 0 0" rpy="1.5708 -0.1359 -3.1416" />
    <parent link="arm_link1" />
    <child link="arm_link2" />
    <axis xyz="0 0 1" />
    <limit lower="0" upper="3.14" effort="100" velocity="5" />
  </joint>

  <link name="arm_link3">
    <inertial>
      <origin xyz="-0.0202737662122021 -0.133914995944595 -0.000458682652737356" rpy="0 0 0" />
      <mass value="0.5" />
      <inertia ixx="0.01361711" ixy="0.00165794" ixz="-0.00000048" iyy="0.00045024" iyz="-0.00000045" izz="0.01380322" />
    </inertial>
    <visual>
      <origin xyz="0 0 0" rpy="0 0 0" />
      <geometry><mesh filename="${mesh_dir}/arm_link3.STL" /></geometry>
      <material name=""><color rgba="0.79216 0.81961 0.93333 1" /></material>
    </visual>
    <collision>
      <origin xyz="0 0 0" rpy="0 0 0" />
      <geometry><mesh filename="${mesh_dir}/arm_link3.STL" /></geometry>
    </collision>
  </link>
  <joint name="arm_joint3" type="revolute">
    <origin xyz="0.28503 0 0" rpy="0 0 -1.7939" />
    <parent link="arm_link2" />
    <child link="arm_link3" />
    <axis xyz="0 0 1" />
    <limit lower="-2.967" upper="0" effort="100" velocity="5" />
  </joint>

  <link name="arm_link4">
    <inertial>
      <origin xyz="-9.66635791618542E-05 0.000876064475651083 -0.00496880904640868" rpy="0 0 0" />
      <mass value="0.38" />
      <inertia ixx="0.00018501" ixy="0.00000054" ixz="0.00000120" iyy="0.00018965" iyz="-0.00000841" izz="0.00015484" />
    </inertial>
    <visual>
      <origin xyz="0 0 0" rpy="0 0 0" />
      <geometry><mesh filename="${mesh_dir}/arm_link4.STL" /></geometry>
      <material name=""><color rgba="0.79216 0.81961 0.93333 1" /></material>
    </visual>
    <collision>
      <origin xyz="0 0 0" rpy="0 0 0" />
      <geometry><mesh filename="${mesh_dir}/arm_link4.STL" /></geometry>
    </collision>
  </link>
  <joint name="arm_joint4" type="revolute">
    <origin xyz="-0.021984 -0.25075 0" rpy="1.5708 0 0" />
    <parent link="arm_link3" />
    <child link="arm_link4" />
    <axis xyz="0 0 1" />
    <limit lower="-1.745" upper="1.745" effort="100" velocity="5" />
  </joint>

  <link name="arm_link5">
    <inertial>
      <origin xyz="-4.10554118924211E-05 -0.0566486692356075 -0.0037205791677906" rpy="0 0 0" />
      <mass value="0.383" />
      <inertia ixx="0.00166169" ixy="0.00000006" ixz="-0.00000007" iyy="0.00018510" iyz="0.00001026" izz="0.00164321" />
    </inertial>
    <visual>
      <origin xyz="0 0 0" rpy="0 0 0" />
      <geometry><mesh filename="${mesh_dir}/arm_link5.STL" /></geometry>
      <material name=""><color rgba="0.79216 0.81961 0.93333 1" /></material>
    </visual>
    <collision>
      <origin xyz="0 0 0" rpy="0 0 0" />
      <geometry><mesh filename="${mesh_dir}/arm_link5.STL" /></geometry>
    </collision>
  </link>
  <joint name="arm_joint5" type="revolute">
    <origin xyz="0 0 0" rpy="-1.5708 0 0" />
    <parent link="arm_link4" />
    <child link="arm_link5" />
    <axis xyz="0 0 1" />
    <limit lower="-1.22" upper="1.22" effort="100" velocity="5" />
  </joint>

  <link name="arm_link6">
    <inertial>
      <origin xyz="-8.82590762930069E-05 9.0598378529832E-06 -0.002" rpy="0 0 0" />
      <mass value="0.00699089613564366" />
      <inertia ixx="0.00000057" ixy="0" ixz="0" iyy="0.00000057" iyz="0" izz="0.00000107" />
    </inertial>
    <visual>
      <origin xyz="0 0 0" rpy="0 0 0" />
      <geometry><mesh filename="${mesh_dir}/arm_link6.STL" /></geometry>
      <material name=""><color rgba="0.89804 0.91765 0.92941 1" /></material>
    </visual>
    <collision>
      <origin xyz="0 0 0" rpy="0 0 0" />
      <geometry><mesh filename="${mesh_dir}/arm_link6.STL" /></geometry>
    </collision>
  </link>
  <joint name="arm_joint6" type="revolute">
    <origin xyz="8.8259E-05 -0.091 0" rpy="1.5708 0 0" />
    <parent link="arm_link5" />
    <child link="arm_link6" />
    <axis xyz="0 0 1" />
    <limit lower="-2.0944" upper="2.0944" effort="100" velocity="5" />
  </joint>

  <link name="arm_end_link">
    <inertial>
      <origin xyz="0 0 0" rpy="0 0 0" />
      <mass value="1e-6" />
      <inertia ixx="1e-9" ixy="0" ixz="0" iyy="1e-9" iyz="0" izz="1e-9" />
    </inertial>
  </link>
  <joint name="arm_end_fixed" type="fixed">
    <origin xyz="0 0 0" rpy="0 0 0" />
    <parent link="arm_link6" />
    <child link="arm_end_link" />
  </joint>

</robot>
